{
  "version": 8,
  "blockIdVersion": 11,
  "anchorX": 0,
  "anchorY": 0,
  "anchorZ": 0,
  "blocks": [
    {
      "x": -6,
      "y": 0,
      "z": -13,
      "name": "Rock_Volcanic_Brick"
    },
    {
      "x": -6,
      "y": 1,
      "z": -13,
      "name": "Rock_Volcanic_Brick_Pillar_Base"
    },
    {
      "x": -6,
      "y": 2,
      "z": -13,
      "name": "Rock_Volcanic_Brick_Pillar_Middle"
    },
    {
      "x": -6,
      "y": 3,
      "z": -13,
      "name": "Rock_Volcanic_Brick_Pillar_Middle"
    },
    {
      "x": -6,
      "y": 4,
      "z": -13,
      "name": "Rock_Volcanic_Brick_Pillar_Middle"
    },
    {
      "x": -6,
      "y": 5,
      "z": -13,
      "name": "Rock_Volcanic_Brick_Pillar_Base",
      "rotation": 8
    },
    {
      "x": -6,
      "y": 6,
      "z": -13,
      "name": "Rock_Crystal_White_Block",
      "rotation": 4
    },
    {
      "x": -6,
      "y": 0,
      "z": -12,
      "name": "Rock_Volcanic_Brick"
    },
    {
      "x": -6,
      "y": 6,
      "z": -12,
      "name": "Rock_Volcanic_Brick_Ornate"
    },
    {
      "x": -6,
      "y": 0,
      "z": -11,
      "name": "Rock_Volcanic_Brick"
    },
    {
      "x": -6,
      "y": 6,
      "z": -11,
      "name": "Rock_Volcanic_Brick_Roof_Shallow",
      "rotation": 3
    },
    {
      "x": -6,
      "y": 0,
      "z": -10,
      "name": "Rock_Volcanic_Brick"
    },
    {
      "x": -6,
      "y": 6,
      "z": -10,
      "name": "Rock_Volcanic_Brick_Roof_Shallow",
      "rotation": 3
    },
    {
      "x": -6,
      "y": 0,
      "z": -9,
      "name": "Rock_Volcanic_Brick"
    },
    {
      "x": -6,
      "y": 1,
      "z": -9,
      "name": "Rock_Volcanic_Brick_Pillar_Base"
    },
    {
      "x": -6,
      "y": 2,
      "z": -9,
      "name": "Rock_Volcanic_Brick_Pillar_Middle"
    },
    {
      "x": -6,
      "y": 3,
      "z": -9,
      "name": "Rock_Volcanic_Brick_Pillar_Middle"
    },
    {
      "x": -6,
      "y": 4,
      "z": -9,
      "name": "Rock_Volcanic_Brick_Pillar_Middle"
    },
    {
      "x": -6,
      "y": 5,
      "z": -9,
      "name": "Rock_Volcanic_Brick_Pillar_Base",
      "rotation": 8
    },
    {
      "x": -6,
      "y": 6,
      "z": -9,
      "name": "Rock_Volcanic_Brick_Roof_Shallow",
      "rotation": 3
    },
    {
      "x": -6,
      "y": 0,
      "z": -8,
      "name": "Rock_Volcanic_Brick"
    },
    {
      "x": -6,
      "y": 6,
      "z": -8,
      "name": "Rock_Volcanic_Brick_Roof_Shallow",
      "rotation": 3
    },
    {
      "x": -6,
      "y": 0,
      "z": -7,
      "name": "Rock_Volcanic_Brick"
    },
    {
      "x": -6,
      "y": 6,
      "z": -7,
      "name": "Rock_Volcanic_Brick_Roof_Shallow",
      "rotation": 3
    },
    {
      "x": -6,
      "y": 0,
      "z": -6,
      "name": "Rock_Volcanic_Brick"
    },
    {
      "x": -6,
      "y": 6,
      "z": -6,
      "name": "Rock_Volcanic_Brick_Roof_Shallow",
      "rotation": 3
    },
    {
      "x": -6,
      "y": 0,
      "z": -5,
      "name": "Rock_Volcanic_Brick"
    },
    {
      "x": -6,
      "y": 1,
      "z": -5,
      "name": "Rock_Volcanic_Brick_Pillar_Base"
    },
    {
      "x": -6,
      "y": 2,
      "z": -5,
      "name": "Rock_Volcanic_Brick_Pillar_Middle"
    },
    {
      "x": -6,
      "y": 3,
      "z": -5,
      "name": "Rock_Volcanic_Brick_Pillar_Middle"
    },
    {
      "x": -6,
      "y": 4,
      "z": -5,
      "name": "Rock_Volcanic_Brick_Pillar_Middle"
    },
    {
      "x": -6,
      "y": 5,
      "z": -5,
      "name": "Rock_Volcanic_Brick_Pillar_Base",
      "rotation": 8
    },
    {
      "x": -6,
      "y": 6,
      "z": -5,
      "name": "Rock_Volcanic_Brick_Roof_Shallow",
      "rotation": 3
    },
    {
      "x": -6,
      "y": 0,
      "z": -4,
      "name": "Rock_Volcanic_Brick"
    },
    {
      "x": -6,
      "y": 6,
      "z": -4,
      "name": "Rock_Volcanic_Brick_Roof_Shallow",
      "rotation": 3
    },
    {
      "x": -6,
      "y": 0,
      "z": -3,
      "name": "Rock_Volcanic_Brick"
    },
    {
      "x": -6,
      "y": 6,
      "z": -3,
      "name": "Rock_Volcanic_Brick_Roof_Shallow",
      "rotation": 3
    },
    {
      "x": -6,
      "y": 0,
      "z": -2,
      "name": "Rock_Volcanic_Brick"
    },
    {
      "x": -6,
      "y": 6,
      "z": -2,
      "name": "Rock_Volcanic_Brick_Roof_Shallow",
      "rotation": 3
    },
    {
      "x": -6,
      "y": 0,
      "z": -1,
      "name": "Rock_Volcanic_Brick"
    },
    {
      "x": -6,
      "y": 1,
      "z": -1,
      "name": "Rock_Volcanic_Brick_Pillar_Base"
    },
    {
      "x": -6,
      "y": 2,
      "z": -1,
      "name": "Rock_Volcanic_Brick_Pillar_Middle"
    },
    {
      "x": -6,
      "y": 3,
      "z": -1,
      "name": "Rock_Volcanic_Brick_Pillar_Middle"
    },
    {
      "x": -6,
      "y": 4,
      "z": -1,
      "name": "Rock_Volcanic_Brick_Pillar_Middle"
    },
    {
      "x": -6,
      "y": 5,
      "z": -1,
      "name": "Rock_Volcanic_Brick_Pillar_Base",
      "rotation": 8
    },
    {
      "x": -6,
      "y": 6,
      "z": -1,
      "name": "Rock_Volcanic_Brick_Roof_Shallow",
      "rotation": 3
    },
    {
      "x": -6,
      "y": 0,
      "z": 0,
      "name": "Rock_Volcanic_Brick"
    },
    {
      "x": -6,
      "y": 6,
      "z": 0,
      "name": "Rock_Volcanic_Brick_Roof_Shallow",
      "rotation": 3
    },
    {
      "x": -6,
      "y": 0,
      "z": 1,
      "name": "Rock_Volcanic_Brick"
    },
    {
      "x": -6,
      "y": 6,
      "z": 1,
      "name": "Rock_Volcanic_Brick_Roof_Shallow",
      "rotation": 3
    },
    {
      "x": -6,
      "y": 0,
      "z": 2,
      "name": "Rock_Volcanic_Brick"
    },
    {
      "x": -6,
      "y": 6,
      "z": 2,
      "name": "Rock_Volcanic_Brick_Roof_Shallow",
      "rotation": 3
    },
    {
      "x": -6,
      "y": 0,
      "z": 3,
      "name": "Rock_Volcanic_Brick"
    },
    {
      "x": -6,
      "y": 1,
      "z": 3,
      "name": "Rock_Volcanic_Brick_Pillar_Base"
    },
    {
      "x": -6,
      "y": 2,
      "z": 3,
      "name": "Rock_Volcanic_Brick_Pillar_Middle"
    },
    {
      "x": -6,
      "y": 3,
      "z": 3,
      "name": "Rock_Volcanic_Brick_Pillar_Middle"
    },
    {
      "x": -6,
      "y": 4,
      "z": 3,
      "name": "Rock_Volcanic_Brick_Pillar_Middle"
    },
    {
      "x": -6,
      "y": 5,
      "z": 3,
      "name": "Rock_Volcanic_Brick_Pillar_Base",
      "rotation": 8
    },
    {
      "x": -6,
      "y": 6,
      "z": 3,
      "name": "Rock_Volcanic_Brick_Roof_Shallow",
      "rotation": 3
    },
    {
      "x": -6,
      "y": 0,
      "z": 4,
      "name": "Rock_Volcanic_Brick"
    },
    {
      "x": -6,
      "y": 6,
      "z": 4,
      "name": "Rock_Volcanic_Brick_Roof_Shallow",
      "rotation": 3
    },
    {
      "x": -6,
      "y": 0,
      "z": 5,
      "name": "Rock_Volcanic_Brick"
    },
    {
      "x": -6,
      "y": 6,
      "z": 5,
      "name": "Rock_Volcanic_Brick_Roof_Shallow",
      "rotation": 3
    },
    {
      "x": -6,
      "y": 0,
      "z": 6,
      "name": "Rock_Volcanic_Brick"
    },
    {
      "x": -6,
      "y": 6,
      "z": 6,
      "name": "Rock_Volcanic_Brick_Roof_Shallow",
      "rotation": 3
    },
    {
      "x": -6,
      "y": 0,
      "z": 7,
      "name": "Rock_Volcanic_Brick"
    },
    {
      "x": -6,
      "y": 1,
      "z": 7,
      "name": "Rock_Volcanic_Brick_Pillar_Base"
    },
    {
      "x": -6,
      "y": 2,
      "z": 7,
      "name": "Rock_Volcanic_Brick_Pillar_Middle"
    },
    {
      "x": -6,
      "y": 3,
      "z": 7,
      "name": "Rock_Volcanic_Brick_Pillar_Middle"
    },
    {
      "x": -6,
      "y": 4,
      "z": 7,
      "name": "Rock_Volcanic_Brick_Pillar_Middle"
    },
    {
      "x": -6,
      "y": 5,
      "z": 7,
      "name": "Rock_Volcanic_Brick_Pillar_Base",
      "rotation": 8
    },
    {
      "x": -6,
      "y": 6,
      "z": 7,
      "name": "Rock_Volcanic_Brick_Roof_Shallow",
      "rotation": 3
    },
    {
      "x": -6,
      "y": 0,
      "z": 8,
      "name": "Rock_Volcanic_Brick"
    },
    {
      "x": -6,
      "y": 6,
      "z": 8,
      "name": "Rock_Volcanic_Brick_Roof_Shallow",
      "rotation": 3
    },
    {
      "x": -6,
      "y": 0,
      "z": 9,
      "name": "Rock_Volcanic_Brick"
    },
    {
      "x": -6,
      "y": 6,
      "z": 9,
      "name": "Rock_Volcanic_Brick_Roof_Shallow",
      "rotation": 3
    },
    {
      "x": -6,
      "y": 0,
      "z": 10,
      "name": "Rock_Volcanic_Brick"
    },
    {
      "x": -6,
      "y": 6,
      "z": 10,
      "name": "Rock_Volcanic_Brick_Roof_Shallow",
      "rotation": 3
    },
    {
      "x": -6,
      "y": 0,
      "z": 11,
      "name": "Rock_Volcanic_Brick"
    },
    {
      "x": -6,
      "y": 1,
      "z": 11,
      "name": "Rock_Volcanic_Brick_Pillar_Base"
    },
    {
      "x": -6,
      "y": 2,
      "z": 11,
      "name": "Rock_Volcanic_Brick_Pillar_Middle"
    },
    {
      "x": -6,
      "y": 3,
      "z": 11,
      "name": "Rock_Volcanic_Brick_Pillar_Middle"
    },
    {
      "x": -6,
      "y": 4,
      "z": 11,
      "name": "Rock_Volcanic_Brick_Pillar_Middle"
    },
    {
      "x": -6,
      "y": 5,
      "z": 11,
      "name": "Rock_Volcanic_Brick_Pillar_Base",
      "rotation": 8
    },
    {
      "x": -6,
      "y": 6,
      "z": 11,
      "name": "Rock_Volcanic_Brick_Roof_Shallow",
      "rotation": 3
    },
    {
      "x": -6,
      "y": 0,
      "z": 12,
      "name": "Rock_Volcanic_Brick"
    },
    {
      "x": -6,
      "y": 6,
      "z": 12,
      "name": "Rock_Volcanic_Brick_Roof_Shallow",
      "rotation": 3
    },
    {
      "x": -6,
      "y": 0,
      "z": 13,
      "name": "Rock_Volcanic_Brick"
    },
    {
      "x": -6,
      "y": 6,
      "z": 13,
      "name": "Rock_Volcanic_Brick_Roof_Shallow",
      "rotation": 3
    },
    {
      "x": -6,
      "y": 0,
      "z": 14,
      "name": "Rock_Volcanic_Brick"
    },
    {
      "x": -6,
      "y": 6,
      "z": 14,
      "name": "Rock_Volcanic_Brick_Ornate"
    },
    {
      "x": -6,
      "y": 0,
      "z": 15,
      "name": "Rock_Volcanic_Brick"
    },
    {
      "x": -6,
      "y": 1,
      "z": 15,
      "name": "Rock_Volcanic_Brick_Pillar_Base"
    },
    {
      "x": -6,
      "y": 2,
      "z": 15,
      "name": "Rock_Volcanic_Brick_Pillar_Middle"
    },
    {
      "x": -6,
      "y": 3,
      "z": 15,
      "name": "Rock_Volcanic_Brick_Pillar_Middle"
    },
    {
      "x": -6,
      "y": 4,
      "z": 15,
      "name": "Rock_Volcanic_Brick_Pillar_Middle"
    },
    {
      "x": -6,
      "y": 5,
      "z": 15,
      "name": "Rock_Volcanic_Brick_Pillar_Base",
      "rotation": 8
    },
    {
      "x": -6,
      "y": 6,
      "z": 15,
      "name": "Rock_Crystal_White_Block",
      "rotation": 4
    },
    {
      "x": -5,
      "y": 0,
      "z": -13,
      "name": "Rock_Volcanic_Brick"
    },
    {
      "x": -5,
      "y": 6,
      "z": -13,
      "name": "Rock_Volcanic_Brick_Ornate"
    },
    {
      "x": -5,
      "y": 0,
      "z": -12,
      "name": "Rock_Volcanic_Brick"
    },
    {
      "x": -5,
      "y": 6,
      "z": -12,
      "name": "Rock_Volcanic_Brick_Ornate"
    },
    {
      "x": -5,
      "y": 0,
      "z": -11,
      "name": "Rock_Volcanic_Brick"
    },
    {
      "x": -5,
      "y": 6,
      "z": -11,
      "name": "Rock_Volcanic_Brick_Roof_Shallow",
      "filler": 1,
      "rotation": 3
    },
    {
      "x": -5,
      "y": 0,
      "z": -10,
      "name": "Rock_Volcanic_Brick"
    },
    {
      "x": -5,
      "y": 6,
      "z": -10,
      "name": "Rock_Volcanic_Brick_Roof_Shallow",
      "filler": 1,
      "rotation": 3
    },
    {
      "x": -5,
      "y": 0,
      "z": -9,
      "name": "Rock_Volcanic_Brick"
    },
    {
      "x": -5,
      "y": 6,
      "z": -9,
      "name": "Rock_Volcanic_Brick_Roof_Shallow",
      "filler": 1,
      "rotation": 3
    },
    {
      "x": -5,
      "y": 0,
      "z": -8,
      "name": "Rock_Volcanic_Brick"
    },
    {
      "x": -5,
      "y": 6,
      "z": -8,
      "name": "Rock_Volcanic_Brick_Roof_Shallow",
      "filler": 1,
      "rotation": 3
    },
    {
      "x": -5,
      "y": 0,
      "z": -7,
      "name": "Rock_Volcanic_Brick"
    },
    {
      "x": -5,
      "y": 6,
      "z": -7,
      "name": "Rock_Volcanic_Brick_Roof_Shallow",
      "filler": 1,
      "rotation": 3
    },
    {
      "x": -5,
      "y": 0,
      "z": -6,
      "name": "Rock_Volcanic_Brick"
    },
    {
      "x": -5,
      "y": 6,
      "z": -6,
      "name": "Rock_Volcanic_Brick_Roof_Shallow",
      "filler": 1,
      "rotation": 3
    },
    {
      "x": -5,
      "y": 0,
      "z": -5,
      "name": "Rock_Volcanic_Brick"
    },
    {
      "x": -5,
      "y": 6,
      "z": -5,
      "name": "Rock_Volcanic_Brick_Roof_Shallow",
      "filler": 1,
      "rotation": 3
    },
    {
      "x": -5,
      "y": 0,
      "z": -4,
      "name": "Rock_Volcanic_Brick"
    },
    {
      "x": -5,
      "y": 6,
      "z": -4,
      "name": "Rock_Volcanic_Brick_Roof_Shallow",
      "filler": 1,
      "rotation": 3
    },
    {
      "x": -5,
      "y": 0,
      "z": -3,
      "name": "Rock_Volcanic_Brick"
    },
    {
      "x": -5,
      "y": 6,
      "z": -3,
      "name": "Rock_Volcanic_Brick_Roof_Shallow",
      "filler": 1,
      "rotation": 3
    },
    {
      "x": -5,
      "y": 0,
      "z": -2,
      "name": "Rock_Volcanic_Brick"
    },
    {
      "x": -5,
      "y": 6,
      "z": -2,
      "name": "Rock_Volcanic_Brick_Roof_Shallow",
      "filler": 1,
      "rotation": 3
    },
    {
      "x": -5,
      "y": 0,
      "z": -1,
      "name": "Rock_Volcanic_Brick"
    },
    {
      "x": -5,
      "y": 6,
      "z": -1,
      "name": "Rock_Volcanic_Brick_Roof_Shallow",
      "filler": 1,
      "rotation": 3
    },
    {
      "x": -5,
      "y": 0,
      "z": 0,
      "name": "Rock_Volcanic_Brick"
    },
    {
      "x": -5,
      "y": 6,
      "z": 0,
      "name": "Rock_Volcanic_Brick_Roof_Shallow",
      "filler": 1,
      "rotation": 3
    },
    {
      "x": -5,
      "y": 0,
      "z": 1,
      "name": "Rock_Volcanic_Brick"
    },
    {
      "x": -5,
      "y": 6,
      "z": 1,
      "name": "Rock_Volcanic_Brick_Roof_Shallow",
      "filler": 1,
      "rotation": 3
    },
    {
      "x": -5,
      "y": 0,
      "z": 2,
      "name": "Rock_Volcanic_Brick"
    },
    {
      "x": -5,
      "y": 6,
      "z": 2,
      "name": "Rock_Volcanic_Brick_Roof_Shallow",
      "filler": 1,
      "rotation": 3
    },
    {
      "x": -5,
      "y": 0,
      "z": 3,
      "name": "Rock_Volcanic_Brick"
    },
    {
      "x": -5,
      "y": 6,
      "z": 3,
      "name": "Rock_Volcanic_Brick_Roof_Shallow",
      "filler": 1,
      "rotation": 3
    },
    {
      "x": -5,
      "y": 0,
      "z": 4,
      "name": "Rock_Volcanic_Brick"
    },
    {
      "x": -5,
      "y": 6,
      "z": 4,
      "name": "Rock_Volcanic_Brick_Roof_Shallow",
      "filler": 1,
      "rotation": 3
    },
    {
      "x": -5,
      "y": 0,
      "z": 5,
      "name": "Rock_Volcanic_Brick"
    },
    {
      "x": -5,
      "y": 6,
      "z": 5,
      "name": "Rock_Volcanic_Brick_Roof_Shallow",
      "filler": 1,
      "rotation": 3
    },
    {
      "x": -5,
      "y": 0,
      "z": 6,
      "name": "Rock_Volcanic_Brick"
    },
    {
      "x": -5,
      "y": 6,
      "z": 6,
      "name": "Rock_Volcanic_Brick_Roof_Shallow",
      "filler": 1,
      "rotation": 3
    },
    {
      "x": -5,
      "y": 0,
      "z": 7,
      "name": "Rock_Volcanic_Brick"
    },
    {
      "x": -5,
      "y": 6,
      "z": 7,
      "name": "Rock_Volcanic_Brick_Roof_Shallow",
      "filler": 1,
      "rotation": 3
    },
    {
      "x": -5,
      "y": 0,
      "z": 8,
      "name": "Rock_Volcanic_Brick"
    },
    {
      "x": -5,
      "y": 6,
      "z": 8,
      "name": "Rock_Volcanic_Brick_Roof_Shallow",
      "filler": 1,
      "rotation": 3
    },
    {
      "x": -5,
      "y": 0,
      "z": 9,
      "name": "Rock_Volcanic_Brick"
    },
    {
      "x": -5,
      "y": 6,
      "z": 9,
      "name": "Rock_Volcanic_Brick_Roof_Shallow",
      "filler": 1,
      "rotation": 3
    },
    {
      "x": -5,
      "y": 0,
      "z": 10,
      "name": "Rock_Volcanic_Brick"
    },
    {
      "x": -5,
      "y": 6,
      "z": 10,
      "name": "Rock_Volcanic_Brick_Roof_Shallow",
      "filler": 1,
      "rotation": 3
    },
    {
      "x": -5,
      "y": 0,
      "z": 11,
      "name": "Rock_Volcanic_Brick"
    },
    {
      "x": -5,
      "y": 6,
      "z": 11,
      "name": "Rock_Volcanic_Brick_Roof_Shallow",
      "filler": 1,
      "rotation": 3
    },
    {
      "x": -5,
      "y": 0,
      "z": 12,
      "name": "Rock_Volcanic_Brick"
    },
    {
      "x": -5,
      "y": 6,
      "z": 12,
      "name": "Rock_Volcanic_Brick_Roof_Shallow",
      "filler": 1,
      "rotation": 3
    },
    {
      "x": -5,
      "y": 0,
      "z": 13,
      "name": "Rock_Volcanic_Brick"
    },
    {
      "x": -5,
      "y": 6,
      "z": 13,
      "name": "Rock_Volcanic_Brick_Roof_Shallow",
      "filler": 1,
      "rotation": 3
    },
    {
      "x": -5,
      "y": 0,
      "z": 14,
      "name": "Rock_Volcanic_Brick"
    },
    {
      "x": -5,
      "y": 6,
      "z": 14,
      "name": "Rock_Volcanic_Brick_Ornate"
    },
    {
      "x": -5,
      "y": 0,
      "z": 15,
      "name": "Rock_Volcanic_Brick"
    },
    {
      "x": -5,
      "y": 6,
      "z": 15,
      "name": "Rock_Volcanic_Brick_Ornate"
    },
    {
      "x": -4,
      "y": 0,
      "z": -13,
      "name": "Rock_Volcanic_Brick"
    },
    {
      "x": -4,
      "y": 6,
      "z": -13,
      "name": "Rock_Volcanic_Brick_Roof_Shallow",
      "rotation": 2
    },
    {
      "x": -4,
      "y": 0,
      "z": -12,
      "name": "Rock_Volcanic_Brick"
    },
    {
      "x": -4,
      "y": 6,
      "z": -12,
      "name": "Rock_Volcanic_Brick_Roof_Shallow",
      "filler": 32,
      "rotation": 2
    },
    {
      "x": -4,
      "y": 0,
      "z": -11,
      "name": "Rock_Volcanic_Brick"
    },
    {
      "x": -4,
      "y": 1,
      "z": -11,
      "name": "Rock_Volcanic_Brick"
    },
    {
      "x": -4,
      "y": 2,
      "z": -11,
      "name": "Rock_Volcanic_Brick_Ornate"
    },
    {
      "x": -4,
      "y": 3,
      "z": -11,
      "name": "Rock_Volcanic_Brick_Decorative"
    },
    {
      "x": -4,
      "y": 4,
      "z": -11,
      "name": "Rock_Volcanic_Brick_Smooth"
    },
    {
      "x": -4,
      "y": 5,
      "z": -11,
      "name": "Rock_Volcanic_Brick_Ornate"
    },
    {
      "x": -4,
      "y": 6,
      "z": -11,
      "name": "Rock_Volcanic_Brick_Ornate"
    },
    {
      "x": -4,
      "y": 0,
      "z": -10,
      "name": "Rock_Volcanic_Brick"
    },
    {
      "x": -4,
      "y": 1,
      "z": -10,
      "name": "Rock_Volcanic_Brick"
    },
    {
      "x": -4,
      "y": 2,
      "z": -10,
      "name": "Rock_Volcanic_Brick_Ornate"
    },
    {
      "x": -4,
      "y": 3,
      "z": -10,
      "name": "Rock_Volcanic_Brick_Decorative"
    },
    {
      "x": -4,
      "y": 4,
      "z": -10,
      "name": "Rock_Volcanic_Brick_Smooth"
    },
    {
      "x": -4,
      "y": 5,
      "z": -10,
      "name": "Rock_Volcanic_Brick_Ornate"
    },
    {
      "x": -4,
      "y": 6,
      "z": -10,
      "name": "Rock_Crystal_White_Block",
      "rotation": 4
    },
    {
      "x": -4,
      "y": 7,
      "z": -10,
      "name": "Rock_Volcanic_Brick_Roof_Flat"
    },
    {
      "x": -4,
      "y": 0,
      "z": -9,
      "name": "Rock_Volcanic_Brick"
    },
    {
      "x": -4,
      "y": 1,
      "z": -9,
      "name": "Rock_Volcanic_Brick"
    },
    {
      "x": -4,
      "y": 2,
      "z": -9,
      "name": "Rock_Volcanic_Brick_Ornate"
    },
    {
      "x": -4,
      "y": 3,
      "z": -9,
      "name": "Rock_Volcanic_Brick_Decorative"
    },
    {
      "x": -4,
      "y": 4,
      "z": -9,
      "name": "Rock_Volcanic_Brick_Smooth"
    },
    {
      "x": -4,
      "y": 5,
      "z": -9,
      "name": "Rock_Volcanic_Brick_Ornate"
    },
    {
      "x": -4,
      "y": 6,
      "z": -9,
      "name": "Rock_Crystal_White_Block",
      "rotation": 4
    },
    {
      "x": -4,
      "y": 7,
      "z": -9,
      "name": "Rock_Volcanic_Brick_Roof_Shallow",
      "rotation": 3
    },
    {
      "x": -4,
      "y": 0,
      "z": -8,
      "name": "Rock_Volcanic_Brick"
    },
    {
      "x": -4,
      "y": 1,
      "z": -8,
      "name": "Rock_Volcanic_Brick"
    },
    {
      "x": -4,
      "y": 2,
      "z": -8,
      "name": "Rock_Volcanic_Brick_Ornate"
    },
    {
      "x": -4,
      "y": 3,
      "z": -8,
      "name": "Rock_Volcanic_Brick_Decorative"
    },
    {
      "x": -4,
      "y": 4,
      "z": -8,
      "name": "Rock_Volcanic_Brick_Smooth"
    },
    {
      "x": -4,
      "y": 5,
      "z": -8,
      "name": "Rock_Volcanic_Brick_Ornate"
    },
    {
      "x": -4,
      "y": 6,
      "z": -8,
      "name": "Rock_Crystal_White_Block",
      "rotation": 4
    },
    {
      "x": -4,
      "y": 7,
      "z": -8,
      "name": "Rock_Volcanic_Brick_Roof_Shallow",
      "rotation": 3
    },
    {
      "x": -4,
      "y": 0,
      "z": -7,
      "name": "Rock_Volcanic_Brick"
    },
    {
      "x": -4,
      "y": 1,
      "z": -7,
      "name": "Rock_Volcanic_Brick"
    },
    {
      "x": -4,
      "y": 2,
      "z": -7,
      "name": "Rock_Volcanic_Brick_Ornate"
    },
    {
      "x": -4,
      "y": 3,
      "z": -7,
      "name": "Rock_Volcanic_Brick_Decorative"
    },
    {
      "x": -4,
      "y": 4,
      "z": -7,
      "name": "Rock_Volcanic_Brick_Smooth"
    },
    {
      "x": -4,
      "y": 5,
      "z": -7,
      "name": "Rock_Volcanic_Brick_Ornate"
    },
    {
      "x": -4,
      "y": 6,
      "z": -7,
      "name": "Rock_Crystal_White_Block",
      "rotation": 4
    },
    {
      "x": -4,
      "y": 7,
      "z": -7,
      "name": "Rock_Volcanic_Brick_Roof_Shallow",
      "rotation": 3
    },
    {
      "x": -4,
      "y": 0,
      "z": -6,
      "name": "Rock_Volcanic_Brick"
    },
    {
      "x": -4,
      "y": 1,
      "z": -6,
      "name": "Rock_Volcanic_Brick"
    },
    {
      "x": -4,
      "y": 2,
      "z": -6,
      "name": "Rock_Volcanic_Brick_Ornate"
    },
    {
      "x": -4,
      "y": 3,
      "z": -6,
      "name": "Rock_Volcanic_Brick_Decorative"
    },
    {
      "x": -4,
      "y": 4,
      "z": -6,
      "name": "Rock_Volcanic_Brick_Smooth"
    },
    {
      "x": -4,
      "y": 5,
      "z": -6,
      "name": "Rock_Volcanic_Brick_Ornate"
    },
    {
      "x": -4,
      "y": 6,
      "z": -6,
      "name": "Rock_Crystal_White_Block",
      "rotation": 4
    },
    {
      "x": -4,
      "y": 7,
      "z": -6,
      "name": "Rock_Volcanic_Brick_Roof_Shallow",
      "rotation": 3
    },
    {
      "x": -4,
      "y": 0,
      "z": -5,
      "name": "Rock_Volcanic_Brick"
    },
    {
      "x": -4,
      "y": 1,
      "z": -5,
      "name": "Rock_Volcanic_Brick"
    },
    {
      "x": -4,
      "y": 2,
      "z": -5,
      "name": "Rock_Volcanic_Brick_Ornate"
    },
    {
      "x": -4,
      "y": 3,
      "z": -5,
      "name": "Rock_Volcanic_Brick_Decorative"
    },
    {
      "x": -4,
      "y": 4,
      "z": -5,
      "name": "Rock_Volcanic_Brick_Smooth"
    },
    {
      "x": -4,
      "y": 5,
      "z": -5,
      "name": "Rock_Volcanic_Brick_Ornate"
    },
    {
      "x": -4,
      "y": 6,
      "z": -5,
      "name": "Rock_Crystal_White_Block",
      "rotation": 4
    },
    {
      "x": -4,
      "y": 7,
      "z": -5,
      "name": "Rock_Volcanic_Brick_Roof_Shallow",
      "rotation": 3
    },
    {
      "x": -4,
      "y": 0,
      "z": -4,
      "name": "Rock_Volcanic_Brick"
    },
    {
      "x": -4,
      "y": 1,
      "z": -4,
      "name": "Rock_Volcanic_Brick"
    },
    {
      "x": -4,
      "y": 2,
      "z": -4,
      "name": "Rock_Volcanic_Brick_Ornate"
    },
    {
      "x": -4,
      "y": 3,
      "z": -4,
      "name": "Rock_Volcanic_Brick_Decorative"
    },
    {
      "x": -4,
      "y": 4,
      "z": -4,
      "name": "Rock_Volcanic_Brick_Smooth"
    },
    {
      "x": -4,
      "y": 5,
      "z": -4,
      "name": "Rock_Volcanic_Brick_Ornate"
    },
    {
      "x": -4,
      "y": 6,
      "z": -4,
      "name": "Rock_Crystal_White_Block",
      "rotation": 4
    },
    {
      "x": -4,
      "y": 7,
      "z": -4,
      "name": "Rock_Volcanic_Brick_Roof_Shallow",
      "rotation": 3
    },
    {
      "x": -4,
      "y": 0,
      "z": -3,
      "name": "Rock_Volcanic_Brick"
    },
    {
      "x": -4,
      "y": 1,
      "z": -3,
      "name": "Rock_Volcanic_Brick"
    },
    {
      "x": -4,
      "y": 2,
      "z": -3,
      "name": "Rock_Volcanic_Brick_Ornate"
    },
    {
      "x": -4,
      "y": 3,
      "z": -3,
      "name": "Rock_Volcanic_Brick_Decorative"
    },
    {
      "x": -4,
      "y": 4,
      "z": -3,
      "name": "Rock_Volcanic_Brick_Smooth"
    },
    {
      "x": -4,
      "y": 5,
      "z": -3,
      "name": "Rock_Volcanic_Brick_Ornate"
    },
    {
      "x": -4,
      "y": 6,
      "z": -3,
      "name": "Rock_Crystal_White_Block",
      "rotation": 4
    },
    {
      "x": -4,
      "y": 7,
      "z": -3,
      "name": "Rock_Volcanic_Brick_Roof_Shallow",
      "rotation": 3
    },
    {
      "x": -4,
      "y": 0,
      "z": -2,
      "name": "Rock_Volcanic_Brick"
    },
    {
      "x": -4,
      "y": 1,
      "z": -2,
      "name": "Rock_Volcanic_Brick"
    },
    {
      "x": -4,
      "y": 2,
      "z": -2,
      "name": "Rock_Volcanic_Brick_Ornate"
    },
    {
      "x": -4,
      "y": 3,
      "z": -2,
      "name": "Rock_Volcanic_Brick_Decorative"
    },
    {
      "x": -4,
      "y": 4,
      "z": -2,
      "name": "Rock_Volcanic_Brick_Smooth"
    },
    {
      "x": -4,
      "y": 5,
      "z": -2,
      "name": "Rock_Volcanic_Brick_Ornate"
    },
    {
      "x": -4,
      "y": 6,
      "z": -2,
      "name": "Rock_Crystal_White_Block",
      "rotation": 4
    },
    {
      "x": -4,
      "y": 7,
      "z": -2,
      "name": "Rock_Volcanic_Brick_Roof_Shallow",
      "rotation": 3
    },
    {
      "x": -4,
      "y": 0,
      "z": -1,
      "name": "Rock_Volcanic_Brick"
    },
    {
      "x": -4,
      "y": 1,
      "z": -1,
      "name": "Rock_Volcanic_Brick"
    },
    {
      "x": -4,
      "y": 2,
      "z": -1,
      "name": "Rock_Volcanic_Brick_Ornate"
    },
    {
      "x": -4,
      "y": 3,
      "z": -1,
      "name": "Rock_Volcanic_Brick_Decorative"
    },
    {
      "x": -4,
      "y": 4,
      "z": -1,
      "name": "Rock_Volcanic_Brick_Smooth"
    },
    {
      "x": -4,
      "y": 5,
      "z": -1,
      "name": "Rock_Volcanic_Brick_Ornate"
    },
    {
      "x": -4,
      "y": 6,
      "z": -1,
      "name": "Rock_Crystal_White_Block",
      "rotation": 4
    },
    {
      "x": -4,
      "y": 7,
      "z": -1,
      "name": "Rock_Volcanic_Brick_Roof_Shallow",
      "rotation": 3
    },
    {
      "x": -4,
      "y": 0,
      "z": 0,
      "name": "Rock_Volcanic_Brick"
    },
    {
      "x": -4,
      "y": 1,
      "z": 0,
      "name": "Rock_Volcanic_Brick"
    },
    {
      "x": -4,
      "y": 2,
      "z": 0,
      "name": "Rock_Volcanic_Brick_Ornate"
    },
    {
      "x": -4,
      "y": 3,
      "z": 0,
      "name": "Rock_Volcanic_Brick_Decorative"
    },
    {
      "x": -4,
      "y": 4,
      "z": 0,
      "name": "Rock_Volcanic_Brick_Smooth"
    },
    {
      "x": -4,
      "y": 5,
      "z": 0,
      "name": "Rock_Volcanic_Brick_Ornate"
    },
    {
      "x": -4,
      "y": 6,
      "z": 0,
      "name": "Rock_Crystal_White_Block",
      "rotation": 4
    },
    {
      "x": -4,
      "y": 7,
      "z": 0,
      "name": "Rock_Volcanic_Brick_Roof_Shallow",
      "rotation": 3
    },
    {
      "x": -4,
      "y": 0,
      "z": 1,
      "name": "Rock_Volcanic_Brick"
    },
    {
      "x": -4,
      "y": 1,
      "z": 1,
      "name": "Rock_Volcanic_Brick"
    },
    {
      "x": -4,
      "y": 2,
      "z": 1,
      "name": "Rock_Volcanic_Brick_Ornate"
    },
    {
      "x": -4,
      "y": 3,
      "z": 1,
      "name": "Rock_Volcanic_Brick_Decorative"
    },
    {
      "x": -4,
      "y": 4,
      "z": 1,
      "name": "Rock_Volcanic_Brick_Smooth"
    },
    {
      "x": -4,
      "y": 5,
      "z": 1,
      "name": "Rock_Volcanic_Brick_Ornate"
    },
    {
      "x": -4,
      "y": 6,
      "z": 1,
      "name": "Rock_Crystal_White_Block",
      "rotation": 4
    },
    {
      "x": -4,
      "y": 7,
      "z": 1,
      "name": "Rock_Volcanic_Brick_Roof_Shallow",
      "rotation": 3
    },
    {
      "x": -4,
      "y": 0,
      "z": 2,
      "name": "Rock_Volcanic_Brick"
    },
    {
      "x": -4,
      "y": 1,
      "z": 2,
      "name": "Rock_Volcanic_Brick"
    },
    {
      "x": -4,
      "y": 2,
      "z": 2,
      "name": "Rock_Volcanic_Brick_Ornate"
    },
    {
      "x": -4,
      "y": 3,
      "z": 2,
      "name": "Rock_Volcanic_Brick_Decorative"
    },
    {
      "x": -4,
      "y": 4,
      "z": 2,
      "name": "Rock_Volcanic_Brick_Smooth"
    },
    {
      "x": -4,
      "y": 5,
      "z": 2,
      "name": "Rock_Volcanic_Brick_Ornate"
    },
    {
      "x": -4,
      "y": 6,
      "z": 2,
      "name": "Rock_Crystal_White_Block",
      "rotation": 4
    },
    {
      "x": -4,
      "y": 7,
      "z": 2,
      "name": "Rock_Volcanic_Brick_Roof_Shallow",
      "rotation": 3
    },
    {
      "x": -4,
      "y": 0,
      "z": 3,
      "name": "Rock_Volcanic_Brick"
    },
    {
      "x": -4,
      "y": 1,
      "z": 3,
      "name": "Rock_Volcanic_Brick"
    },
    {
      "x": -4,
      "y": 2,
      "z": 3,
      "name": "Rock_Volcanic_Brick_Ornate"
    },
    {
      "x": -4,
      "y": 3,
      "z": 3,
      "name": "Rock_Volcanic_Brick_Decorative"
    },
    {
      "x": -4,
      "y": 4,
      "z": 3,
      "name": "Rock_Volcanic_Brick_Smooth"
    },
    {
      "x": -4,
      "y": 5,
      "z": 3,
      "name": "Rock_Volcanic_Brick_Ornate"
    },
    {
      "x": -4,
      "y": 6,
      "z": 3,
      "name": "Rock_Crystal_White_Block",
      "rotation": 4
    },
    {
      "x": -4,
      "y": 7,
      "z": 3,
      "name": "Rock_Volcanic_Brick_Roof_Shallow",
      "rotation": 3
    },
    {
      "x": -4,
      "y": 0,
      "z": 4,
      "name": "Rock_Volcanic_Brick"
    },
    {
      "x": -4,
      "y": 1,
      "z": 4,
      "name": "Rock_Volcanic_Brick"
    },
    {
      "x": -4,
      "y": 2,
      "z": 4,
      "name": "Rock_Volcanic_Brick_Ornate"
    },
    {
      "x": -4,
      "y": 3,
      "z": 4,
      "name": "Rock_Volcanic_Brick_Decorative"
    },
    {
      "x": -4,
      "y": 4,
      "z": 4,
      "name": "Rock_Volcanic_Brick_Smooth"
    },
    {
      "x": -4,
      "y": 5,
      "z": 4,
      "name": "Rock_Volcanic_Brick_Ornate"
    },
    {
      "x": -4,
      "y": 6,
      "z": 4,
      "name": "Rock_Crystal_White_Block",
      "rotation": 4
    },
    {
      "x": -4,
      "y": 7,
      "z": 4,
      "name": "Rock_Volcanic_Brick_Roof_Shallow",
      "rotation": 3
    },
    {
      "x": -4,
      "y": 0,
      "z": 5,
      "name": "Rock_Volcanic_Brick"
    },
    {
      "x": -4,
      "y": 1,
      "z": 5,
      "name": "Rock_Volcanic_Brick"
    },
    {
      "x": -4,
      "y": 2,
      "z": 5,
      "name": "Rock_Volcanic_Brick_Ornate"
    },
    {
      "x": -4,
      "y": 3,
      "z": 5,
      "name": "Rock_Volcanic_Brick_Decorative"
    },
    {
      "x": -4,
      "y": 4,
      "z": 5,
      "name": "Rock_Volcanic_Brick_Smooth"
    },
    {
      "x": -4,
      "y": 5,
      "z": 5,
      "name": "Rock_Volcanic_Brick_Ornate"
    },
    {
      "x": -4,
      "y": 6,
      "z": 5,
      "name": "Rock_Crystal_White_Block",
      "rotation": 4
    },
    {
      "x": -4,
      "y": 7,
      "z": 5,
      "name": "Rock_Volcanic_Brick_Roof_Shallow",
      "rotation": 3
    },
    {
      "x": -4,
      "y": 0,
      "z": 6,
      "name": "Rock_Volcanic_Brick"
    },
    {
      "x": -4,
      "y": 1,
      "z": 6,
      "name": "Rock_Volcanic_Brick"
    },
    {
      "x": -4,
      "y": 2,
      "z": 6,
      "name": "Rock_Volcanic_Brick_Ornate"
    },
    {
      "x": -4,
      "y": 3,
      "z": 6,
      "name": "Rock_Volcanic_Brick_Decorative"
    },
    {
      "x": -4,
      "y": 4,
      "z": 6,
      "name": "Rock_Volcanic_Brick_Smooth"
    },
    {
      "x": -4,
      "y": 5,
      "z": 6,
      "name": "Rock_Volcanic_Brick_Ornate"
    },
    {
      "x": -4,
      "y": 6,
      "z": 6,
      "name": "Rock_Crystal_White_Block",
      "rotation": 4
    },
    {
      "x": -4,
      "y": 7,
      "z": 6,
      "name": "Rock_Volcanic_Brick_Roof_Shallow",
      "rotation": 3
    },
    {
      "x": -4,
      "y": 0,
      "z": 7,
      "name": "Rock_Volcanic_Brick"
    },
    {
      "x": -4,
      "y": 1,
      "z": 7,
      "name": "Rock_Volcanic_Brick"
    },
    {
      "x": -4,
      "y": 2,
      "z": 7,
      "name": "Rock_Volcanic_Brick_Ornate"
    },
    {
      "x": -4,
      "y": 3,
      "z": 7,
      "name": "Rock_Volcanic_Brick_Decorative"
    },
    {
      "x": -4,
      "y": 4,
      "z": 7,
      "name": "Rock_Volcanic_Brick_Smooth"
    },
    {
      "x": -4,
      "y": 5,
      "z": 7,
      "name": "Rock_Volcanic_Brick_Ornate"
    },
    {
      "x": -4,
      "y": 6,
      "z": 7,
      "name": "Rock_Crystal_White_Block",
      "rotation": 4
    },
    {
      "x": -4,
      "y": 7,
      "z": 7,
      "name": "Rock_Volcanic_Brick_Roof_Shallow",
      "rotation": 3
    },
    {
      "x": -4,
      "y": 0,
      "z": 8,
      "name": "Rock_Volcanic_Brick"
    },
    {
      "x": -4,
      "y": 1,
      "z": 8,
      "name": "Rock_Volcanic_Brick"
    },
    {
      "x": -4,
      "y": 2,
      "z": 8,
      "name": "Rock_Volcanic_Brick_Ornate"
    },
    {
      "x": -4,
      "y": 3,
      "z": 8,
      "name": "Rock_Volcanic_Brick_Decorative"
    },
    {
      "x": -4,
      "y": 4,
      "z": 8,
      "name": "Rock_Volcanic_Brick_Smooth"
    },
    {
      "x": -4,
      "y": 5,
      "z": 8,
      "name": "Rock_Volcanic_Brick_Ornate"
    },
    {
      "x": -4,
      "y": 6,
      "z": 8,
      "name": "Rock_Crystal_White_Block",
      "rotation": 4
    },
    {
      "x": -4,
      "y": 7,
      "z": 8,
      "name": "Rock_Volcanic_Brick_Roof_Shallow",
      "rotation": 3
    },
    {
      "x": -4,
      "y": 0,
      "z": 9,
      "name": "Rock_Volcanic_Brick"
    },
    {
      "x": -4,
      "y": 1,
      "z": 9,
      "name": "Rock_Volcanic_Brick"
    },
    {
      "x": -4,
      "y": 2,
      "z": 9,
      "name": "Rock_Volcanic_Brick_Ornate"
    },
    {
      "x": -4,
      "y": 3,
      "z": 9,
      "name": "Rock_Volcanic_Brick_Decorative"
    },
    {
      "x": -4,
      "y": 4,
      "z": 9,
      "name": "Rock_Volcanic_Brick_Smooth"
    },
    {
      "x": -4,
      "y": 5,
      "z": 9,
      "name": "Rock_Volcanic_Brick_Ornate"
    },
    {
      "x": -4,
      "y": 6,
      "z": 9,
      "name": "Rock_Crystal_White_Block",
      "rotation": 4
    },
    {
      "x": -4,
      "y": 7,
      "z": 9,
      "name": "Rock_Volcanic_Brick_Roof_Shallow",
      "rotation": 3
    },
    {
      "x": -4,
      "y": 0,
      "z": 10,
      "name": "Rock_Volcanic_Brick"
    },
    {
      "x": -4,
      "y": 1,
      "z": 10,
      "name": "Rock_Volcanic_Brick"
    },
    {
      "x": -4,
      "y": 2,
      "z": 10,
      "name": "Rock_Volcanic_Brick_Ornate"
    },
    {
      "x": -4,
      "y": 3,
      "z": 10,
      "name": "Rock_Volcanic_Brick_Decorative"
    },
    {
      "x": -4,
      "y": 4,
      "z": 10,
      "name": "Rock_Volcanic_Brick_Smooth"
    },
    {
      "x": -4,
      "y": 5,
      "z": 10,
      "name": "Rock_Volcanic_Brick_Ornate"
    },
    {
      "x": -4,
      "y": 6,
      "z": 10,
      "name": "Rock_Crystal_White_Block",
      "rotation": 4
    },
    {
      "x": -4,
      "y": 7,
      "z": 10,
      "name": "Rock_Volcanic_Brick_Roof_Shallow",
      "rotation": 3
    },
    {
      "x": -4,
      "y": 0,
      "z": 11,
      "name": "Rock_Volcanic_Brick"
    },
    {
      "x": -4,
      "y": 1,
      "z": 11,
      "name": "Rock_Volcanic_Brick"
    },
    {
      "x": -4,
      "y": 2,
      "z": 11,
      "name": "Rock_Volcanic_Brick_Ornate"
    },
    {
      "x": -4,
      "y": 3,
      "z": 11,
      "name": "Rock_Volcanic_Brick_Decorative"
    },
    {
      "x": -4,
      "y": 4,
      "z": 11,
      "name": "Rock_Volcanic_Brick_Smooth"
    },
    {
      "x": -4,
      "y": 5,
      "z": 11,
      "name": "Rock_Volcanic_Brick_Ornate"
    },
    {
      "x": -4,
      "y": 6,
      "z": 11,
      "name": "Rock_Crystal_White_Block"
    },
    {
      "x": -4,
      "y": 7,
      "z": 11,
      "name": "Rock_Volcanic_Brick_Roof_Shallow",
      "rotation": 3
    },
    {
      "x": -4,
      "y": 0,
      "z": 12,
      "name": "Rock_Volcanic_Brick"
    },
    {
      "x": -4,
      "y": 1,
      "z": 12,
      "name": "Rock_Volcanic_Brick"
    },
    {
      "x": -4,
      "y": 2,
      "z": 12,
      "name": "Rock_Volcanic_Brick_Ornate"
    },
    {
      "x": -4,
      "y": 3,
      "z": 12,
      "name": "Rock_Volcanic_Brick_Decorative"
    },
    {
      "x": -4,
      "y": 4,
      "z": 12,
      "name": "Rock_Volcanic_Brick_Decorative"
    },
    {
      "x": -4,
      "y": 5,
      "z": 12,
      "name": "Rock_Volcanic_Brick_Ornate"
    },
    {
      "x": -4,
      "y": 6,
      "z": 12,
      "name": "Rock_Crystal_White_Block"
    },
    {
      "x": -4,
      "y": 7,
      "z": 12,
      "name": "Rock_Volcanic_Brick_Roof_Flat"
    },
    {
      "x": -4,
      "y": 0,
      "z": 13,
      "name": "Rock_Volcanic_Brick"
    },
    {
      "x": -4,
      "y": 1,
      "z": 13,
      "name": "Rock_Volcanic_Brick"
    },
    {
      "x": -4,
      "y": 2,
      "z": 13,
      "name": "Rock_Volcanic_Brick_Ornate"
    },
    {
      "x": -4,
      "y": 3,
      "z": 13,
      "name": "Rock_Volcanic_Brick_Decorative"
    },
    {
      "x": -4,
      "y": 4,
      "z": 13,
      "name": "Rock_Volcanic_Brick_Decorative"
    },
    {
      "x": -4,
      "y": 5,
      "z": 13,
      "name": "Rock_Volcanic_Brick_Ornate"
    },
    {
      "x": -4,
      "y": 6,
      "z": 13,
      "name": "Rock_Volcanic_Brick_Ornate"
    },
    {
      "x": -4,
      "y": 0,
      "z": 14,
      "name": "Rock_Volcanic_Brick"
    },
    {
      "x": -4,
      "y": 6,
      "z": 14,
      "name": "Rock_Volcanic_Brick_Roof_Shallow",
      "filler": 992
    },
    {
      "x": -4,
      "y": 0,
      "z": 15,
      "name": "Rock_Volcanic_Brick"
    },
    {
      "x": -4,
      "y": 6,
      "z": 15,
      "name": "Rock_Volcanic_Brick_Roof_Shallow"
    },
    {
      "x": -3,
      "y": 0,
      "z": -13,
      "name": "Rock_Volcanic_Brick"
    },
    {
      "x": -3,
      "y": 6,
      "z": -13,
      "name": "Rock_Volcanic_Brick_Roof_Shallow",
      "rotation": 2
    },
    {
      "x": -3,
      "y": 0,
      "z": -12,
      "name": "Rock_Volcanic_Brick"
    },
    {
      "x": -3,
      "y": 6,
      "z": -12,
      "name": "Rock_Volcanic_Brick_Roof_Shallow",
      "filler": 32,
      "rotation": 2
    },
    {
      "x": -3,
      "y": 0,
      "z": -11,
      "name": "Rock_Volcanic_Brick"
    },
    {
      "x": -3,
      "y": 1,
      "z": -11,
      "name": "Rock_Volcanic_Brick"
    },
    {
      "x": -3,
      "y": 2,
      "z": -11,
      "name": "Rock_Volcanic_Brick_Ornate"
    },
    {
      "x": -3,
      "y": 3,
      "z": -11,
      "name": "Rock_Volcanic_Brick_Decorative"
    },
    {
      "x": -3,
      "y": 4,
      "z": -11,
      "name": "Rock_Volcanic_Brick_Smooth"
    },
    {
      "x": -3,
      "y": 5,
      "z": -11,
      "name": "Rock_Volcanic_Brick_Ornate"
    },
    {
      "x": -3,
      "y": 6,
      "z": -11,
      "name": "Rock_Crystal_White_Block",
      "rotation": 5
    },
    {
      "x": -3,
      "y": 7,
      "z": -11,
      "name": "Rock_Volcanic_Brick_Roof_Flat",
      "rotation": 3
    },
    {
      "x": -3,
      "y": 0,
      "z": -10,
      "name": "Rock_Volcanic_Brick"
    },
    {
      "x": -3,
      "y": 1,
      "z": -10,
      "name": "Rock_Crystal_White_Block"
    },
    {
      "x": -3,
      "y": 2,
      "z": -10,
      "name": "Rock_Crystal_White_Block"
    },
    {
      "x": -3,
      "y": 3,
      "z": -10,
      "name": "Rock_Crystal_White_Block",
      "rotation": 4
    },
    {
      "x": -3,
      "y": 4,
      "z": -10,
      "name": "Furniture_Temple_Dark_Platform",
      "rotation": 1
    },
    {
      "x": -3,
      "y": 7,
      "z": -10,
      "name": "Rock_Volcanic_Brick_Smooth_Half"
    },
    {
      "x": -3,
      "y": 0,
      "z": -9,
      "name": "Rock_Volcanic_Brick"
    },
    {
      "x": -3,
      "y": 1,
      "z": -9,
      "name": "Furniture_Human_Ruins_Bookshelf",
      "rotation": 1
    },
    {
      "x": -3,
      "y": 2,
      "z": -9,
      "name": "Furniture_Human_Ruins_Bookshelf",
      "rotation": 1
    },
    {
      "x": -3,
      "y": 3,
      "z": -9,
      "name": "Furniture_Human_Ruins_Bookshelf",
      "rotation": 1
    },
    {
      "x": -3,
      "y": 4,
      "z": -9,
      "name": "Furniture_Temple_Dark_Platform",
      "rotation": 1
    },
    {
      "x": -3,
      "y": 7,
      "z": -9,
      "name": "Rock_Volcanic_Brick_Roof_Shallow",
      "filler": 1,
      "rotation": 3
    },
    {
      "x": -3,
      "y": 0,
      "z": -8,
      "name": "Rock_Volcanic_Brick"
    },
    {
      "x": -3,
      "y": 1,
      "z": -8,
      "name": "Furniture_Human_Ruins_Bookshelf",
      "rotation": 1
    },
    {
      "x": -3,
      "y": 2,
      "z": -8,
      "name": "Furniture_Human_Ruins_Bookshelf",
      "rotation": 1
    },
    {
      "x": -3,
      "y": 3,
      "z": -8,
      "name": "Furniture_Human_Ruins_Bookshelf",
      "rotation": 1
    },
    {
      "x": -3,
      "y": 4,
      "z": -8,
      "name": "Furniture_Temple_Dark_Platform",
      "rotation": 1
    },
    {
      "x": -3,
      "y": 7,
      "z": -8,
      "name": "Rock_Volcanic_Brick_Roof_Shallow",
      "filler": 1,
      "rotation": 3
    },
    {
      "x": -3,
      "y": 0,
      "z": -7,
      "name": "Rock_Volcanic_Brick"
    },
    {
      "x": -3,
      "y": 1,
      "z": -7,
      "name": "Furniture_Human_Ruins_Bookshelf",
      "rotation": 1
    },
    {
      "x": -3,
      "y": 2,
      "z": -7,
      "name": "Furniture_Human_Ruins_Bookshelf",
      "rotation": 1
    },
    {
      "x": -3,
      "y": 3,
      "z": -7,
      "name": "Furniture_Human_Ruins_Bookshelf",
      "rotation": 1
    },
    {
      "x": -3,
      "y": 4,
      "z": -7,
      "name": "Furniture_Temple_Dark_Platform",
      "rotation": 1
    },
    {
      "x": -3,
      "y": 7,
      "z": -7,
      "name": "Rock_Volcanic_Brick_Roof_Shallow",
      "filler": 1,
      "rotation": 3
    },
    {
      "x": -3,
      "y": 0,
      "z": -6,
      "name": "Rock_Volcanic_Brick"
    },
    {
      "x": -3,
      "y": 1,
      "z": -6,
      "name": "Furniture_Human_Ruins_Bookshelf",
      "rotation": 1
    },
    {
      "x": -3,
      "y": 2,
      "z": -6,
      "name": "Furniture_Human_Ruins_Bookshelf",
      "rotation": 1
    },
    {
      "x": -3,
      "y": 3,
      "z": -6,
      "name": "Furniture_Human_Ruins_Bookshelf",
      "rotation": 1
    },
    {
      "x": -3,
      "y": 4,
      "z": -6,
      "name": "Furniture_Temple_Dark_Platform",
      "rotation": 1
    },
    {
      "x": -3,
      "y": 7,
      "z": -6,
      "name": "Rock_Volcanic_Brick_Roof_Shallow",
      "filler": 1,
      "rotation": 3
    },
    {
      "x": -3,
      "y": 0,
      "z": -5,
      "name": "Rock_Volcanic_Brick"
    },
    {
      "x": -3,
      "y": 1,
      "z": -5,
      "name": "Furniture_Human_Ruins_Bookshelf",
      "rotation": 1
    },
    {
      "x": -3,
      "y": 2,
      "z": -5,
      "name": "Furniture_Human_Ruins_Bookshelf",
      "rotation": 1
    },
    {
      "x": -3,
      "y": 3,
      "z": -5,
      "name": "Furniture_Human_Ruins_Bookshelf",
      "rotation": 1
    },
    {
      "x": -3,
      "y": 4,
      "z": -5,
      "name": "Furniture_Temple_Dark_Platform",
      "rotation": 1
    },
    {
      "x": -3,
      "y": 7,
      "z": -5,
      "name": "Rock_Volcanic_Brick_Roof_Shallow",
      "filler": 1,
      "rotation": 3
    },
    {
      "x": -3,
      "y": 0,
      "z": -4,
      "name": "Rock_Volcanic_Brick"
    },
    {
      "x": -3,
      "y": 1,
      "z": -4,
      "name": "Furniture_Human_Ruins_Bookshelf",
      "rotation": 1
    },
    {
      "x": -3,
      "y": 2,
      "z": -4,
      "name": "Furniture_Human_Ruins_Bookshelf",
      "rotation": 1
    },
    {
      "x": -3,
      "y": 3,
      "z": -4,
      "name": "Furniture_Human_Ruins_Bookshelf",
      "rotation": 1
    },
    {
      "x": -3,
      "y": 4,
      "z": -4,
      "name": "Furniture_Temple_Dark_Platform",
      "rotation": 1
    },
    {
      "x": -3,
      "y": 7,
      "z": -4,
      "name": "Rock_Volcanic_Brick_Roof_Shallow",
      "filler": 1,
      "rotation": 3
    },
    {
      "x": -3,
      "y": 0,
      "z": -3,
      "name": "Rock_Volcanic_Brick"
    },
    {
      "x": -3,
      "y": 1,
      "z": -3,
      "name": "Furniture_Human_Ruins_Bookshelf",
      "rotation": 1
    },
    {
      "x": -3,
      "y": 2,
      "z": -3,
      "name": "Furniture_Human_Ruins_Bookshelf",
      "rotation": 1
    },
    {
      "x": -3,
      "y": 3,
      "z": -3,
      "name": "Furniture_Human_Ruins_Bookshelf",
      "rotation": 1
    },
    {
      "x": -3,
      "y": 4,
      "z": -3,
      "name": "Furniture_Temple_Dark_Platform",
      "rotation": 1
    },
    {
      "x": -3,
      "y": 7,
      "z": -3,
      "name": "Rock_Volcanic_Brick_Roof_Shallow",
      "filler": 1,
      "rotation": 3
    },
    {
      "x": -3,
      "y": 0,
      "z": -2,
      "name": "Rock_Volcanic_Brick"
    },
    {
      "x": -3,
      "y": 1,
      "z": -2,
      "name": "Furniture_Human_Ruins_Bookshelf",
      "rotation": 1
    },
    {
      "x": -3,
      "y": 2,
      "z": -2,
      "name": "Furniture_Human_Ruins_Bookshelf",
      "rotation": 1
    },
    {
      "x": -3,
      "y": 3,
      "z": -2,
      "name": "Furniture_Human_Ruins_Bookshelf",
      "rotation": 1
    },
    {
      "x": -3,
      "y": 4,
      "z": -2,
      "name": "Furniture_Temple_Dark_Platform",
      "rotation": 1
    },
    {
      "x": -3,
      "y": 7,
      "z": -2,
      "name": "Rock_Volcanic_Brick_Roof_Shallow",
      "filler": 1,
      "rotation": 3
    },
    {
      "x": -3,
      "y": 0,
      "z": -1,
      "name": "Rock_Volcanic_Brick"
    },
    {
      "x": -3,
      "y": 1,
      "z": -1,
      "name": "Furniture_Human_Ruins_Bookshelf",
      "rotation": 1
    },
    {
      "x": -3,
      "y": 2,
      "z": -1,
      "name": "Furniture_Human_Ruins_Bookshelf",
      "rotation": 1
    },
    {
      "x": -3,
      "y": 3,
      "z": -1,
      "name": "Furniture_Human_Ruins_Bookshelf",
      "rotation": 1
    },
    {
      "x": -3,
      "y": 4,
      "z": -1,
      "name": "Furniture_Temple_Dark_Platform",
      "rotation": 1
    },
    {
      "x": -3,
      "y": 7,
      "z": -1,
      "name": "Rock_Volcanic_Brick_Roof_Shallow",
      "filler": 1,
      "rotation": 3
    },
    {
      "x": -3,
      "y": 0,
      "z": 0,
      "name": "Rock_Volcanic_Brick"
    },
    {
      "x": -3,
      "y": 1,
      "z": 0,
      "name": "Furniture_Human_Ruins_Bookshelf",
      "rotation": 1
    },
    {
      "x": -3,
      "y": 2,
      "z": 0,
      "name": "Furniture_Human_Ruins_Bookshelf",
      "rotation": 1
    },
    {
      "x": -3,
      "y": 3,
      "z": 0,
      "name": "Furniture_Human_Ruins_Bookshelf",
      "rotation": 1
    },
    {
      "x": -3,
      "y": 4,
      "z": 0,
      "name": "Furniture_Temple_Dark_Platform",
      "rotation": 1
    },
    {
      "x": -3,
      "y": 7,
      "z": 0,
      "name": "Rock_Volcanic_Brick_Roof_Shallow",
      "filler": 1,
      "rotation": 3
    },
    {
      "x": -3,
      "y": 0,
      "z": 1,
      "name": "Rock_Volcanic_Brick"
    },
    {
      "x": -3,
      "y": 1,
      "z": 1,
      "name": "Furniture_Human_Ruins_Bookshelf",
      "rotation": 1
    },
    {
      "x": -3,
      "y": 2,
      "z": 1,
      "name": "Furniture_Human_Ruins_Bookshelf",
      "rotation": 1
    },
    {
      "x": -3,
      "y": 3,
      "z": 1,
      "name": "Furniture_Human_Ruins_Bookshelf",
      "rotation": 1
    },
    {
      "x": -3,
      "y": 4,
      "z": 1,
      "name": "Furniture_Temple_Dark_Platform",
      "rotation": 1
    },
    {
      "x": -3,
      "y": 7,
      "z": 1,
      "name": "Rock_Volcanic_Brick_Roof_Shallow",
      "filler": 1,
      "rotation": 3
    },
    {
      "x": -3,
      "y": 0,
      "z": 2,
      "name": "Rock_Volcanic_Brick"
    },
    {
      "x": -3,
      "y": 1,
      "z": 2,
      "name": "Furniture_Human_Ruins_Bookshelf",
      "rotation": 1
    },
    {
      "x": -3,
      "y": 2,
      "z": 2,
      "name": "Furniture_Human_Ruins_Bookshelf",
      "rotation": 1
    },
    {
      "x": -3,
      "y": 3,
      "z": 2,
      "name": "Furniture_Human_Ruins_Bookshelf",
      "rotation": 1
    },
    {
      "x": -3,
      "y": 4,
      "z": 2,
      "name": "Furniture_Temple_Dark_Platform",
      "rotation": 1
    },
    {
      "x": -3,
      "y": 7,
      "z": 2,
      "name": "Rock_Volcanic_Brick_Roof_Shallow",
      "filler": 1,
      "rotation": 3
    },
    {
      "x": -3,
      "y": 0,
      "z": 3,
      "name": "Rock_Volcanic_Brick"
    },
    {
      "x": -3,
      "y": 1,
      "z": 3,
      "name": "Furniture_Human_Ruins_Bookshelf",
      "rotation": 1
    },
    {
      "x": -3,
      "y": 2,
      "z": 3,
      "name": "Furniture_Human_Ruins_Bookshelf",
      "rotation": 1
    },
    {
      "x": -3,
      "y": 3,
      "z": 3,
      "name": "Furniture_Human_Ruins_Bookshelf",
      "rotation": 1
    },
    {
      "x": -3,
      "y": 4,
      "z": 3,
      "name": "Furniture_Temple_Dark_Platform",
      "rotation": 1
    },
    {
      "x": -3,
      "y": 7,
      "z": 3,
      "name": "Rock_Volcanic_Brick_Roof_Shallow",
      "filler": 1,
      "rotation": 3
    },
    {
      "x": -3,
      "y": 0,
      "z": 4,
      "name": "Rock_Volcanic_Brick"
    },
    {
      "x": -3,
      "y": 1,
      "z": 4,
      "name": "Furniture_Human_Ruins_Bookshelf",
      "rotation": 1
    },
    {
      "x": -3,
      "y": 2,
      "z": 4,
      "name": "Furniture_Human_Ruins_Bookshelf",
      "rotation": 1
    },
    {
      "x": -3,
      "y": 3,
      "z": 4,
      "name": "Furniture_Human_Ruins_Bookshelf",
      "rotation": 1
    },
    {
      "x": -3,
      "y": 4,
      "z": 4,
      "name": "Furniture_Temple_Dark_Platform",
      "rotation": 1
    },
    {
      "x": -3,
      "y": 7,
      "z": 4,
      "name": "Rock_Volcanic_Brick_Roof_Shallow",
      "filler": 1,
      "rotation": 3
    },
    {
      "x": -3,
      "y": 0,
      "z": 5,
      "name": "Rock_Volcanic_Brick"
    },
    {
      "x": -3,
      "y": 1,
      "z": 5,
      "name": "Furniture_Human_Ruins_Bookshelf",
      "rotation": 1
    },
    {
      "x": -3,
      "y": 2,
      "z": 5,
      "name": "Furniture_Human_Ruins_Bookshelf",
      "rotation": 1
    },
    {
      "x": -3,
      "y": 3,
      "z": 5,
      "name": "Furniture_Human_Ruins_Bookshelf",
      "rotation": 1
    },
    {
      "x": -3,
      "y": 4,
      "z": 5,
      "name": "Furniture_Temple_Dark_Platform",
      "rotation": 1
    },
    {
      "x": -3,
      "y": 7,
      "z": 5,
      "name": "Rock_Volcanic_Brick_Roof_Shallow",
      "filler": 1,
      "rotation": 3
    },
    {
      "x": -3,
      "y": 0,
      "z": 6,
      "name": "Rock_Volcanic_Brick"
    },
    {
      "x": -3,
      "y": 1,
      "z": 6,
      "name": "Furniture_Human_Ruins_Bookshelf",
      "rotation": 1
    },
    {
      "x": -3,
      "y": 2,
      "z": 6,
      "name": "Furniture_Human_Ruins_Bookshelf",
      "rotation": 1
    },
    {
      "x": -3,
      "y": 3,
      "z": 6,
      "name": "Furniture_Human_Ruins_Bookshelf",
      "rotation": 1
    },
    {
      "x": -3,
      "y": 4,
      "z": 6,
      "name": "Furniture_Temple_Dark_Platform",
      "rotation": 1
    },
    {
      "x": -3,
      "y": 7,
      "z": 6,
      "name": "Rock_Volcanic_Brick_Roof_Shallow",
      "filler": 1,
      "rotation": 3
    },
    {
      "x": -3,
      "y": 0,
      "z": 7,
      "name": "Rock_Volcanic_Brick"
    },
    {
      "x": -3,
      "y": 1,
      "z": 7,
      "name": "Rock_Crystal_White_Block",
      "rotation": 5
    },
    {
      "x": -3,
      "y": 2,
      "z": 7,
      "name": "Rock_Crystal_White_Block"
    },
    {
      "x": -3,
      "y": 3,
      "z": 7,
      "name": "Rock_Crystal_White_Block",
      "rotation": 5
    },
    {
      "x": -3,
      "y": 4,
      "z": 7,
      "name": "Furniture_Temple_Dark_Platform",
      "rotation": 1
    },
    {
      "x": -3,
      "y": 7,
      "z": 7,
      "name": "Rock_Volcanic_Brick_Roof_Shallow",
      "filler": 1,
      "rotation": 3
    },
    {
      "x": -3,
      "y": 0,
      "z": 8,
      "name": "Rock_Volcanic_Brick"
    },
    {
      "x": -3,
      "y": 1,
      "z": 8,
      "name": "Rock_Volcanic_Brick"
    },
    {
      "x": -3,
      "y": 2,
      "z": 8,
      "name": "Rock_Volcanic_Brick_Ornate"
    },
    {
      "x": -3,
      "y": 3,
      "z": 8,
      "name": "Rock_Volcanic_Brick_Decorative"
    },
    {
      "x": -3,
      "y": 4,
      "z": 8,
      "name": "Rock_Volcanic_Brick_Smooth"
    },
    {
      "x": -3,
      "y": 5,
      "z": 8,
      "name": "Rock_Volcanic_Brick_Ornate"
    },
    {
      "x": -3,
      "y": 6,
      "z": 8,
      "name": "Rock_Crystal_White_Block",
      "rotation": 5
    },
    {
      "x": -3,
      "y": 7,
      "z": 8,
      "name": "Rock_Volcanic_Brick_Roof_Shallow",
      "filler": 1,
      "rotation": 3
    },
    {
      "x": -3,
      "y": 0,
      "z": 9,
      "name": "Rock_Volcanic_Brick"
    },
    {
      "x": -3,
      "y": 7,
      "z": 9,
      "name": "Rock_Volcanic_Brick_Roof_Shallow",
      "filler": 1,
      "rotation": 3
    },
    {
      "x": -3,
      "y": 0,
      "z": 10,
      "name": "Rock_Volcanic_Brick"
    },
    {
      "x": -3,
      "y": 4,
      "z": 10,
      "name": "Furniture_Temple_Dark_Platform",
      "rotation": 1
    },
    {
      "x": -3,
      "y": 7,
      "z": 10,
      "name": "Rock_Volcanic_Brick_Roof_Shallow",
      "filler": 1,
      "rotation": 3
    },
    {
      "x": -3,
      "y": 0,
      "z": 11,
      "name": "Rock_Volcanic_Brick"
    },
    {
      "x": -3,
      "y": 4,
      "z": 11,
      "name": "Furniture_Temple_Dark_Platform",
      "rotation": 1
    },
    {
      "x": -3,
      "y": 7,
      "z": 11,
      "name": "Rock_Volcanic_Brick_Roof_Shallow",
      "filler": 1,
      "rotation": 3
    },
    {
      "x": -3,
      "y": 0,
      "z": 12,
      "name": "Rock_Volcanic_Brick"
    },
    {
      "x": -3,
      "y": 1,
      "z": 12,
      "name": "Rock_Crystal_White_Block",
      "rotation": 5
    },
    {
      "x": -3,
      "y": 2,
      "z": 12,
      "name": "Rock_Crystal_White_Block",
      "rotation": 5
    },
    {
      "x": -3,
      "y": 3,
      "z": 12,
      "name": "Rock_Crystal_White_Block",
      "rotation": 5
    },
    {
      "x": -3,
      "y": 4,
      "z": 12,
      "name": "Furniture_Temple_Dark_Platform",
      "rotation": 1
    },
    {
      "x": -3,
      "y": 7,
      "z": 12,
      "name": "Rock_Volcanic_Brick_Smooth_Half"
    },
    {
      "x": -3,
      "y": 0,
      "z": 13,
      "name": "Rock_Volcanic_Brick"
    },
    {
      "x": -3,
      "y": 1,
      "z": 13,
      "name": "Rock_Volcanic_Brick"
    },
    {
      "x": -3,
      "y": 2,
      "z": 13,
      "name": "Rock_Volcanic_Brick_Ornate"
    },
    {
      "x": -3,
      "y": 3,
      "z": 13,
      "name": "Rock_Volcanic_Brick_Decorative"
    },
    {
      "x": -3,
      "y": 4,
      "z": 13,
      "name": "Rock_Volcanic_Brick_Decorative"
    },
    {
      "x": -3,
      "y": 5,
      "z": 13,
      "name": "Rock_Volcanic_Brick_Ornate"
    },
    {
      "x": -3,
      "y": 6,
      "z": 13,
      "name": "Rock_Crystal_White_Block"
    },
    {
      "x": -3,
      "y": 7,
      "z": 13,
      "name": "Rock_Volcanic_Brick_Roof_Flat",
      "rotation": 1
    },
    {
      "x": -3,
      "y": 0,
      "z": 14,
      "name": "Rock_Volcanic_Brick"
    },
    {
      "x": -3,
      "y": 6,
      "z": 14,
      "name": "Rock_Volcanic_Brick_Roof_Shallow",
      "filler": 992
    },
    {
      "x": -3,
      "y": 0,
      "z": 15,
      "name": "Rock_Volcanic_Brick"
    },
    {
      "x": -3,
      "y": 6,
      "z": 15,
      "name": "Rock_Volcanic_Brick_Roof_Shallow"
    },
    {
      "x": -2,
      "y": 0,
      "z": -15,
      "name": "Rock_Volcanic_Brick"
    },
    {
      "x": -2,
      "y": 1,
      "z": -15,
      "name": "Furniture_Human_Ruins_Brazier"
    },
    {
      "x": -2,
      "y": 0,
      "z": -14,
      "name": "Rock_Volcanic_Brick"
    },
    {
      "x": -2,
      "y": 1,
      "z": -14,
      "name": "Furniture_Village_Statue",
      "rotation": 2
    },
    {
      "x": -2,
      "y": 2,
      "z": -14,
      "name": "Furniture_Village_Statue",
      "filler": 1024,
      "rotation": 2
    },
    {
      "x": -2,
      "y": 3,
      "z": -14,
      "name": "Furniture_Village_Statue",
      "filler": 2048,
      "rotation": 2
    },
    {
      "x": -2,
      "y": 0,
      "z": -13,
      "name": "Rock_Volcanic_Brick"
    },
    {
      "x": -2,
      "y": 1,
      "z": -13,
      "name": "Rock_Volcanic_Brick_Pillar_Base"
    },
    {
      "x": -2,
      "y": 2,
      "z": -13,
      "name": "Rock_Volcanic_Brick_Pillar_Middle"
    },
    {
      "x": -2,
      "y": 3,
      "z": -13,
      "name": "Rock_Volcanic_Brick_Pillar_Middle"
    },
    {
      "x": -2,
      "y": 4,
      "z": -13,
      "name": "Rock_Volcanic_Brick_Pillar_Middle"
    },
    {
      "x": -2,
      "y": 5,
      "z": -13,
      "name": "Rock_Volcanic_Brick_Pillar_Base",
      "rotation": 8
    },
    {
      "x": -2,
      "y": 6,
      "z": -13,
      "name": "Rock_Volcanic_Brick_Roof_Shallow",
      "rotation": 2
    },
    {
      "x": -2,
      "y": 0,
      "z": -12,
      "name": "Rock_Volcanic_Brick"
    },
    {
      "x": -2,
      "y": 6,
      "z": -12,
      "name": "Rock_Volcanic_Brick_Roof_Shallow",
      "filler": 32,
      "rotation": 2
    },
    {
      "x": -2,
      "y": 0,
      "z": -11,
      "name": "Rock_Volcanic_Brick"
    },
    {
      "x": -2,
      "y": 1,
      "z": -11,
      "name": "Rock_Volcanic_Brick"
    },
    {
      "x": -2,
      "y": 2,
      "z": -11,
      "name": "Rock_Volcanic_Brick_Ornate"
    },
    {
      "x": -2,
      "y": 3,
      "z": -11,
      "name": "Rock_Volcanic_Brick_Decorative"
    },
    {
      "x": -2,
      "y": 4,
      "z": -11,
      "name": "Rock_Volcanic_Brick_Smooth"
    },
    {
      "x": -2,
      "y": 5,
      "z": -11,
      "name": "Rock_Volcanic_Brick_Ornate"
    },
    {
      "x": -2,
      "y": 6,
      "z": -11,
      "name": "Rock_Crystal_White_Block",
      "rotation": 5
    },
    {
      "x": -2,
      "y": 7,
      "z": -11,
      "name": "Rock_Volcanic_Brick_Roof_Shallow",
      "rotation": 2
    },
    {
      "x": -2,
      "y": 0,
      "z": -10,
      "name": "Rock_Volcanic_Brick"
    },
    {
      "x": -2,
      "y": 1,
      "z": -10,
      "name": "Furniture_Human_Ruins_Bookshelf"
    },
    {
      "x": -2,
      "y": 2,
      "z": -10,
      "name": "Furniture_Human_Ruins_Bookshelf"
    },
    {
      "x": -2,
      "y": 3,
      "z": -10,
      "name": "Furniture_Human_Ruins_Bookshelf"
    },
    {
      "x": -2,
      "y": 7,
      "z": -10,
      "name": "Rock_Volcanic_Brick_Roof_Shallow",
      "filler": 32,
      "rotation": 2
    },
    {
      "x": -2,
      "y": 0,
      "z": -9,
      "name": "Rock_Volcanic_Brick"
    },
    {
      "x": -2,
      "y": 8,
      "z": -9,
      "name": "Rock_Volcanic_Brick_Smooth_Half"
    },
    {
      "x": -2,
      "y": 0,
      "z": -8,
      "name": "Rock_Volcanic_Brick"
    },
    {
      "x": -2,
      "y": 8,
      "z": -8,
      "name": "Rock_Volcanic_Brick_Smooth_Half"
    },
    {
      "x": -2,
      "y": 0,
      "z": -7,
      "name": "Rock_Volcanic_Brick"
    },
    {
      "x": -2,
      "y": 8,
      "z": -7,
      "name": "Rock_Volcanic_Brick_Smooth_Half"
    },
    {
      "x": -2,
      "y": 0,
      "z": -6,
      "name": "Rock_Volcanic_Brick"
    },
    {
      "x": -2,
      "y": 8,
      "z": -6,
      "name": "Rock_Volcanic_Brick_Smooth_Half"
    },
    {
      "x": -2,
      "y": 0,
      "z": -5,
      "name": "Rock_Volcanic_Brick"
    },
    {
      "x": -2,
      "y": 8,
      "z": -5,
      "name": "Rock_Volcanic_Brick_Smooth_Half"
    },
    {
      "x": -2,
      "y": 0,
      "z": -4,
      "name": "Rock_Volcanic_Brick"
    },
    {
      "x": -2,
      "y": 8,
      "z": -4,
      "name": "Rock_Volcanic_Brick_Smooth_Half"
    },
    {
      "x": -2,
      "y": 0,
      "z": -3,
      "name": "Rock_Volcanic_Brick"
    },
    {
      "x": -2,
      "y": 8,
      "z": -3,
      "name": "Rock_Volcanic_Brick_Smooth_Half"
    },
    {
      "x": -2,
      "y": 0,
      "z": -2,
      "name": "Rock_Volcanic_Brick"
    },
    {
      "x": -2,
      "y": 8,
      "z": -2,
      "name": "Rock_Volcanic_Brick_Smooth_Half"
    },
    {
      "x": -2,
      "y": 0,
      "z": -1,
      "name": "Rock_Volcanic_Brick"
    },
    {
      "x": -2,
      "y": 8,
      "z": -1,
      "name": "Rock_Volcanic_Brick_Smooth_Half"
    },
    {
      "x": -2,
      "y": 0,
      "z": 0,
      "name": "Rock_Volcanic_Brick"
    },
    {
      "x": -2,
      "y": 8,
      "z": 0,
      "name": "Rock_Volcanic_Brick_Smooth_Half"
    },
    {
      "x": -2,
      "y": 0,
      "z": 1,
      "name": "Rock_Volcanic_Brick"
    },
    {
      "x": -2,
      "y": 8,
      "z": 1,
      "name": "Rock_Volcanic_Brick_Smooth_Half"
    },
    {
      "x": -2,
      "y": 0,
      "z": 2,
      "name": "Rock_Volcanic_Brick"
    },
    {
      "x": -2,
      "y": 8,
      "z": 2,
      "name": "Rock_Volcanic_Brick_Smooth_Half"
    },
    {
      "x": -2,
      "y": 0,
      "z": 3,
      "name": "Rock_Volcanic_Brick"
    },
    {
      "x": -2,
      "y": 8,
      "z": 3,
      "name": "Rock_Volcanic_Brick_Smooth_Half"
    },
    {
      "x": -2,
      "y": 0,
      "z": 4,
      "name": "Rock_Volcanic_Brick"
    },
    {
      "x": -2,
      "y": 8,
      "z": 4,
      "name": "Rock_Volcanic_Brick_Smooth_Half"
    },
    {
      "x": -2,
      "y": 0,
      "z": 5,
      "name": "Rock_Volcanic_Brick"
    },
    {
      "x": -2,
      "y": 8,
      "z": 5,
      "name": "Rock_Volcanic_Brick_Smooth_Half"
    },
    {
      "x": -2,
      "y": 0,
      "z": 6,
      "name": "Rock_Volcanic_Brick"
    },
    {
      "x": -2,
      "y": 8,
      "z": 6,
      "name": "Rock_Volcanic_Brick_Smooth_Half"
    },
    {
      "x": -2,
      "y": 0,
      "z": 7,
      "name": "Rock_Volcanic_Brick"
    },
    {
      "x": -2,
      "y": 1,
      "z": 7,
      "name": "Furniture_Human_Ruins_Bookshelf",
      "rotation": 2
    },
    {
      "x": -2,
      "y": 2,
      "z": 7,
      "name": "Furniture_Human_Ruins_Bookshelf",
      "rotation": 2
    },
    {
      "x": -2,
      "y": 3,
      "z": 7,
      "name": "Furniture_Human_Ruins_Bookshelf",
      "rotation": 2
    },
    {
      "x": -2,
      "y": 8,
      "z": 7,
      "name": "Rock_Volcanic_Brick_Smooth_Half"
    },
    {
      "x": -2,
      "y": 0,
      "z": 8,
      "name": "Rock_Volcanic_Brick"
    },
    {
      "x": -2,
      "y": 1,
      "z": 8,
      "name": "Rock_Volcanic_Brick"
    },
    {
      "x": -2,
      "y": 2,
      "z": 8,
      "name": "Rock_Volcanic_Brick_Ornate"
    },
    {
      "x": -2,
      "y": 3,
      "z": 8,
      "name": "Rock_Volcanic_Brick_Decorative"
    },
    {
      "x": -2,
      "y": 4,
      "z": 8,
      "name": "Rock_Volcanic_Brick_Smooth"
    },
    {
      "x": -2,
      "y": 5,
      "z": 8,
      "name": "Rock_Volcanic_Brick_Ornate"
    },
    {
      "x": -2,
      "y": 6,
      "z": 8,
      "name": "Rock_Crystal_White_Block",
      "rotation": 5
    },
    {
      "x": -2,
      "y": 7,
      "z": 8,
      "name": "Rock_Volcanic_Brick"
    },
    {
      "x": -2,
      "y": 8,
      "z": 8,
      "name": "Rock_Volcanic_Brick_Smooth_Half"
    },
    {
      "x": -2,
      "y": 0,
      "z": 9,
      "name": "Rock_Volcanic_Brick"
    },
    {
      "x": -2,
      "y": 8,
      "z": 9,
      "name": "Rock_Volcanic_Brick_Smooth_Half"
    },
    {
      "x": -2,
      "y": 0,
      "z": 10,
      "name": "Rock_Volcanic_Brick"
    },
    {
      "x": -2,
      "y": 8,
      "z": 10,
      "name": "Rock_Volcanic_Brick_Smooth_Half"
    },
    {
      "x": -2,
      "y": 0,
      "z": 11,
      "name": "Rock_Volcanic_Brick"
    },
    {
      "x": -2,
      "y": 8,
      "z": 11,
      "name": "Rock_Volcanic_Brick_Smooth_Half"
    },
    {
      "x": -2,
      "y": 0,
      "z": 12,
      "name": "Rock_Volcanic_Brick"
    },
    {
      "x": -2,
      "y": 1,
      "z": 12,
      "name": "Furniture_Human_Ruins_Bookshelf",
      "rotation": 2
    },
    {
      "x": -2,
      "y": 2,
      "z": 12,
      "name": "Furniture_Human_Ruins_Bookshelf",
      "rotation": 2
    },
    {
      "x": -2,
      "y": 3,
      "z": 12,
      "name": "Furniture_Human_Ruins_Bookshelf",
      "rotation": 2
    },
    {
      "x": -2,
      "y": 7,
      "z": 12,
      "name": "Rock_Volcanic_Brick_Roof_Shallow",
      "filler": 992
    },
    {
      "x": -2,
      "y": 0,
      "z": 13,
      "name": "Rock_Volcanic_Brick"
    },
    {
      "x": -2,
      "y": 1,
      "z": 13,
      "name": "Rock_Volcanic_Brick"
    },
    {
      "x": -2,
      "y": 2,
      "z": 13,
      "name": "Rock_Volcanic_Brick_Ornate"
    },
    {
      "x": -2,
      "y": 3,
      "z": 13,
      "name": "Rock_Volcanic_Brick_Decorative"
    },
    {
      "x": -2,
      "y": 4,
      "z": 13,
      "name": "Rock_Volcanic_Brick_Decorative"
    },
    {
      "x": -2,
      "y": 5,
      "z": 13,
      "name": "Rock_Volcanic_Brick_Ornate"
    },
    {
      "x": -2,
      "y": 6,
      "z": 13,
      "name": "Rock_Crystal_White_Block"
    },
    {
      "x": -2,
      "y": 7,
      "z": 13,
      "name": "Rock_Volcanic_Brick_Roof_Shallow"
    },
    {
      "x": -2,
      "y": 0,
      "z": 14,
      "name": "Rock_Volcanic_Brick"
    },
    {
      "x": -2,
      "y": 6,
      "z": 14,
      "name": "Rock_Volcanic_Brick_Roof_Shallow",
      "filler": 992
    },
    {
      "x": -2,
      "y": 0,
      "z": 15,
      "name": "Rock_Volcanic_Brick"
    },
    {
      "x": -2,
      "y": 1,
      "z": 15,
      "name": "Rock_Volcanic_Brick_Pillar_Base"
    },
    {
      "x": -2,
      "y": 2,
      "z": 15,
      "name": "Rock_Volcanic_Brick_Pillar_Middle"
    },
    {
      "x": -2,
      "y": 3,
      "z": 15,
      "name": "Rock_Volcanic_Brick_Pillar_Middle"
    },
    {
      "x": -2,
      "y": 4,
      "z": 15,
      "name": "Rock_Volcanic_Brick_Pillar_Middle"
    },
    {
      "x": -2,
      "y": 5,
      "z": 15,
      "name": "Rock_Volcanic_Brick_Pillar_Base",
      "rotation": 8
    },
    {
      "x": -2,
      "y": 6,
      "z": 15,
      "name": "Rock_Volcanic_Brick_Roof_Shallow"
    },
    {
      "x": -1,
      "y": 0,
      "z": -15,
      "name": "Rock_Volcanic_Brick_Smooth_Half"
    },
    {
      "x": -1,
      "y": 0,
      "z": -14,
      "name": "Rock_Volcanic_Brick_Stairs",
      "rotation": 2
    },
    {
      "x": -1,
      "y": 0,
      "z": -13,
      "name": "Rock_Volcanic_Brick"
    },
    {
      "x": -1,
      "y": 6,
      "z": -13,
      "name": "Rock_Volcanic_Brick_Roof_Shallow",
      "rotation": 2
    },
    {
      "x": -1,
      "y": 0,
      "z": -12,
      "name": "Rock_Volcanic_Brick"
    },
    {
      "x": -1,
      "y": 6,
      "z": -12,
      "name": "Rock_Volcanic_Brick_Roof_Shallow",
      "filler": 32,
      "rotation": 2
    },
    {
      "x": -1,
      "y": 0,
      "z": -11,
      "name": "Rock_Volcanic_Brick"
    },
    {
      "x": -1,
      "y": 1,
      "z": -11,
      "name": "*Furniture_Temple_Dark_Door_Medium_State_Definitions_CloseDoorIn",
      "filler": 30,
      "rotation": 2
    },
    {
      "x": -1,
      "y": 2,
      "z": -11,
      "name": "*Furniture_Temple_Dark_Door_Medium_State_Definitions_CloseDoorIn",
      "filler": 1054,
      "rotation": 2
    },
    {
      "x": -1,
      "y": 3,
      "z": -11,
      "name": "*Furniture_Temple_Dark_Door_Medium_State_Definitions_CloseDoorIn",
      "filler": 2078,
      "rotation": 2
    },
    {
      "x": -1,
      "y": 4,
      "z": -11,
      "name": "Rock_Volcanic_Brick_Smooth"
    },
    {
      "x": -1,
      "y": 5,
      "z": -11,
      "name": "Rock_Volcanic_Brick_Ornate"
    },
    {
      "x": -1,
      "y": 6,
      "z": -11,
      "name": "Rock_Crystal_White_Block",
      "rotation": 5
    },
    {
      "x": -1,
      "y": 7,
      "z": -11,
      "name": "Rock_Volcanic_Brick_Roof_Shallow",
      "rotation": 2
    },
    {
      "x": -1,
      "y": 0,
      "z": -10,
      "name": "Rock_Volcanic_Brick"
    },
    {
      "x": -1,
      "y": 7,
      "z": -10,
      "name": "Rock_Volcanic_Brick_Roof_Shallow",
      "filler": 32,
      "rotation": 2
    },
    {
      "x": -1,
      "y": 0,
      "z": -9,
      "name": "Rock_Volcanic_Brick"
    },
    {
      "x": -1,
      "y": 8,
      "z": -9,
      "name": "Rock_Volcanic_Brick_Smooth_Half"
    },
    {
      "x": -1,
      "y": 0,
      "z": -8,
      "name": "Rock_Volcanic_Brick"
    },
    {
      "x": -1,
      "y": 8,
      "z": -8,
      "name": "Rock_Volcanic_Brick_Smooth_Half"
    },
    {
      "x": -1,
      "y": 0,
      "z": -7,
      "name": "Rock_Volcanic_Brick"
    },
    {
      "x": -1,
      "y": 8,
      "z": -7,
      "name": "Rock_Volcanic_Brick_Smooth_Half"
    },
    {
      "x": -1,
      "y": 0,
      "z": -6,
      "name": "Rock_Volcanic_Brick"
    },
    {
      "x": -1,
      "y": 8,
      "z": -6,
      "name": "Rock_Volcanic_Brick_Smooth_Half"
    },
    {
      "x": -1,
      "y": 0,
      "z": -5,
      "name": "Rock_Volcanic_Brick"
    },
    {
      "x": -1,
      "y": 8,
      "z": -5,
      "name": "Rock_Volcanic_Brick_Smooth_Half"
    },
    {
      "x": -1,
      "y": 0,
      "z": -4,
      "name": "Rock_Volcanic_Brick"
    },
    {
      "x": -1,
      "y": 8,
      "z": -4,
      "name": "Rock_Volcanic_Brick_Smooth_Half"
    },
    {
      "x": -1,
      "y": 0,
      "z": -3,
      "name": "Rock_Volcanic_Brick"
    },
    {
      "x": -1,
      "y": 8,
      "z": -3,
      "name": "Rock_Volcanic_Brick_Smooth_Half"
    },
    {
      "x": -1,
      "y": 0,
      "z": -2,
      "name": "Rock_Volcanic_Brick"
    },
    {
      "x": -1,
      "y": 8,
      "z": -2,
      "name": "Rock_Volcanic_Brick_Smooth_Half"
    },
    {
      "x": -1,
      "y": 0,
      "z": -1,
      "name": "Rock_Volcanic_Brick"
    },
    {
      "x": -1,
      "y": 8,
      "z": -1,
      "name": "Rock_Volcanic_Brick_Smooth_Half"
    },
    {
      "x": -1,
      "y": 0,
      "z": 0,
      "name": "Rock_Volcanic_Brick"
    },
    {
      "x": -1,
      "y": 8,
      "z": 0,
      "name": "Rock_Volcanic_Brick_Smooth_Half"
    },
    {
      "x": -1,
      "y": 0,
      "z": 1,
      "name": "Rock_Volcanic_Brick"
    },
    {
      "x": -1,
      "y": 8,
      "z": 1,
      "name": "Rock_Volcanic_Brick_Smooth_Half"
    },
    {
      "x": -1,
      "y": 0,
      "z": 2,
      "name": "Rock_Volcanic_Brick"
    },
    {
      "x": -1,
      "y": 8,
      "z": 2,
      "name": "Rock_Volcanic_Brick_Smooth_Half"
    },
    {
      "x": -1,
      "y": 0,
      "z": 3,
      "name": "Rock_Volcanic_Brick"
    },
    {
      "x": -1,
      "y": 8,
      "z": 3,
      "name": "Rock_Volcanic_Brick_Smooth_Half"
    },
    {
      "x": -1,
      "y": 0,
      "z": 4,
      "name": "Rock_Volcanic_Brick"
    },
    {
      "x": -1,
      "y": 8,
      "z": 4,
      "name": "Rock_Volcanic_Brick_Smooth_Half"
    },
    {
      "x": -1,
      "y": 0,
      "z": 5,
      "name": "Rock_Volcanic_Brick"
    },
    {
      "x": -1,
      "y": 8,
      "z": 5,
      "name": "Rock_Volcanic_Brick_Smooth_Half"
    },
    {
      "x": -1,
      "y": 0,
      "z": 6,
      "name": "Rock_Volcanic_Brick"
    },
    {
      "x": -1,
      "y": 8,
      "z": 6,
      "name": "Rock_Volcanic_Brick_Smooth_Half"
    },
    {
      "x": -1,
      "y": 0,
      "z": 7,
      "name": "Rock_Volcanic_Brick"
    },
    {
      "x": -1,
      "y": 1,
      "z": 7,
      "name": "Furniture_Human_Ruins_Bookshelf",
      "rotation": 2
    },
    {
      "x": -1,
      "y": 2,
      "z": 7,
      "name": "Furniture_Human_Ruins_Bookshelf",
      "rotation": 2
    },
    {
      "x": -1,
      "y": 3,
      "z": 7,
      "name": "Furniture_Human_Ruins_Bookshelf",
      "rotation": 2
    },
    {
      "x": -1,
      "y": 8,
      "z": 7,
      "name": "Rock_Volcanic_Brick_Smooth_Half"
    },
    {
      "x": -1,
      "y": 0,
      "z": 8,
      "name": "Rock_Volcanic_Brick"
    },
    {
      "x": -1,
      "y": 1,
      "z": 8,
      "name": "Rock_Volcanic_Brick"
    },
    {
      "x": -1,
      "y": 2,
      "z": 8,
      "name": "Rock_Volcanic_Brick_Ornate"
    },
    {
      "x": -1,
      "y": 3,
      "z": 8,
      "name": "Rock_Volcanic_Brick_Decorative"
    },
    {
      "x": -1,
      "y": 4,
      "z": 8,
      "name": "Rock_Volcanic_Brick_Smooth"
    },
    {
      "x": -1,
      "y": 5,
      "z": 8,
      "name": "Rock_Volcanic_Brick_Ornate"
    },
    {
      "x": -1,
      "y": 6,
      "z": 8,
      "name": "Rock_Crystal_White_Block",
      "rotation": 5
    },
    {
      "x": -1,
      "y": 7,
      "z": 8,
      "name": "Rock_Volcanic_Brick"
    },
    {
      "x": -1,
      "y": 8,
      "z": 8,
      "name": "Rock_Volcanic_Brick_Smooth_Half"
    },
    {
      "x": -1,
      "y": 0,
      "z": 9,
      "name": "Rock_Volcanic_Brick"
    },
    {
      "x": -1,
      "y": 8,
      "z": 9,
      "name": "Rock_Volcanic_Brick_Smooth_Half"
    },
    {
      "x": -1,
      "y": 0,
      "z": 10,
      "name": "Rock_Volcanic_Brick"
    },
    {
      "x": -1,
      "y": 8,
      "z": 10,
      "name": "Rock_Volcanic_Brick_Smooth_Half"
    },
    {
      "x": -1,
      "y": 0,
      "z": 11,
      "name": "Rock_Volcanic_Brick"
    },
    {
      "x": -1,
      "y": 8,
      "z": 11,
      "name": "Rock_Volcanic_Brick_Smooth_Half"
    },
    {
      "x": -1,
      "y": 0,
      "z": 12,
      "name": "Rock_Volcanic_Brick"
    },
    {
      "x": -1,
      "y": 1,
      "z": 12,
      "name": "Furniture_Human_Ruins_Bookshelf",
      "rotation": 2
    },
    {
      "x": -1,
      "y": 2,
      "z": 12,
      "name": "Furniture_Human_Ruins_Bookshelf",
      "rotation": 2
    },
    {
      "x": -1,
      "y": 3,
      "z": 12,
      "name": "Furniture_Human_Ruins_Bookshelf",
      "rotation": 2
    },
    {
      "x": -1,
      "y": 7,
      "z": 12,
      "name": "Rock_Volcanic_Brick_Roof_Shallow",
      "filler": 992
    },
    {
      "x": -1,
      "y": 0,
      "z": 13,
      "name": "Rock_Volcanic_Brick"
    },
    {
      "x": -1,
      "y": 1,
      "z": 13,
      "name": "Rock_Volcanic_Brick"
    },
    {
      "x": -1,
      "y": 2,
      "z": 13,
      "name": "Rock_Volcanic_Brick_Ornate"
    },
    {
      "x": -1,
      "y": 3,
      "z": 13,
      "name": "Rock_Volcanic_Brick_Decorative"
    },
    {
      "x": -1,
      "y": 4,
      "z": 13,
      "name": "Rock_Volcanic_Brick_Decorative"
    },
    {
      "x": -1,
      "y": 5,
      "z": 13,
      "name": "Rock_Volcanic_Brick_Ornate"
    },
    {
      "x": -1,
      "y": 6,
      "z": 13,
      "name": "Rock_Crystal_White_Block"
    },
    {
      "x": -1,
      "y": 7,
      "z": 13,
      "name": "Rock_Volcanic_Brick_Roof_Shallow"
    },
    {
      "x": -1,
      "y": 0,
      "z": 14,
      "name": "Rock_Volcanic_Brick"
    },
    {
      "x": -1,
      "y": 6,
      "z": 14,
      "name": "Rock_Volcanic_Brick_Roof_Shallow",
      "filler": 992
    },
    {
      "x": -1,
      "y": 0,
      "z": 15,
      "name": "Rock_Volcanic_Brick"
    },
    {
      "x": -1,
      "y": 6,
      "z": 15,
      "name": "Rock_Volcanic_Brick_Roof_Shallow"
    },
    {
      "x": 0,
      "y": 0,
      "z": -15,
      "name": "Rock_Volcanic_Brick_Smooth_Half"
    },
    {
      "x": 0,
      "y": 0,
      "z": -14,
      "name": "Rock_Volcanic_Brick_Stairs",
      "rotation": 2
    },
    {
      "x": 0,
      "y": 0,
      "z": -13,
      "name": "Rock_Volcanic_Brick"
    },
    {
      "x": 0,
      "y": 6,
      "z": -13,
      "name": "Rock_Volcanic_Brick_Roof_Shallow",
      "rotation": 2
    },
    {
      "x": 0,
      "y": 0,
      "z": -12,
      "name": "Rock_Volcanic_Brick"
    },
    {
      "x": 0,
      "y": 6,
      "z": -12,
      "name": "Rock_Volcanic_Brick_Roof_Shallow",
      "filler": 32,
      "rotation": 2
    },
    {
      "x": 0,
      "y": 0,
      "z": -11,
      "name": "Rock_Volcanic_Brick"
    },
    {
      "x": 0,
      "y": 1,
      "z": -11,
      "name": "*Furniture_Temple_Dark_Door_Medium_State_Definitions_CloseDoorIn",
      "filler": 31,
      "rotation": 2
    },
    {
      "x": 0,
      "y": 2,
      "z": -11,
      "name": "*Furniture_Temple_Dark_Door_Medium_State_Definitions_CloseDoorIn",
      "filler": 1055,
      "rotation": 2
    },
    {
      "x": 0,
      "y": 3,
      "z": -11,
      "name": "*Furniture_Temple_Dark_Door_Medium_State_Definitions_CloseDoorIn",
      "filler": 2079,
      "rotation": 2
    },
    {
      "x": 0,
      "y": 4,
      "z": -11,
      "name": "Rock_Volcanic_Brick_Smooth"
    },
    {
      "x": 0,
      "y": 5,
      "z": -11,
      "name": "Rock_Volcanic_Brick_Ornate"
    },
    {
      "x": 0,
      "y": 6,
      "z": -11,
      "name": "Rock_Crystal_White_Block",
      "rotation": 5
    },
    {
      "x": 0,
      "y": 7,
      "z": -11,
      "name": "Rock_Volcanic_Brick_Roof_Shallow",
      "rotation": 2
    },
    {
      "x": 0,
      "y": 0,
      "z": -10,
      "name": "Rock_Volcanic_Brick"
    },
    {
      "x": 0,
      "y": 7,
      "z": -10,
      "name": "Rock_Volcanic_Brick_Roof_Shallow",
      "filler": 32,
      "rotation": 2
    },
    {
      "x": 0,
      "y": 0,
      "z": -9,
      "name": "Rock_Volcanic_Brick"
    },
    {
      "x": 0,
      "y": 8,
      "z": -9,
      "name": "Rock_Volcanic_Brick_Smooth_Half"
    },
    {
      "x": 0,
      "y": 0,
      "z": -8,
      "name": "Rock_Volcanic_Brick"
    },
    {
      "x": 0,
      "y": 8,
      "z": -8,
      "name": "Rock_Volcanic_Brick_Smooth_Half"
    },
    {
      "x": 0,
      "y": 0,
      "z": -7,
      "name": "Rock_Volcanic_Brick"
    },
    {
      "x": 0,
      "y": 8,
      "z": -7,
      "name": "Rock_Volcanic_Brick_Smooth_Half"
    },
    {
      "x": 0,
      "y": 0,
      "z": -6,
      "name": "Rock_Volcanic_Brick"
    },
    {
      "x": 0,
      "y": 8,
      "z": -6,
      "name": "Rock_Volcanic_Brick_Smooth_Half"
    },
    {
      "x": 0,
      "y": 0,
      "z": -5,
      "name": "Rock_Volcanic_Brick"
    },
    {
      "x": 0,
      "y": 8,
      "z": -5,
      "name": "Rock_Volcanic_Brick_Smooth_Half"
    },
    {
      "x": 0,
      "y": 0,
      "z": -4,
      "name": "Rock_Volcanic_Brick"
    },
    {
      "x": 0,
      "y": 8,
      "z": -4,
      "name": "Rock_Volcanic_Brick_Smooth_Half"
    },
    {
      "x": 0,
      "y": 0,
      "z": -3,
      "name": "Rock_Volcanic_Brick"
    },
    {
      "x": 0,
      "y": 8,
      "z": -3,
      "name": "Rock_Volcanic_Brick_Smooth_Half"
    },
    {
      "x": 0,
      "y": 0,
      "z": -2,
      "name": "Rock_Volcanic_Brick"
    },
    {
      "x": 0,
      "y": 8,
      "z": -2,
      "name": "Rock_Volcanic_Brick_Smooth_Half"
    },
    {
      "x": 0,
      "y": 0,
      "z": -1,
      "name": "Rock_Volcanic_Brick"
    },
    {
      "x": 0,
      "y": 8,
      "z": -1,
      "name": "Rock_Volcanic_Brick_Smooth_Half"
    },
    {
      "x": 0,
      "y": 0,
      "z": 0,
      "name": "Rock_Volcanic_Brick"
    },
    {
      "x": 0,
      "y": 8,
      "z": 0,
      "name": "Rock_Volcanic_Brick_Smooth_Half"
    },
    {
      "x": 0,
      "y": 0,
      "z": 1,
      "name": "Rock_Volcanic_Brick"
    },
    {
      "x": 0,
      "y": 8,
      "z": 1,
      "name": "Rock_Volcanic_Brick_Smooth_Half"
    },
    {
      "x": 0,
      "y": 0,
      "z": 2,
      "name": "Rock_Volcanic_Brick"
    },
    {
      "x": 0,
      "y": 8,
      "z": 2,
      "name": "Rock_Volcanic_Brick_Smooth_Half"
    },
    {
      "x": 0,
      "y": 0,
      "z": 3,
      "name": "Rock_Volcanic_Brick"
    },
    {
      "x": 0,
      "y": 8,
      "z": 3,
      "name": "Rock_Volcanic_Brick_Smooth_Half"
    },
    {
      "x": 0,
      "y": 0,
      "z": 4,
      "name": "Rock_Volcanic_Brick"
    },
    {
      "x": 0,
      "y": 8,
      "z": 4,
      "name": "Rock_Volcanic_Brick_Smooth_Half"
    },
    {
      "x": 0,
      "y": 0,
      "z": 5,
      "name": "Rock_Volcanic_Brick"
    },
    {
      "x": 0,
      "y": 8,
      "z": 5,
      "name": "Rock_Volcanic_Brick_Smooth_Half"
    },
    {
      "x": 0,
      "y": 0,
      "z": 6,
      "name": "Rock_Volcanic_Brick"
    },
    {
      "x": 0,
      "y": 8,
      "z": 6,
      "name": "Rock_Volcanic_Brick_Smooth_Half"
    },
    {
      "x": 0,
      "y": 0,
      "z": 7,
      "name": "Rock_Volcanic_Brick"
    },
    {
      "x": 0,
      "y": 1,
      "z": 7,
      "name": "Furniture_Human_Ruins_Bookshelf",
      "rotation": 2
    },
    {
      "x": 0,
      "y": 2,
      "z": 7,
      "name": "Rock_Volcanic_Brick_Ornate"
    },
    {
      "x": 0,
      "y": 3,
      "z": 7,
      "name": "Furniture_Human_Ruins_Bookshelf",
      "rotation": 2
    },
    {
      "x": 0,
      "y": 8,
      "z": 7,
      "name": "Rock_Volcanic_Brick_Smooth_Half"
    },
    {
      "x": 0,
      "y": 0,
      "z": 8,
      "name": "Rock_Volcanic_Brick"
    },
    {
      "x": 0,
      "y": 1,
      "z": 8,
      "name": "Rock_Volcanic_Brick"
    },
    {
      "x": 0,
      "y": 2,
      "z": 8,
      "name": "Rock_Volcanic_Brick_Ornate"
    },
    {
      "x": 0,
      "y": 3,
      "z": 8,
      "name": "Rock_Volcanic_Brick_Decorative"
    },
    {
      "x": 0,
      "y": 4,
      "z": 8,
      "name": "Rock_Volcanic_Brick_Smooth"
    },
    {
      "x": 0,
      "y": 5,
      "z": 8,
      "name": "Rock_Volcanic_Brick_Ornate"
    },
    {
      "x": 0,
      "y": 6,
      "z": 8,
      "name": "Rock_Crystal_White_Block",
      "rotation": 5
    },
    {
      "x": 0,
      "y": 7,
      "z": 8,
      "name": "Rock_Volcanic_Brick"
    },
    {
      "x": 0,
      "y": 8,
      "z": 8,
      "name": "Rock_Volcanic_Brick_Smooth_Half"
    },
    {
      "x": 0,
      "y": 0,
      "z": 9,
      "name": "Rock_Volcanic_Brick"
    },
    {
      "x": 0,
      "y": 8,
      "z": 9,
      "name": "Rock_Volcanic_Brick_Smooth_Half"
    },
    {
      "x": 0,
      "y": 0,
      "z": 10,
      "name": "Rock_Volcanic_Brick"
    },
    {
      "x": 0,
      "y": 8,
      "z": 10,
      "name": "Rock_Volcanic_Brick_Smooth_Half"
    },
    {
      "x": 0,
      "y": 0,
      "z": 11,
      "name": "Rock_Volcanic_Brick"
    },
    {
      "x": 0,
      "y": 8,
      "z": 11,
      "name": "Rock_Volcanic_Brick_Smooth_Half"
    },
    {
      "x": 0,
      "y": 0,
      "z": 12,
      "name": "Rock_Volcanic_Brick"
    },
    {
      "x": 0,
      "y": 1,
      "z": 12,
      "name": "Furniture_Human_Ruins_Bookshelf",
      "rotation": 2
    },
    {
      "x": 0,
      "y": 2,
      "z": 12,
      "name": "Furniture_Human_Ruins_Bookshelf",
      "rotation": 2
    },
    {
      "x": 0,
      "y": 3,
      "z": 12,
      "name": "Furniture_Human_Ruins_Bookshelf",
      "rotation": 2
    },
    {
      "x": 0,
      "y": 7,
      "z": 12,
      "name": "Rock_Volcanic_Brick_Roof_Shallow",
      "filler": 992
    },
    {
      "x": 0,
      "y": 0,
      "z": 13,
      "name": "Rock_Volcanic_Brick"
    },
    {
      "x": 0,
      "y": 1,
      "z": 13,
      "name": "Rock_Volcanic_Brick"
    },
    {
      "x": 0,
      "y": 2,
      "z": 13,
      "name": "Rock_Volcanic_Brick_Ornate"
    },
    {
      "x": 0,
      "y": 3,
      "z": 13,
      "name": "Rock_Volcanic_Brick_Decorative"
    },
    {
      "x": 0,
      "y": 4,
      "z": 13,
      "name": "Rock_Volcanic_Brick_Decorative"
    },
    {
      "x": 0,
      "y": 5,
      "z": 13,
      "name": "Rock_Volcanic_Brick_Ornate"
    },
    {
      "x": 0,
      "y": 6,
      "z": 13,
      "name": "Rock_Crystal_White_Block"
    },
    {
      "x": 0,
      "y": 7,
      "z": 13,
      "name": "Rock_Volcanic_Brick_Roof_Shallow"
    },
    {
      "x": 0,
      "y": 0,
      "z": 14,
      "name": "Rock_Volcanic_Brick"
    },
    {
      "x": 0,
      "y": 6,
      "z": 14,
      "name": "Rock_Volcanic_Brick_Roof_Shallow",
      "filler": 992
    },
    {
      "x": 0,
      "y": 0,
      "z": 15,
      "name": "Rock_Volcanic_Brick"
    },
    {
      "x": 0,
      "y": 6,
      "z": 15,
      "name": "Rock_Volcanic_Brick_Roof_Shallow"
    },
    {
      "x": 1,
      "y": 0,
      "z": -15,
      "name": "Rock_Volcanic_Brick_Smooth_Half"
    },
    {
      "x": 1,
      "y": 0,
      "z": -14,
      "name": "Rock_Volcanic_Brick_Stairs",
      "rotation": 2
    },
    {
      "x": 1,
      "y": 0,
      "z": -13,
      "name": "Rock_Volcanic_Brick"
    },
    {
      "x": 1,
      "y": 6,
      "z": -13,
      "name": "Rock_Volcanic_Brick_Roof_Shallow",
      "rotation": 2
    },
    {
      "x": 1,
      "y": 0,
      "z": -12,
      "name": "Rock_Volcanic_Brick"
    },
    {
      "x": 1,
      "y": 6,
      "z": -12,
      "name": "Rock_Volcanic_Brick_Roof_Shallow",
      "filler": 32,
      "rotation": 2
    },
    {
      "x": 1,
      "y": 0,
      "z": -11,
      "name": "Rock_Volcanic_Brick"
    },
    {
      "x": 1,
      "y": 1,
      "z": -11,
      "name": "*Furniture_Temple_Dark_Door_Medium_State_Definitions_CloseDoorIn",
      "rotation": 2
    },
    {
      "x": 1,
      "y": 2,
      "z": -11,
      "name": "*Furniture_Temple_Dark_Door_Medium_State_Definitions_CloseDoorIn",
      "filler": 1024,
      "rotation": 2
    },
    {
      "x": 1,
      "y": 3,
      "z": -11,
      "name": "*Furniture_Temple_Dark_Door_Medium_State_Definitions_CloseDoorIn",
      "filler": 2048,
      "rotation": 2
    },
    {
      "x": 1,
      "y": 4,
      "z": -11,
      "name": "Rock_Volcanic_Brick_Smooth"
    },
    {
      "x": 1,
      "y": 5,
      "z": -11,
      "name": "Rock_Volcanic_Brick_Ornate"
    },
    {
      "x": 1,
      "y": 6,
      "z": -11,
      "name": "Rock_Crystal_White_Block",
      "rotation": 5
    },
    {
      "x": 1,
      "y": 7,
      "z": -11,
      "name": "Rock_Volcanic_Brick_Roof_Shallow",
      "rotation": 2
    },
    {
      "x": 1,
      "y": 0,
      "z": -10,
      "name": "Rock_Volcanic_Brick"
    },
    {
      "x": 1,
      "y": 7,
      "z": -10,
      "name": "Rock_Volcanic_Brick_Roof_Shallow",
      "filler": 32,
      "rotation": 2
    },
    {
      "x": 1,
      "y": 0,
      "z": -9,
      "name": "Rock_Volcanic_Brick"
    },
    {
      "x": 1,
      "y": 8,
      "z": -9,
      "name": "Rock_Volcanic_Brick_Smooth_Half"
    },
    {
      "x": 1,
      "y": 0,
      "z": -8,
      "name": "Rock_Volcanic_Brick"
    },
    {
      "x": 1,
      "y": 8,
      "z": -8,
      "name": "Rock_Volcanic_Brick_Smooth_Half"
    },
    {
      "x": 1,
      "y": 0,
      "z": -7,
      "name": "Rock_Volcanic_Brick"
    },
    {
      "x": 1,
      "y": 8,
      "z": -7,
      "name": "Rock_Volcanic_Brick_Smooth_Half"
    },
    {
      "x": 1,
      "y": 0,
      "z": -6,
      "name": "Rock_Volcanic_Brick"
    },
    {
      "x": 1,
      "y": 8,
      "z": -6,
      "name": "Rock_Volcanic_Brick_Smooth_Half"
    },
    {
      "x": 1,
      "y": 0,
      "z": -5,
      "name": "Rock_Volcanic_Brick"
    },
    {
      "x": 1,
      "y": 8,
      "z": -5,
      "name": "Rock_Volcanic_Brick_Smooth_Half"
    },
    {
      "x": 1,
      "y": 0,
      "z": -4,
      "name": "Rock_Volcanic_Brick"
    },
    {
      "x": 1,
      "y": 8,
      "z": -4,
      "name": "Rock_Volcanic_Brick_Smooth_Half"
    },
    {
      "x": 1,
      "y": 0,
      "z": -3,
      "name": "Rock_Volcanic_Brick"
    },
    {
      "x": 1,
      "y": 8,
      "z": -3,
      "name": "Rock_Volcanic_Brick_Smooth_Half"
    },
    {
      "x": 1,
      "y": 0,
      "z": -2,
      "name": "Rock_Volcanic_Brick"
    },
    {
      "x": 1,
      "y": 8,
      "z": -2,
      "name": "Rock_Volcanic_Brick_Smooth_Half"
    },
    {
      "x": 1,
      "y": 0,
      "z": -1,
      "name": "Rock_Volcanic_Brick"
    },
    {
      "x": 1,
      "y": 8,
      "z": -1,
      "name": "Rock_Volcanic_Brick_Smooth_Half"
    },
    {
      "x": 1,
      "y": 0,
      "z": 0,
      "name": "Rock_Volcanic_Brick"
    },
    {
      "x": 1,
      "y": 8,
      "z": 0,
      "name": "Rock_Volcanic_Brick_Smooth_Half"
    },
    {
      "x": 1,
      "y": 0,
      "z": 1,
      "name": "Rock_Volcanic_Brick"
    },
    {
      "x": 1,
      "y": 8,
      "z": 1,
      "name": "Rock_Volcanic_Brick_Smooth_Half"
    },
    {
      "x": 1,
      "y": 0,
      "z": 2,
      "name": "Rock_Volcanic_Brick"
    },
    {
      "x": 1,
      "y": 8,
      "z": 2,
      "name": "Rock_Volcanic_Brick_Smooth_Half"
    },
    {
      "x": 1,
      "y": 0,
      "z": 3,
      "name": "Rock_Volcanic_Brick"
    },
    {
      "x": 1,
      "y": 8,
      "z": 3,
      "name": "Rock_Volcanic_Brick_Smooth_Half"
    },
    {
      "x": 1,
      "y": 0,
      "z": 4,
      "name": "Rock_Volcanic_Brick"
    },
    {
      "x": 1,
      "y": 8,
      "z": 4,
      "name": "Rock_Volcanic_Brick_Smooth_Half"
    },
    {
      "x": 1,
      "y": 0,
      "z": 5,
      "name": "Rock_Volcanic_Brick"
    },
    {
      "x": 1,
      "y": 8,
      "z": 5,
      "name": "Rock_Volcanic_Brick_Smooth_Half"
    },
    {
      "x": 1,
      "y": 0,
      "z": 6,
      "name": "Rock_Volcanic_Brick"
    },
    {
      "x": 1,
      "y": 8,
      "z": 6,
      "name": "Rock_Volcanic_Brick_Smooth_Half"
    },
    {
      "x": 1,
      "y": 0,
      "z": 7,
      "name": "Rock_Volcanic_Brick"
    },
    {
      "x": 1,
      "y": 1,
      "z": 7,
      "name": "Furniture_Human_Ruins_Bookshelf",
      "rotation": 2
    },
    {
      "x": 1,
      "y": 2,
      "z": 7,
      "name": "Furniture_Human_Ruins_Bookshelf",
      "rotation": 2
    },
    {
      "x": 1,
      "y": 3,
      "z": 7,
      "name": "Furniture_Human_Ruins_Bookshelf",
      "rotation": 2
    },
    {
      "x": 1,
      "y": 8,
      "z": 7,
      "name": "Rock_Volcanic_Brick_Smooth_Half"
    },
    {
      "x": 1,
      "y": 0,
      "z": 8,
      "name": "Rock_Volcanic_Brick"
    },
    {
      "x": 1,
      "y": 1,
      "z": 8,
      "name": "Rock_Volcanic_Brick"
    },
    {
      "x": 1,
      "y": 2,
      "z": 8,
      "name": "Rock_Volcanic_Brick_Ornate"
    },
    {
      "x": 1,
      "y": 3,
      "z": 8,
      "name": "Rock_Volcanic_Brick_Decorative"
    },
    {
      "x": 1,
      "y": 4,
      "z": 8,
      "name": "Rock_Volcanic_Brick_Smooth"
    },
    {
      "x": 1,
      "y": 5,
      "z": 8,
      "name": "Rock_Volcanic_Brick_Ornate"
    },
    {
      "x": 1,
      "y": 6,
      "z": 8,
      "name": "Rock_Crystal_White_Block",
      "rotation": 5
    },
    {
      "x": 1,
      "y": 7,
      "z": 8,
      "name": "Rock_Volcanic_Brick"
    },
    {
      "x": 1,
      "y": 8,
      "z": 8,
      "name": "Rock_Volcanic_Brick_Smooth_Half"
    },
    {
      "x": 1,
      "y": 0,
      "z": 9,
      "name": "Rock_Volcanic_Brick"
    },
    {
      "x": 1,
      "y": 8,
      "z": 9,
      "name": "Rock_Volcanic_Brick_Smooth_Half"
    },
    {
      "x": 1,
      "y": 0,
      "z": 10,
      "name": "Rock_Volcanic_Brick"
    },
    {
      "x": 1,
      "y": 8,
      "z": 10,
      "name": "Rock_Volcanic_Brick_Smooth_Half"
    },
    {
      "x": 1,
      "y": 0,
      "z": 11,
      "name": "Rock_Volcanic_Brick"
    },
    {
      "x": 1,
      "y": 8,
      "z": 11,
      "name": "Rock_Volcanic_Brick_Smooth_Half"
    },
    {
      "x": 1,
      "y": 0,
      "z": 12,
      "name": "Rock_Volcanic_Brick"
    },
    {
      "x": 1,
      "y": 1,
      "z": 12,
      "name": "Furniture_Human_Ruins_Bookshelf",
      "rotation": 2
    },
    {
      "x": 1,
      "y": 2,
      "z": 12,
      "name": "Furniture_Human_Ruins_Bookshelf",
      "rotation": 2
    },
    {
      "x": 1,
      "y": 3,
      "z": 12,
      "name": "Furniture_Human_Ruins_Bookshelf",
      "rotation": 2
    },
    {
      "x": 1,
      "y": 7,
      "z": 12,
      "name": "Rock_Volcanic_Brick_Roof_Shallow",
      "filler": 992
    },
    {
      "x": 1,
      "y": 0,
      "z": 13,
      "name": "Rock_Volcanic_Brick"
    },
    {
      "x": 1,
      "y": 1,
      "z": 13,
      "name": "Rock_Volcanic_Brick"
    },
    {
      "x": 1,
      "y": 2,
      "z": 13,
      "name": "Rock_Volcanic_Brick_Ornate"
    },
    {
      "x": 1,
      "y": 3,
      "z": 13,
      "name": "Rock_Volcanic_Brick_Decorative"
    },
    {
      "x": 1,
      "y": 4,
      "z": 13,
      "name": "Rock_Volcanic_Brick_Decorative"
    },
    {
      "x": 1,
      "y": 5,
      "z": 13,
      "name": "Rock_Volcanic_Brick_Ornate"
    },
    {
      "x": 1,
      "y": 6,
      "z": 13,
      "name": "Rock_Crystal_White_Block"
    },
    {
      "x": 1,
      "y": 7,
      "z": 13,
      "name": "Rock_Volcanic_Brick_Roof_Shallow"
    },
    {
      "x": 1,
      "y": 0,
      "z": 14,
      "name": "Rock_Volcanic_Brick"
    },
    {
      "x": 1,
      "y": 6,
      "z": 14,
      "name": "Rock_Volcanic_Brick_Roof_Shallow",
      "filler": 992
    },
    {
      "x": 1,
      "y": 0,
      "z": 15,
      "name": "Rock_Volcanic_Brick"
    },
    {
      "x": 1,
      "y": 6,
      "z": 15,
      "name": "Rock_Volcanic_Brick_Roof_Shallow"
    },
    {
      "x": 2,
      "y": 0,
      "z": -15,
      "name": "Rock_Volcanic_Brick"
    },
    {
      "x": 2,
      "y": 1,
      "z": -15,
      "name": "Furniture_Human_Ruins_Brazier"
    },
    {
      "x": 2,
      "y": 0,
      "z": -14,
      "name": "Rock_Volcanic_Brick"
    },
    {
      "x": 2,
      "y": 1,
      "z": -14,
      "name": "Furniture_Village_Statue",
      "rotation": 2
    },
    {
      "x": 2,
      "y": 2,
      "z": -14,
      "name": "Furniture_Village_Statue",
      "filler": 1024,
      "rotation": 2
    },
    {
      "x": 2,
      "y": 3,
      "z": -14,
      "name": "Furniture_Village_Statue",
      "filler": 2048,
      "rotation": 2
    },
    {
      "x": 2,
      "y": 0,
      "z": -13,
      "name": "Rock_Volcanic_Brick"
    },
    {
      "x": 2,
      "y": 1,
      "z": -13,
      "name": "Rock_Volcanic_Brick_Pillar_Base"
    },
    {
      "x": 2,
      "y": 2,
      "z": -13,
      "name": "Rock_Volcanic_Brick_Pillar_Middle"
    },
    {
      "x": 2,
      "y": 3,
      "z": -13,
      "name": "Rock_Volcanic_Brick_Pillar_Middle"
    },
    {
      "x": 2,
      "y": 4,
      "z": -13,
      "name": "Rock_Volcanic_Brick_Pillar_Middle"
    },
    {
      "x": 2,
      "y": 5,
      "z": -13,
      "name": "Rock_Volcanic_Brick_Pillar_Base",
      "rotation": 8
    },
    {
      "x": 2,
      "y": 6,
      "z": -13,
      "name": "Rock_Volcanic_Brick_Roof_Shallow",
      "rotation": 2
    },
    {
      "x": 2,
      "y": 0,
      "z": -12,
      "name": "Rock_Volcanic_Brick"
    },
    {
      "x": 2,
      "y": 6,
      "z": -12,
      "name": "Rock_Volcanic_Brick_Roof_Shallow",
      "filler": 32,
      "rotation": 2
    },
    {
      "x": 2,
      "y": 0,
      "z": -11,
      "name": "Rock_Volcanic_Brick"
    },
    {
      "x": 2,
      "y": 1,
      "z": -11,
      "name": "Rock_Volcanic_Brick"
    },
    {
      "x": 2,
      "y": 2,
      "z": -11,
      "name": "Rock_Volcanic_Brick_Ornate"
    },
    {
      "x": 2,
      "y": 3,
      "z": -11,
      "name": "Rock_Volcanic_Brick_Decorative"
    },
    {
      "x": 2,
      "y": 4,
      "z": -11,
      "name": "Rock_Volcanic_Brick_Smooth"
    },
    {
      "x": 2,
      "y": 5,
      "z": -11,
      "name": "Rock_Volcanic_Brick_Ornate"
    },
    {
      "x": 2,
      "y": 6,
      "z": -11,
      "name": "Rock_Crystal_White_Block",
      "rotation": 5
    },
    {
      "x": 2,
      "y": 7,
      "z": -11,
      "name": "Rock_Volcanic_Brick_Roof_Shallow",
      "rotation": 2
    },
    {
      "x": 2,
      "y": 0,
      "z": -10,
      "name": "Rock_Volcanic_Brick"
    },
    {
      "x": 2,
      "y": 1,
      "z": -10,
      "name": "Furniture_Human_Ruins_Bookshelf"
    },
    {
      "x": 2,
      "y": 2,
      "z": -10,
      "name": "Furniture_Human_Ruins_Bookshelf"
    },
    {
      "x": 2,
      "y": 3,
      "z": -10,
      "name": "Furniture_Human_Ruins_Bookshelf"
    },
    {
      "x": 2,
      "y": 7,
      "z": -10,
      "name": "Rock_Volcanic_Brick_Roof_Shallow",
      "filler": 32,
      "rotation": 2
    },
    {
      "x": 2,
      "y": 0,
      "z": -9,
      "name": "Rock_Volcanic_Brick"
    },
    {
      "x": 2,
      "y": 8,
      "z": -9,
      "name": "Rock_Volcanic_Brick_Smooth_Half"
    },
    {
      "x": 2,
      "y": 0,
      "z": -8,
      "name": "Rock_Volcanic_Brick"
    },
    {
      "x": 2,
      "y": 8,
      "z": -8,
      "name": "Rock_Volcanic_Brick_Smooth_Half"
    },
    {
      "x": 2,
      "y": 0,
      "z": -7,
      "name": "Rock_Volcanic_Brick"
    },
    {
      "x": 2,
      "y": 8,
      "z": -7,
      "name": "Rock_Volcanic_Brick_Smooth_Half"
    },
    {
      "x": 2,
      "y": 0,
      "z": -6,
      "name": "Rock_Volcanic_Brick"
    },
    {
      "x": 2,
      "y": 8,
      "z": -6,
      "name": "Rock_Volcanic_Brick_Smooth_Half"
    },
    {
      "x": 2,
      "y": 0,
      "z": -5,
      "name": "Rock_Volcanic_Brick"
    },
    {
      "x": 2,
      "y": 8,
      "z": -5,
      "name": "Rock_Volcanic_Brick_Smooth_Half"
    },
    {
      "x": 2,
      "y": 0,
      "z": -4,
      "name": "Rock_Volcanic_Brick"
    },
    {
      "x": 2,
      "y": 8,
      "z": -4,
      "name": "Rock_Volcanic_Brick_Smooth_Half"
    },
    {
      "x": 2,
      "y": 0,
      "z": -3,
      "name": "Rock_Volcanic_Brick"
    },
    {
      "x": 2,
      "y": 8,
      "z": -3,
      "name": "Rock_Volcanic_Brick_Smooth_Half"
    },
    {
      "x": 2,
      "y": 0,
      "z": -2,
      "name": "Rock_Volcanic_Brick"
    },
    {
      "x": 2,
      "y": 8,
      "z": -2,
      "name": "Rock_Volcanic_Brick_Smooth_Half"
    },
    {
      "x": 2,
      "y": 0,
      "z": -1,
      "name": "Rock_Volcanic_Brick"
    },
    {
      "x": 2,
      "y": 8,
      "z": -1,
      "name": "Rock_Volcanic_Brick_Smooth_Half"
    },
    {
      "x": 2,
      "y": 0,
      "z": 0,
      "name": "Rock_Volcanic_Brick"
    },
    {
      "x": 2,
      "y": 8,
      "z": 0,
      "name": "Rock_Volcanic_Brick_Smooth_Half"
    },
    {
      "x": 2,
      "y": 0,
      "z": 1,
      "name": "Rock_Volcanic_Brick"
    },
    {
      "x": 2,
      "y": 8,
      "z": 1,
      "name": "Rock_Volcanic_Brick_Smooth_Half"
    },
    {
      "x": 2,
