{
  "version": 8,
  "blockIdVersion": 11,
  "anchorX": 0,
  "anchorY": 0,
  "anchorZ": 0,
  "blocks": [
    {
      "x": -4,
      "y": 0,
      "z": -1,
      "name": "*Wood_Blackwood_Fence_State_Definitions_Corner",
      "rotation": 1
    },
    {
      "x": -4,
      "y": 0,
      "z": 0,
      "name": "Wood_Blackwood_Fence",
      "rotation": 3
    },
    {
      "x": -4,
      "y": 0,
      "z": 1,
      "name": "*Wood_Blackwood_Fence_State_Definitions_Corner",
      "rotation": 2
    },
    {
      "x": -3,
      "y": 0,
      "z": -2,
      "name": "Deco_Halloween_Pumpkin_Cute",
      "rotation": 2
    },
    {
      "x": -3,
      "y": 0,
      "z": -1,
      "name": "Wood_Blackwood_Fence",
      "rotation": 2
    },
    {
      "x": -3,
      "y": 4,
      "z": -1,
      "name": "Wood_Sallow_Roots"
    },
    {
      "x": -3,
      "y": 5,
      "z": -1,
      "name": "Wood_Blackwood_Roof_Shallow",
      "rotation": 3
    },
    {
      "x": -3,
      "y": 0,
      "z": 0,
      "name": "Wood_Blackwood_Planks"
    },
    {
      "x": -3,
      "y": 1,
      "z": 0,
      "name": "Furniture_Temple_Scarak_Brazier"
    },
    {
      "x": -3,
      "y": 4,
      "z": 0,
      "name": "Deco_Halloween_Lights",
      "rotation": 3
    },
    {
      "x": -3,
      "y": 5,
      "z": 0,
      "name": "Wood_Blackwood_Roof_Shallow",
      "rotation": 3
    },
    {
      "x": -3,
      "y": 0,
      "z": 1,
      "name": "Wood_Blackwood_Fence"
    },
    {
      "x": -3,
      "y": 4,
      "z": 1,
      "name": "Wood_Sallow_Roots"
    },
    {
      "x": -3,
      "y": 5,
      "z": 1,
      "name": "Wood_Blackwood_Roof_Shallow",
      "rotation": 3
    },
    {
      "x": -3,
      "y": 0,
      "z": 2,
      "name": "Deco_Halloween_Pumpkin_Cute"
    },
    {
      "x": -2,
      "y": 0,
      "z": -3,
      "name": "Deco_Halloween_Pumpkin_Scary",
      "rotation": 2
    },
    {
      "x": -2,
      "y": 0,
      "z": -2,
      "name": "Wood_Blackwood_Planks"
    },
    {
      "x": -2,
      "y": 1,
      "z": -2,
      "name": "Deco_Halloween_Pumpkin_Hypixel",
      "rotation": 2
    },
    {
      "x": -2,
      "y": 0,
      "z": -1,
      "name": "Wood_Blackwood_Planks"
    },
    {
      "x": -2,
      "y": 1,
      "z": -1,
      "name": "Furniture_Temple_Scarak_Statue",
      "rotation": 2
    },
    {
      "x": -2,
      "y": 2,
      "z": -1,
      "name": "Furniture_Temple_Scarak_Statue",
      "filler": 1024,
      "rotation": 2
    },
    {
      "x": -2,
      "y": 3,
      "z": -1,
      "name": "Furniture_Temple_Scarak_Statue",
      "filler": 2048,
      "rotation": 2
    },
    {
      "x": -2,
      "y": 4,
      "z": -1,
      "name": "Deco_Halloween_Lights",
      "rotation": 2
    },
    {
      "x": -2,
      "y": 5,
      "z": -1,
      "name": "Wood_Blackwood_Roof_Shallow",
      "filler": 1,
      "rotation": 3
    },
    {
      "x": -2,
      "y": 0,
      "z": 0,
      "name": "Wood_Blackwood_Planks"
    },
    {
      "x": -2,
      "y": 1,
      "z": 0,
      "name": "Wood_Blackwood_Ornate"
    },
    {
      "x": -2,
      "y": 2,
      "z": 0,
      "name": "Wood_Blackwood_Ornate"
    },
    {
      "x": -2,
      "y": 3,
      "z": 0,
      "name": "Wood_Blackwood_Ornate"
    },
    {
      "x": -2,
      "y": 4,
      "z": 0,
      "name": "Wood_Blackwood_Ornate"
    },
    {
      "x": -2,
      "y": 5,
      "z": 0,
      "name": "Wood_Blackwood_Roof_Shallow",
      "filler": 1,
      "rotation": 3
    },
    {
      "x": -2,
      "y": 0,
      "z": 1,
      "name": "Wood_Blackwood_Planks"
    },
    {
      "x": -2,
      "y": 1,
      "z": 1,
      "name": "Furniture_Temple_Scarak_Statue"
    },
    {
      "x": -2,
      "y": 2,
      "z": 1,
      "name": "Furniture_Temple_Scarak_Statue",
      "filler": 1024
    },
    {
      "x": -2,
      "y": 3,
      "z": 1,
      "name": "Furniture_Temple_Scarak_Statue",
      "filler": 2048
    },
    {
      "x": -2,
      "y": 4,
      "z": 1,
      "name": "Deco_Halloween_Lights"
    },
    {
      "x": -2,
      "y": 5,
      "z": 1,
      "name": "Wood_Blackwood_Roof_Shallow",
      "filler": 1,
      "rotation": 3
    },
    {
      "x": -2,
      "y": 0,
      "z": 2,
      "name": "Wood_Blackwood_Planks"
    },
    {
      "x": -2,
      "y": 1,
      "z": 2,
      "name": "Deco_Halloween_Pumpkin_Scary"
    },
    {
      "x": -2,
      "y": 0,
      "z": 3,
      "name": "Deco_Halloween_Pumpkin_Hypixel"
    },
    {
      "x": -1,
      "y": 0,
      "z": -2,
      "name": "Wood_Blackwood_Planks_Half"
    },
    {
      "x": -1,
      "y": 0,
      "z": -1,
      "name": "Wood_Blackwood_Planks"
    },
    {
      "x": -1,
      "y": 5,
      "z": -1,
      "name": "Wood_Blackwood_Beam",
      "rotation": 5
    },
    {
      "x": -1,
      "y": 6,
      "z": -1,
      "name": "Wood_Blackwood_Roof_Flat",
      "rotation": 2
    },
    {
      "x": -1,
      "y": 0,
      "z": 0,
      "name": "Wood_Blackwood_Planks"
    },
    {
      "x": -1,
      "y": 5,
      "z": 0,
      "name": "Wood_Blackwood_Ornate"
    },
    {
      "x": -1,
      "y": 6,
      "z": 0,
      "name": "Wood_Blackwood_Roof_Steep",
      "rotation": 3
    },
    {
      "x": -1,
      "y": 7,
      "z": 0,
      "name": "Wood_Blackwood_Roof_Steep",
      "filler": 1024,
      "rotation": 3
    },
    {
      "x": -1,
      "y": 0,
      "z": 1,
      "name": "Wood_Blackwood_Planks"
    },
    {
      "x": -1,
      "y": 5,
      "z": 1,
      "name": "Wood_Blackwood_Beam",
      "rotation": 5
    },
    {
      "x": -1,
      "y": 6,
      "z": 1,
      "name": "Wood_Blackwood_Roof_Flat"
    },
    {
      "x": -1,
      "y": 0,
      "z": 2,
      "name": "Wood_Blackwood_Planks_Half"
    },
    {
      "x": 0,
      "y": 0,
      "z": -2,
      "name": "Wood_Blackwood_Planks_Half"
    },
    {
      "x": 0,
      "y": 0,
      "z": -1,
      "name": "Wood_Blackwood_Planks"
    },
    {
      "x": 0,
      "y": 5,
      "z": -1,
      "name": "Rock_Crystal_Green_Block",
      "rotation": 4
    },
    {
      "x": 0,
      "y": 6,
      "z": -1,
      "name": "Wood_Blackwood_Roof_Flat",
      "rotation": 2
    },
    {
      "x": 0,
      "y": 0,
      "z": 0,
      "name": "Wood_Blackwood_Planks"
    },
    {
      "x": 0,
      "y": 5,
      "z": 0,
      "name": "Wood_Blackwood_Ornate"
    },
    {
      "x": 0,
      "y": 6,
      "z": 0,
      "name": "Wood_Blackwood_Beam",
      "rotation": 5
    },
    {
      "x": 0,
      "y": 7,
      "z": 0,
      "name": "Rock_Crystal_Green_Block",
      "rotation": 5
    },
    {
      "x": 0,
      "y": 0,
      "z": 1,
      "name": "Wood_Blackwood_Planks"
    },
    {
      "x": 0,
      "y": 5,
      "z": 1,
      "name": "Rock_Crystal_Green_Block",
      "rotation": 4
    },
    {
      "x": 0,
      "y": 6,
      "z": 1,
      "name": "Wood_Blackwood_Roof_Flat"
    },
    {
      "x": 0,
      "y": 0,
      "z": 2,
      "name": "Wood_Blackwood_Planks_Half"
    },
    {
      "x": 1,
      "y": 0,
      "z": -2,
      "name": "Wood_Blackwood_Planks_Half"
    },
    {
      "x": 1,
      "y": 0,
      "z": -1,
      "name": "Wood_Blackwood_Planks"
    },
    {
      "x": 1,
      "y": 5,
      "z": -1,
      "name": "Wood_Blackwood_Beam",
      "rotation": 5
    },
    {
      "x": 1,
      "y": 6,
      "z": -1,
      "name": "Wood_Blackwood_Roof_Flat",
      "rotation": 2
    },
    {
      "x": 1,
      "y": 0,
      "z": 0,
      "name": "Wood_Blackwood_Planks"
    },
    {
      "x": 1,
      "y": 5,
      "z": 0,
      "name": "Wood_Blackwood_Ornate"
    },
    {
      "x": 1,
      "y": 6,
      "z": 0,
      "name": "Wood_Blackwood_Roof_Steep",
      "rotation": 1
    },
    {
      "x": 1,
      "y": 7,
      "z": 0,
      "name": "Wood_Blackwood_Roof_Steep",
      "filler": 1024,
      "rotation": 1
    },
    {
      "x": 1,
      "y": 0,
      "z": 1,
      "name": "Wood_Blackwood_Planks"
    },
    {
      "x": 1,
      "y": 5,
      "z": 1,
      "name": "Wood_Blackwood_Beam",
      "rotation": 5
    },
    {
      "x": 1,
      "y": 6,
      "z": 1,
      "name": "Wood_Blackwood_Roof_Flat"
    },
    {
      "x": 1,
      "y": 0,
      "z": 2,
      "name": "Wood_Blackwood_Planks_Half"
    },
    {
      "x": 2,
      "y": 0,
      "z": -3,
      "name": "Deco_Halloween_Pumpkin_Hypixel",
      "rotation": 2
    },
    {
      "x": 2,
      "y": 0,
      "z": -2,
      "name": "Wood_Blackwood_Planks"
    },
    {
      "x": 2,
      "y": 1,
      "z": -2,
      "name": "Deco_Halloween_Pumpkin_Scary",
      "rotation": 2
    },
    {
      "x": 2,
      "y": 0,
      "z": -1,
      "name": "Wood_Blackwood_Planks"
    },
    {
      "x": 2,
      "y": 1,
      "z": -1,
      "name": "Furniture_Temple_Scarak_Statue",
      "rotation": 2
    },
    {
      "x": 2,
      "y": 2,
      "z": -1,
      "name": "Furniture_Temple_Scarak_Statue",
      "filler": 1024,
      "rotation": 2
    },
    {
      "x": 2,
      "y": 3,
      "z": -1,
      "name": "Furniture_Temple_Scarak_Statue",
      "filler": 2048,
      "rotation": 2
    },
    {
      "x": 2,
      "y": 4,
      "z": -1,
      "name": "Deco_Halloween_Lights",
      "rotation": 2
    },
    {
      "x": 2,
      "y": 5,
      "z": -1,
      "name": "Wood_Blackwood_Roof_Shallow",
      "filler": 31,
      "rotation": 1
    },
    {
      "x": 2,
      "y": 0,
      "z": 0,
      "name": "Wood_Blackwood_Planks"
    },
    {
      "x": 2,
      "y": 1,
      "z": 0,
      "name": "Wood_Blackwood_Ornate"
    },
    {
      "x": 2,
      "y": 2,
      "z": 0,
      "name": "Wood_Blackwood_Ornate"
    },
    {
      "x": 2,
      "y": 3,
      "z": 0,
      "name": "Wood_Blackwood_Ornate"
    },
    {
      "x": 2,
      "y": 4,
      "z": 0,
      "name": "Wood_Blackwood_Ornate"
    },
    {
      "x": 2,
      "y": 5,
      "z": 0,
      "name": "Wood_Blackwood_Roof_Shallow",
      "filler": 31,
      "rotation": 1
    },
    {
      "x": 2,
      "y": 0,
      "z": 1,
      "name": "Wood_Blackwood_Planks"
    },
    {
      "x": 2,
      "y": 1,
      "z": 1,
      "name": "Furniture_Temple_Scarak_Statue"
    },
    {
      "x": 2,
      "y": 2,
      "z": 1,
      "name": "Furniture_Temple_Scarak_Statue",
      "filler": 1024
    },
    {
      "x": 2,
      "y": 3,
      "z": 1,
      "name": "Furniture_Temple_Scarak_Statue",
      "filler": 2048
    },
    {
      "x": 2,
      "y": 4,
      "z": 1,
      "name": "Deco_Halloween_Lights"
    },
    {
      "x": 2,
      "y": 5,
      "z": 1,
      "name": "Wood_Blackwood_Roof_Shallow",
      "filler": 31,
      "rotation": 1
    },
    {
      "x": 2,
      "y": 0,
      "z": 2,
      "name": "Wood_Blackwood_Planks"
    },
    {
      "x": 2,
      "y": 1,
      "z": 2,
      "name": "Deco_Halloween_Pumpkin_Cute"
    },
    {
      "x": 2,
      "y": 0,
      "z": 3,
      "name": "Deco_Halloween_Pumpkin_Cute"
    },
    {
      "x": 3,
      "y": 0,
      "z": -2,
      "name": "Deco_Halloween_Pumpkin_Cute",
      "rotation": 2
    },
    {
      "x": 3,
      "y": 0,
      "z": -1,
      "name": "Wood_Blackwood_Fence",
      "rotation": 2
    },
    {
      "x": 3,
      "y": 4,
      "z": -1,
      "name": "Wood_Sallow_Roots"
    },
    {
      "x": 3,
      "y": 5,
      "z": -1,
      "name": "Wood_Blackwood_Roof_Shallow",
      "rotation": 1
    },
    {
      "x": 3,
      "y": 0,
      "z": 0,
      "name": "Wood_Blackwood_Planks"
    },
    {
      "x": 3,
      "y": 1,
      "z": 0,
      "name": "Furniture_Temple_Scarak_Brazier"
    },
    {
      "x": 3,
      "y": 4,
      "z": 0,
      "name": "Deco_Halloween_Lights",
      "rotation": 1
    },
    {
      "x": 3,
      "y": 5,
      "z": 0,
      "name": "Wood_Blackwood_Roof_Shallow",
      "rotation": 1
    },
    {
      "x": 3,
      "y": 0,
      "z": 1,
      "name": "Wood_Blackwood_Fence"
    },
    {
      "x": 3,
      "y": 4,
      "z": 1,
      "name": "Wood_Sallow_Roots"
    },
    {
      "x": 3,
      "y": 5,
      "z": 1,
      "name": "Wood_Blackwood_Roof_Shallow",
      "rotation": 1
    },
    {
      "x": 3,
      "y": 0,
      "z": 2,
      "name": "Deco_Halloween_Pumpkin_Scary"
    },
    {
      "x": 4,
      "y": 0,
      "z": -1,
      "name": "*Wood_Blackwood_Fence_State_Definitions_Corner"
    },
    {
      "x": 4,
      "y": 0,
      "z": 0,
      "name": "Wood_Blackwood_Fence",
      "rotation": 1
    },
    {
      "x": 4,
      "y": 0,
      "z": 1,
      "name": "*Wood_Blackwood_Fence_State_Definitions_Corner",
      "rotation": 3
    }
  ],
  "fluids": [
    {
      "x": -4,
      "y": 0,
      "z": -1,
      "name": "Empty",
      "level": 0
    },
    {
      "x": -4,
      "y": 0,
      "z": 0,
      "name": "Empty",
      "level": 0
    },
    {
      "x": -4,
      "y": 0,
      "z": 1,
      "name": "Empty",
      "level": 0
    },
    {
      "x": -3,
      "y": 0,
      "z": -2,
      "name": "Empty",
      "level": 0
    },
    {
      "x": -3,
      "y": 0,
      "z": -1,
      "name": "Empty",
      "level": 0
    },
    {
      "x": -3,
      "y": 4,
      "z": -1,
      "name": "Empty",
      "level": 0
    },
    {
      "x": -3,
      "y": 5,
      "z": -1,
      "name": "Empty",
      "level": 0
    },
    {
      "x": -3,
      "y": 0,
      "z": 0,
      "name": "Empty",
      "level": 0
    },
    {
      "x": -3,
      "y": 1,
      "z": 0,
      "name": "Empty",
      "level": 0
    },
    {
      "x": -3,
      "y": 4,
      "z": 0,
      "name": "Empty",
      "level": 0
    },
    {
      "x": -3,
      "y": 5,
      "z": 0,
      "name": "Empty",
      "level": 0
    },
    {
      "x": -3,
      "y": 0,
      "z": 1,
      "name": "Empty",
      "level": 0
    },
    {
      "x": -3,
      "y": 4,
      "z": 1,
      "name": "Empty",
      "level": 0
    },
    {
      "x": -3,
      "y": 5,
      "z": 1,
      "name": "Empty",
      "level": 0
    },
    {
      "x": -3,
      "y": 0,
      "z": 2,
      "name": "Empty",
      "level": 0
    },
    {
      "x": -2,
      "y": 0,
      "z": -3,
      "name": "Empty",
      "level": 0
    },
    {
      "x": -2,
      "y": 0,
      "z": -2,
      "name": "Empty",
      "level": 0
    },
    {
      "x": -2,
      "y": 1,
      "z": -2,
      "name": "Empty",
      "level": 0
    },
    {
      "x": -2,
      "y": 0,
      "z": -1,
      "name": "Empty",
      "level": 0
    },
    {
      "x": -2,
      "y": 1,
      "z": -1,
      "name": "Empty",
      "level": 0
    },
    {
      "x": -2,
      "y": 2,
      "z": -1,
      "name": "Empty",
      "level": 0
    },
    {
      "x": -2,
      "y": 3,
      "z": -1,
      "name": "Empty",
      "level": 0
    },
    {
      "x": -2,
      "y": 4,
      "z": -1,
      "name": "Empty",
      "level": 0
    },
    {
      "x": -2,
      "y": 5,
      "z": -1,
      "name": "Empty",
      "level": 0
    },
    {
      "x": -2,
      "y": 0,
      "z": 0,
      "name": "Empty",
      "level": 0
    },
    {
      "x": -2,
      "y": 1,
      "z": 0,
      "name": "Empty",
      "level": 0
    },
    {
      "x": -2,
      "y": 2,
      "z": 0,
      "name": "Empty",
      "level": 0
    },
    {
      "x": -2,
      "y": 3,
      "z": 0,
      "name": "Empty",
      "level": 0
    },
    {
      "x": -2,
      "y": 4,
      "z": 0,
      "name": "Empty",
      "level": 0
    },
    {
      "x": -2,
      "y": 5,
      "z": 0,
      "name": "Empty",
      "level": 0
    },
    {
      "x": -2,
      "y": 0,
      "z": 1,
      "name": "Empty",
      "level": 0
    },
    {
      "x": -2,
      "y": 1,
      "z": 1,
      "name": "Empty",
      "level": 0
    },
    {
      "x": -2,
      "y": 2,
      "z": 1,
      "name": "Empty",
      "level": 0
    },
    {
      "x": -2,
      "y": 3,
      "z": 1,
      "name": "Empty",
      "level": 0
    },
    {
      "x": -2,
      "y": 4,
      "z": 1,
      "name": "Empty",
      "level": 0
    },
    {
      "x": -2,
      "y": 5,
      "z": 1,
      "name": "Empty",
      "level": 0
    },
    {
      "x": -2,
      "y": 0,
      "z": 2,
      "name": "Empty",
      "level": 0
    },
    {
      "x": -2,
      "y": 1,
      "z": 2,
      "name": "Empty",
      "level": 0
    },
    {
      "x": -2,
      "y": 0,
      "z": 3,
      "name": "Empty",
      "level": 0
    },
    {
      "x": -1,
      "y": 0,
      "z": -2,
      "name": "Empty",
      "level": 0
    },
    {
      "x": -1,
      "y": 0,
      "z": -1,
      "name": "Empty",
      "level": 0
    },
    {
      "x": -1,
      "y": 5,
      "z": -1,
      "name": "Empty",
      "level": 0
    },
    {
      "x": -1,
      "y": 6,
      "z": -1,
      "name": "Empty",
      "level": 0
    },
    {
      "x": -1,
      "y": 0,
      "z": 0,
      "name": "Empty",
      "level": 0
    },
    {
      "x": -1,
      "y": 5,
      "z": 0,
      "name": "Empty",
      "level": 0
    },
    {
      "x": -1,
      "y": 6,
      "z": 0,
      "name": "Empty",
      "level": 0
    },
    {
      "x": -1,
      "y": 7,
      "z": 0,
      "name": "Empty",
      "level": 0
    },
    {
      "x": -1,
      "y": 0,
      "z": 1,
      "name": "Empty",
      "level": 0
    },
    {
      "x": -1,
      "y": 5,
      "z": 1,
      "name": "Empty",
      "level": 0
    },
    {
      "x": -1,
      "y": 6,
      "z": 1,
      "name": "Empty",
      "level": 0
    },
    {
      "x": -1,
      "y": 0,
      "z": 2,
      "name": "Empty",
      "level": 0
    },
    {
      "x": 0,
      "y": 0,
      "z": -2,
      "name": "Empty",
      "level": 0
    },
    {
      "x": 0,
      "y": 0,
      "z": -1,
      "name": "Empty",
      "level": 0
    },
    {
      "x": 0,
      "y": 5,
      "z": -1,
      "name": "Empty",
      "level": 0
    },
    {
      "x": 0,
      "y": 6,
      "z": -1,
      "name": "Empty",
      "level": 0
    },
    {
      "x": 0,
      "y": 0,
      "z": 0,
      "name": "Empty",
      "level": 0
    },
    {
      "x": 0,
      "y": 5,
      "z": 0,
      "name": "Empty",
      "level": 0
    },
    {
      "x": 0,
      "y": 6,
      "z": 0,
      "name": "Empty",
      "level": 0
    },
    {
      "x": 0,
      "y": 7,
      "z": 0,
      "name": "Empty",
      "level": 0
    },
    {
      "x": 0,
      "y": 0,
      "z": 1,
      "name": "Empty",
      "level": 0
    },
    {
      "x": 0,
      "y": 5,
      "z": 1,
      "name": "Empty",
      "level": 0
    },
    {
      "x": 0,
      "y": 6,
      "z": 1,
      "name": "Empty",
      "level": 0
    },
    {
      "x": 0,
      "y": 0,
      "z": 2,
      "name": "Empty",
      "level": 0
    },
    {
      "x": 1,
      "y": 0,
      "z": -2,
      "name": "Empty",
      "level": 0
    },
    {
      "x": 1,
      "y": 0,
      "z": -1,
      "name": "Empty",
      "level": 0
    },
    {
      "x": 1,
      "y": 5,
      "z": -1,
      "name": "Empty",
      "level": 0
    },
    {
      "x": 1,
      "y": 6,
      "z": -1,
      "name": "Empty",
      "level": 0
    },
    {
      "x": 1,
      "y": 0,
      "z": 0,
      "name": "Empty",
      "level": 0
    },
    {
      "x": 1,
      "y": 5,
      "z": 0,
      "name": "Empty",
      "level": 0
    },
    {
      "x": 1,
      "y": 6,
      "z": 0,
      "name": "Empty",
      "level": 0
    },
    {
      "x": 1,
      "y": 7,
      "z": 0,
      "name": "Empty",
      "level": 0
    },
    {
      "x": 1,
      "y": 0,
      "z": 1,
      "name": "Empty",
      "level": 0
    },
    {
      "x": 1,
      "y": 5,
      "z": 1,
      "name": "Empty",
      "level": 0
    },
    {
      "x": 1,
      "y": 6,
      "z": 1,
      "name": "Empty",
      "level": 0
    },
    {
      "x": 1,
      "y": 0,
      "z": 2,
      "name": "Empty",
      "level": 0
    },
    {
      "x": 2,
      "y": 0,
      "z": -3,
      "name": "Empty",
      "level": 0
    },
    {
      "x": 2,
      "y": 0,
      "z": -2,
      "name": "Empty",
      "level": 0
    },
    {
      "x": 2,
      "y": 1,
      "z": -2,
      "name": "Empty",
      "level": 0
    },
    {
      "x": 2,
      "y": 0,
      "z": -1,
      "name": "Empty",
      "level": 0
    },
    {
      "x": 2,
      "y": 1,
      "z": -1,
      "name": "Empty",
      "level": 0
    },
    {
      "x": 2,
      "y": 2,
      "z": -1,
      "name": "Empty",
      "level": 0
    },
    {
      "x": 2,
      "y": 3,
      "z": -1,
      "name": "Empty",
      "level": 0
    },
    {
      "x": 2,
      "y": 4,
      "z": -1,
      "name": "Empty",
      "level": 0
    },
    {
      "x": 2,
      "y": 5,
      "z": -1,
      "name": "Empty",
      "level": 0
    },
    {
      "x": 2,
      "y": 0,
      "z": 0,
      "name": "Empty",
      "level": 0
    },
    {
      "x": 2,
      "y": 1,
      "z": 0,
      "name": "Empty",
      "level": 0
    },
    {
      "x": 2,
      "y": 2,
      "z": 0,
      "name": "Empty",
      "level": 0
    },
    {
      "x": 2,
      "y": 3,
      "z": 0,
      "name": "Empty",
      "level": 0
    },
    {
      "x": 2,
      "y": 4,
      "z": 0,
      "name": "Empty",
      "level": 0
    },
    {
      "x": 2,
      "y": 5,
      "z": 0,
      "name": "Empty",
      "level": 0
    },
    {
      "x": 2,
      "y": 0,
      "z": 1,
      "name": "Empty",
      "level": 0
    },
    {
      "x": 2,
      "y": 1,
      "z": 1,
      "name": "Empty",
      "level": 0
    },
    {
      "x": 2,
      "y": 2,
      "z": 1,
      "name": "Empty",
      "level": 0
    },
    {
      "x": 2,
      "y": 3,
      "z": 1,
      "name": "Empty",
      "level": 0
    },
    {
      "x": 2,
      "y": 4,
      "z": 1,
      "name": "Empty",
      "level": 0
    },
    {
      "x": 2,
      "y": 5,
      "z": 1,
      "name": "Empty",
      "level": 0
    },
    {
      "x": 2,
      "y": 0,
      "z": 2,
      "name": "Empty",
      "level": 0
    },
    {
      "x": 2,
      "y": 1,
      "z": 2,
      "name": "Empty",
      "level": 0
    },
    {
      "x": 2,
      "y": 0,
      "z": 3,
      "name": "Empty",
      "level": 0
    },
    {
      "x": 3,
      "y": 0,
      "z": -2,
      "name": "Empty",
      "level": 0
    },
    {
      "x": 3,
      "y": 0,
      "z": -1,
      "name": "Empty",
      "level": 0
    },
    {
      "x": 3,
      "y": 4,
      "z": -1,
      "name": "Empty",
      "level": 0
    },
    {
      "x": 3,
      "y": 5,
      "z": -1,
      "name": "Empty",
      "level": 0
    },
    {
      "x": 3,
      "y": 0,
      "z": 0,
      "name": "Empty",
      "level": 0
    },
    {
      "x": 3,
      "y": 1,
      "z": 0,
      "name": "Empty",
      "level": 0
    },
    {
      "x": 3,
      "y": 4,
      "z": 0,
      "name": "Empty",
      "level": 0
    },
    {
      "x": 3,
      "y": 5,
      "z": 0,
      "name": "Empty",
      "level": 0
    },
    {
      "x": 3,
      "y": 0,
      "z": 1,
      "name": "Empty",
      "level": 0
    },
    {
      "x": 3,
      "y": 4,
      "z": 1,
      "name": "Empty",
      "level": 0
    },
    {
      "x": 3,
      "y": 5,
      "z": 1,
      "name": "Empty",
      "level": 0
    },
    {
      "x": 3,
      "y": 0,
      "z": 2,
      "name": "Empty",
      "level": 0
    },
    {
      "x": 4,
      "y": 0,
      "z": -1,
      "name": "Empty",
      "level": 0
    },
    {
      "x": 4,
      "y": 0,
      "z": 0,
      "name": "Empty",
      "level": 0
    },
    {
      "x": 4,
      "y": 0,
      "z": 1,
      "name": "Empty",
      "level": 0
    }
  ]
}