{
  "version": 8,
  "blockIdVersion": 11,
  "anchorX": 0,
  "anchorY": 0,
  "anchorZ": 0,
  "blocks": [
    {
      "x": -4,
      "y": 0,
      "z": -1,
      "name": "*Rock_Sandstone_Brick_Wall_State_Definitions_Corner",
      "rotation": 1
    },
    {
      "x": -4,
      "y": 0,
      "z": 0,
      "name": "Rock_Sandstone_Brick_Wall",
      "rotation": 1
    },
    {
      "x": -4,
      "y": 0,
      "z": 1,
      "name": "*Rock_Sandstone_Brick_Wall_State_Definitions_Corner",
      "rotation": 2
    },
    {
      "x": -3,
      "y": 0,
      "z": -1,
      "name": "Rock_Sandstone_Brick_Wall"
    },
    {
      "x": -3,
      "y": 5,
      "z": -1,
      "name": "Rock_Sandstone_Brick_Roof_Shallow",
      "rotation": 3
    },
    {
      "x": -3,
      "y": 0,
      "z": 0,
      "name": "Rock_Sandstone_Brick"
    },
    {
      "x": -3,
      "y": 1,
      "z": 0,
      "name": "Furniture_Dungeon_Earth_Brazier"
    },
    {
      "x": -3,
      "y": 2,
      "z": 0,
      "name": "Furniture_Dungeon_Earth_Brazier",
      "filler": 1024
    },
    {
      "x": -3,
      "y": 5,
      "z": 0,
      "name": "Rock_Sandstone_Brick_Roof_Shallow",
      "rotation": 3
    },
    {
      "x": -3,
      "y": 0,
      "z": 1,
      "name": "Rock_Sandstone_Brick_Wall"
    },
    {
      "x": -3,
      "y": 5,
      "z": 1,
      "name": "Rock_Sandstone_Brick_Roof_Shallow",
      "rotation": 3
    },
    {
      "x": -2,
      "y": 0,
      "z": -2,
      "name": "Rock_Sandstone_Brick"
    },
    {
      "x": -2,
      "y": 0,
      "z": -1,
      "name": "Rock_Sandstone_Brick"
    },
    {
      "x": -2,
      "y": 1,
      "z": -1,
      "name": "Furniture_Temple_Wind_Statue_Gaia",
      "rotation": 2
    },
    {
      "x": -2,
      "y": 2,
      "z": -1,
      "name": "Furniture_Temple_Wind_Statue_Gaia",
      "filler": 1024,
      "rotation": 2
    },
    {
      "x": -2,
      "y": 3,
      "z": -1,
      "name": "Furniture_Temple_Wind_Statue_Gaia",
      "filler": 2048,
      "rotation": 2
    },
    {
      "x": -2,
      "y": 5,
      "z": -1,
      "name": "Rock_Sandstone_Brick_Roof_Shallow",
      "filler": 1,
      "rotation": 3
    },
    {
      "x": -2,
      "y": 0,
      "z": 0,
      "name": "Rock_Sandstone_Brick"
    },
    {
      "x": -2,
      "y": 1,
      "z": 0,
      "name": "Rock_Sandstone_Brick_Pillar_Base"
    },
    {
      "x": -2,
      "y": 2,
      "z": 0,
      "name": "Rock_Sandstone_Brick_Pillar_Middle"
    },
    {
      "x": -2,
      "y": 3,
      "z": 0,
      "name": "Rock_Sandstone_Brick_Pillar_Middle"
    },
    {
      "x": -2,
      "y": 4,
      "z": 0,
      "name": "Rock_Sandstone_Brick_Pillar_Base",
      "rotation": 8
    },
    {
      "x": -2,
      "y": 5,
      "z": 0,
      "name": "Rock_Sandstone_Brick_Roof_Shallow",
      "filler": 1,
      "rotation": 3
    },
    {
      "x": -2,
      "y": 0,
      "z": 1,
      "name": "Rock_Sandstone_Brick"
    },
    {
      "x": -2,
      "y": 1,
      "z": 1,
      "name": "Furniture_Temple_Wind_Statue_Gaia"
    },
    {
      "x": -2,
      "y": 2,
      "z": 1,
      "name": "Furniture_Temple_Wind_Statue_Gaia",
      "filler": 1024
    },
    {
      "x": -2,
      "y": 3,
      "z": 1,
      "name": "Furniture_Temple_Wind_Statue_Gaia",
      "filler": 2048
    },
    {
      "x": -2,
      "y": 5,
      "z": 1,
      "name": "Rock_Sandstone_Brick_Roof_Shallow",
      "filler": 1,
      "rotation": 3
    },
    {
      "x": -2,
      "y": 0,
      "z": 2,
      "name": "Rock_Sandstone_Brick"
    },
    {
      "x": -1,
      "y": 0,
      "z": -2,
      "name": "Rock_Sandstone_Brick_Half"
    },
    {
      "x": -1,
      "y": 0,
      "z": -1,
      "name": "Rock_Sandstone_Brick"
    },
    {
      "x": -1,
      "y": 5,
      "z": -1,
      "name": "Rock_Sandstone_Brick_Beam",
      "rotation": 5
    },
    {
      "x": -1,
      "y": 6,
      "z": -1,
      "name": "Rock_Sandstone_Brick_Roof_Flat",
      "rotation": 2
    },
    {
      "x": -1,
      "y": 0,
      "z": 0,
      "name": "Rock_Sandstone_Brick"
    },
    {
      "x": -1,
      "y": 5,
      "z": 0,
      "name": "Rock_Sandstone_Brick_Ornate"
    },
    {
      "x": -1,
      "y": 6,
      "z": 0,
      "name": "Rock_Sandstone_Brick_Roof_Steep",
      "rotation": 3
    },
    {
      "x": -1,
      "y": 7,
      "z": 0,
      "name": "Rock_Sandstone_Brick_Roof_Steep",
      "filler": 1024,
      "rotation": 3
    },
    {
      "x": -1,
      "y": 0,
      "z": 1,
      "name": "Rock_Sandstone_Brick"
    },
    {
      "x": -1,
      "y": 5,
      "z": 1,
      "name": "Rock_Sandstone_Brick_Beam",
      "rotation": 5
    },
    {
      "x": -1,
      "y": 6,
      "z": 1,
      "name": "Rock_Sandstone_Brick_Roof_Flat"
    },
    {
      "x": -1,
      "y": 0,
      "z": 2,
      "name": "Rock_Sandstone_Brick_Half"
    },
    {
      "x": 0,
      "y": 0,
      "z": -2,
      "name": "Rock_Sandstone_Brick_Half"
    },
    {
      "x": 0,
      "y": 0,
      "z": -1,
      "name": "Rock_Sandstone_Brick"
    },
    {
      "x": 0,
      "y": 5,
      "z": -1,
      "name": "Rock_Crystal_Yellow_Block",
      "rotation": 4
    },
    {
      "x": 0,
      "y": 6,
      "z": -1,
      "name": "Rock_Sandstone_Brick_Roof_Flat",
      "rotation": 2
    },
    {
      "x": 0,
      "y": 0,
      "z": 0,
      "name": "Rock_Sandstone_Brick"
    },
    {
      "x": 0,
      "y": 5,
      "z": 0,
      "name": "Rock_Sandstone_Brick_Ornate"
    },
    {
      "x": 0,
      "y": 6,
      "z": 0,
      "name": "Rock_Sandstone_Brick_Beam",
      "rotation": 5
    },
    {
      "x": 0,
      "y": 7,
      "z": 0,
      "name": "Rock_Crystal_Yellow_Block",
      "rotation": 5
    },
    {
      "x": 0,
      "y": 0,
      "z": 1,
      "name": "Rock_Sandstone_Brick"
    },
    {
      "x": 0,
      "y": 5,
      "z": 1,
      "name": "Rock_Crystal_Yellow_Block",
      "rotation": 4
    },
    {
      "x": 0,
      "y": 6,
      "z": 1,
      "name": "Rock_Sandstone_Brick_Roof_Flat"
    },
    {
      "x": 0,
      "y": 0,
      "z": 2,
      "name": "Rock_Sandstone_Brick_Half"
    },
    {
      "x": 1,
      "y": 0,
      "z": -2,
      "name": "Rock_Sandstone_Brick_Half"
    },
    {
      "x": 1,
      "y": 0,
      "z": -1,
      "name": "Rock_Sandstone_Brick"
    },
    {
      "x": 1,
      "y": 5,
      "z": -1,
      "name": "Rock_Sandstone_Brick_Beam",
      "rotation": 5
    },
    {
      "x": 1,
      "y": 6,
      "z": -1,
      "name": "Rock_Sandstone_Brick_Roof_Flat",
      "rotation": 2
    },
    {
      "x": 1,
      "y": 0,
      "z": 0,
      "name": "Rock_Sandstone_Brick"
    },
    {
      "x": 1,
      "y": 5,
      "z": 0,
      "name": "Rock_Sandstone_Brick_Ornate"
    },
    {
      "x": 1,
      "y": 6,
      "z": 0,
      "name": "Rock_Sandstone_Brick_Roof_Steep",
      "rotation": 1
    },
    {
      "x": 1,
      "y": 7,
      "z": 0,
      "name": "Rock_Sandstone_Brick_Roof_Steep",
      "filler": 1024,
      "rotation": 1
    },
    {
      "x": 1,
      "y": 0,
      "z": 1,
      "name": "Rock_Sandstone_Brick"
    },
    {
      "x": 1,
      "y": 5,
      "z": 1,
      "name": "Rock_Sandstone_Brick_Beam",
      "rotation": 5
    },
    {
      "x": 1,
      "y": 6,
      "z": 1,
      "name": "Rock_Sandstone_Brick_Roof_Flat"
    },
    {
      "x": 1,
      "y": 0,
      "z": 2,
      "name": "Rock_Sandstone_Brick_Half"
    },
    {
      "x": 2,
      "y": 0,
      "z": -2,
      "name": "Rock_Sandstone_Brick"
    },
    {
      "x": 2,
      "y": 0,
      "z": -1,
      "name": "Rock_Sandstone_Brick"
    },
    {
      "x": 2,
      "y": 1,
      "z": -1,
      "name": "Furniture_Temple_Wind_Statue_Gaia",
      "rotation": 2
    },
    {
      "x": 2,
      "y": 2,
      "z": -1,
      "name": "Furniture_Temple_Wind_Statue_Gaia",
      "filler": 1024,
      "rotation": 2
    },
    {
      "x": 2,
      "y": 3,
      "z": -1,
      "name": "Furniture_Temple_Wind_Statue_Gaia",
      "filler": 2048,
      "rotation": 2
    },
    {
      "x": 2,
      "y": 5,
      "z": -1,
      "name": "Rock_Sandstone_Brick_Roof_Shallow",
      "filler": 31,
      "rotation": 1
    },
    {
      "x": 2,
      "y": 0,
      "z": 0,
      "name": "Rock_Sandstone_Brick"
    },
    {
      "x": 2,
      "y": 1,
      "z": 0,
      "name": "Rock_Sandstone_Brick_Pillar_Base"
    },
    {
      "x": 2,
      "y": 2,
      "z": 0,
      "name": "Rock_Sandstone_Brick_Pillar_Middle"
    },
    {
      "x": 2,
      "y": 3,
      "z": 0,
      "name": "Rock_Sandstone_Brick_Pillar_Middle"
    },
    {
      "x": 2,
      "y": 4,
      "z": 0,
      "name": "Rock_Sandstone_Brick_Pillar_Base",
      "rotation": 8
    },
    {
      "x": 2,
      "y": 5,
      "z": 0,
      "name": "Rock_Sandstone_Brick_Roof_Shallow",
      "filler": 31,
      "rotation": 1
    },
    {
      "x": 2,
      "y": 0,
      "z": 1,
      "name": "Rock_Sandstone_Brick"
    },
    {
      "x": 2,
      "y": 1,
      "z": 1,
      "name": "Furniture_Temple_Wind_Statue_Gaia"
    },
    {
      "x": 2,
      "y": 2,
      "z": 1,
      "name": "Furniture_Temple_Wind_Statue_Gaia",
      "filler": 1024
    },
    {
      "x": 2,
      "y": 3,
      "z": 1,
      "name": "Furniture_Temple_Wind_Statue_Gaia",
      "filler": 2048
    },
    {
      "x": 2,
      "y": 5,
      "z": 1,
      "name": "Rock_Sandstone_Brick_Roof_Shallow",
      "filler": 31,
      "rotation": 1
    },
    {
      "x": 2,
      "y": 0,
      "z": 2,
      "name": "Rock_Sandstone_Brick"
    },
    {
      "x": 3,
      "y": 0,
      "z": -1,
      "name": "Rock_Sandstone_Brick_Wall"
    },
    {
      "x": 3,
      "y": 5,
      "z": -1,
      "name": "Rock_Sandstone_Brick_Roof_Shallow",
      "rotation": 1
    },
    {
      "x": 3,
      "y": 0,
      "z": 0,
      "name": "Rock_Sandstone_Brick"
    },
    {
      "x": 3,
      "y": 1,
      "z": 0,
      "name": "Furniture_Dungeon_Earth_Brazier"
    },
    {
      "x": 3,
      "y": 2,
      "z": 0,
      "name": "Furniture_Dungeon_Earth_Brazier",
      "filler": 1024
    },
    {
      "x": 3,
      "y": 5,
      "z": 0,
      "name": "Rock_Sandstone_Brick_Roof_Shallow",
      "rotation": 1
    },
    {
      "x": 3,
      "y": 0,
      "z": 1,
      "name": "Rock_Sandstone_Brick_Wall"
    },
    {
      "x": 3,
      "y": 5,
      "z": 1,
      "name": "Rock_Sandstone_Brick_Roof_Shallow",
      "rotation": 1
    },
    {
      "x": 4,
      "y": 0,
      "z": -1,
      "name": "*Rock_Sandstone_Brick_Wall_State_Definitions_Corner"
    },
    {
      "x": 4,
      "y": 0,
      "z": 0,
      "name": "Rock_Sandstone_Brick_Wall",
      "rotation": 1
    },
    {
      "x": 4,
      "y": 0,
      "z": 1,
      "name": "*Rock_Sandstone_Brick_Wall_State_Definitions_Corner",
      "rotation": 3
    }
  ],
  "fluids": [
    {
      "x": -4,
      "y": 0,
      "z": -1,
      "name": "Empty",
      "level": 0
    },
    {
      "x": -4,
      "y": 0,
      "z": 0,
      "name": "Empty",
      "level": 0
    },
    {
      "x": -4,
      "y": 0,
      "z": 1,
      "name": "Empty",
      "level": 0
    },
    {
      "x": -3,
      "y": 0,
      "z": -1,
      "name": "Empty",
      "level": 0
    },
    {
      "x": -3,
      "y": 5,
      "z": -1,
      "name": "Empty",
      "level": 0
    },
    {
      "x": -3,
      "y": 0,
      "z": 0,
      "name": "Empty",
      "level": 0
    },
    {
      "x": -3,
      "y": 1,
      "z": 0,
      "name": "Empty",
      "level": 0
    },
    {
      "x": -3,
      "y": 2,
      "z": 0,
      "name": "Empty",
      "level": 0
    },
    {
      "x": -3,
      "y": 5,
      "z": 0,
      "name": "Empty",
      "level": 0
    },
    {
      "x": -3,
      "y": 0,
      "z": 1,
      "name": "Empty",
      "level": 0
    },
    {
      "x": -3,
      "y": 5,
      "z": 1,
      "name": "Empty",
      "level": 0
    },
    {
      "x": -2,
      "y": 0,
      "z": -2,
      "name": "Empty",
      "level": 0
    },
    {
      "x": -2,
      "y": 0,
      "z": -1,
      "name": "Empty",
      "level": 0
    },
    {
      "x": -2,
      "y": 1,
      "z": -1,
      "name": "Empty",
      "level": 0
    },
    {
      "x": -2,
      "y": 2,
      "z": -1,
      "name": "Empty",
      "level": 0
    },
    {
      "x": -2,
      "y": 3,
      "z": -1,
      "name": "Empty",
      "level": 0
    },
    {
      "x": -2,
      "y": 5,
      "z": -1,
      "name": "Empty",
      "level": 0
    },
    {
      "x": -2,
      "y": 0,
      "z": 0,
      "name": "Empty",
      "level": 0
    },
    {
      "x": -2,
      "y": 1,
      "z": 0,
      "name": "Empty",
      "level": 0
    },
    {
      "x": -2,
      "y": 2,
      "z": 0,
      "name": "Empty",
      "level": 0
    },
    {
      "x": -2,
      "y": 3,
      "z": 0,
      "name": "Empty",
      "level": 0
    },
    {
      "x": -2,
      "y": 4,
      "z": 0,
      "name": "Empty",
      "level": 0
    },
    {
      "x": -2,
      "y": 5,
      "z": 0,
      "name": "Empty",
      "level": 0
    },
    {
      "x": -2,
      "y": 0,
      "z": 1,
      "name": "Empty",
      "level": 0
    },
    {
      "x": -2,
      "y": 1,
      "z": 1,
      "name": "Empty",
      "level": 0
    },
    {
      "x": -2,
      "y": 2,
      "z": 1,
      "name": "Empty",
      "level": 0
    },
    {
      "x": -2,
      "y": 3,
      "z": 1,
      "name": "Empty",
      "level": 0
    },
    {
      "x": -2,
      "y": 5,
      "z": 1,
      "name": "Empty",
      "level": 0
    },
    {
      "x": -2,
      "y": 0,
      "z": 2,
      "name": "Empty",
      "level": 0
    },
    {
      "x": -1,
      "y": 0,
      "z": -2,
      "name": "Empty",
      "level": 0
    },
    {
      "x": -1,
      "y": 0,
      "z": -1,
      "name": "Empty",
      "level": 0
    },
    {
      "x": -1,
      "y": 5,
      "z": -1,
      "name": "Empty",
      "level": 0
    },
    {
      "x": -1,
      "y": 6,
      "z": -1,
      "name": "Empty",
      "level": 0
    },
    {
      "x": -1,
      "y": 0,
      "z": 0,
      "name": "Empty",
      "level": 0
    },
    {
      "x": -1,
      "y": 5,
      "z": 0,
      "name": "Empty",
      "level": 0
    },
    {
      "x": -1,
      "y": 6,
      "z": 0,
      "name": "Empty",
      "level": 0
    },
    {
      "x": -1,
      "y": 7,
      "z": 0,
      "name": "Empty",
      "level": 0
    },
    {
      "x": -1,
      "y": 0,
      "z": 1,
      "name": "Empty",
      "level": 0
    },
    {
      "x": -1,
      "y": 5,
      "z": 1,
      "name": "Empty",
      "level": 0
    },
    {
      "x": -1,
      "y": 6,
      "z": 1,
      "name": "Empty",
      "level": 0
    },
    {
      "x": -1,
      "y": 0,
      "z": 2,
      "name": "Empty",
      "level": 0
    },
    {
      "x": 0,
      "y": 0,
      "z": -2,
      "name": "Empty",
      "level": 0
    },
    {
      "x": 0,
      "y": 0,
      "z": -1,
      "name": "Empty",
      "level": 0
    },
    {
      "x": 0,
      "y": 5,
      "z": -1,
      "name": "Empty",
      "level": 0
    },
    {
      "x": 0,
      "y": 6,
      "z": -1,
      "name": "Empty",
      "level": 0
    },
    {
      "x": 0,
      "y": 0,
      "z": 0,
      "name": "Empty",
      "level": 0
    },
    {
      "x": 0,
      "y": 5,
      "z": 0,
      "name": "Empty",
      "level": 0
    },
    {
      "x": 0,
      "y": 6,
      "z": 0,
      "name": "Empty",
      "level": 0
    },
    {
      "x": 0,
      "y": 7,
      "z": 0,
      "name": "Empty",
      "level": 0
    },
    {
      "x": 0,
      "y": 0,
      "z": 1,
      "name": "Empty",
      "level": 0
    },
    {
      "x": 0,
      "y": 5,
      "z": 1,
      "name": "Empty",
      "level": 0
    },
    {
      "x": 0,
      "y": 6,
      "z": 1,
      "name": "Empty",
      "level": 0
    },
    {
      "x": 0,
      "y": 0,
      "z": 2,
      "name": "Empty",
      "level": 0
    },
    {
      "x": 1,
      "y": 0,
      "z": -2,
      "name": "Empty",
      "level": 0
    },
    {
      "x": 1,
      "y": 0,
      "z": -1,
      "name": "Empty",
      "level": 0
    },
    {
      "x": 1,
      "y": 5,
      "z": -1,
      "name": "Empty",
      "level": 0
    },
    {
      "x": 1,
      "y": 6,
      "z": -1,
      "name": "Empty",
      "level": 0
    },
    {
      "x": 1,
      "y": 0,
      "z": 0,
      "name": "Empty",
      "level": 0
    },
    {
      "x": 1,
      "y": 5,
      "z": 0,
      "name": "Empty",
      "level": 0
    },
    {
      "x": 1,
      "y": 6,
      "z": 0,
      "name": "Empty",
      "level": 0
    },
    {
      "x": 1,
      "y": 7,
      "z": 0,
      "name": "Empty",
      "level": 0
    },
    {
      "x": 1,
      "y": 0,
      "z": 1,
      "name": "Empty",
      "level": 0
    },
    {
      "x": 1,
      "y": 5,
      "z": 1,
      "name": "Empty",
      "level": 0
    },
    {
      "x": 1,
      "y": 6,
      "z": 1,
      "name": "Empty",
      "level": 0
    },
    {
      "x": 1,
      "y": 0,
      "z": 2,
      "name": "Empty",
      "level": 0
    },
    {
      "x": 2,
      "y": 0,
      "z": -2,
      "name": "Empty",
      "level": 0
    },
    {
      "x": 2,
      "y": 0,
      "z": -1,
      "name": "Empty",
      "level": 0
    },
    {
      "x": 2,
      "y": 1,
      "z": -1,
      "name": "Empty",
      "level": 0
    },
    {
      "x": 2,
      "y": 2,
      "z": -1,
      "name": "Empty",
      "level": 0
    },
    {
      "x": 2,
      "y": 3,
      "z": -1,
      "name": "Empty",
      "level": 0
    },
    {
      "x": 2,
      "y": 5,
      "z": -1,
      "name": "Empty",
      "level": 0
    },
    {
      "x": 2,
      "y": 0,
      "z": 0,
      "name": "Empty",
      "level": 0
    },
    {
      "x": 2,
      "y": 1,
      "z": 0,
      "name": "Empty",
      "level": 0
    },
    {
      "x": 2,
      "y": 2,
      "z": 0,
      "name": "Empty",
      "level": 0
    },
    {
      "x": 2,
      "y": 3,
      "z": 0,
      "name": "Empty",
      "level": 0
    },
    {
      "x": 2,
      "y": 4,
      "z": 0,
      "name": "Empty",
      "level": 0
    },
    {
      "x": 2,
      "y": 5,
      "z": 0,
      "name": "Empty",
      "level": 0
    },
    {
      "x": 2,
      "y": 0,
      "z": 1,
      "name": "Empty",
      "level": 0
    },
    {
      "x": 2,
      "y": 1,
      "z": 1,
      "name": "Empty",
      "level": 0
    },
    {
      "x": 2,
      "y": 2,
      "z": 1,
      "name": "Empty",
      "level": 0
    },
    {
      "x": 2,
      "y": 3,
      "z": 1,
      "name": "Empty",
      "level": 0
    },
    {
      "x": 2,
      "y": 5,
      "z": 1,
      "name": "Empty",
      "level": 0
    },
    {
      "x": 2,
      "y": 0,
      "z": 2,
      "name": "Empty",
      "level": 0
    },
    {
      "x": 3,
      "y": 0,
      "z": -1,
      "name": "Empty",
      "level": 0
    },
    {
      "x": 3,
      "y": 5,
      "z": -1,
      "name": "Empty",
      "level": 0
    },
    {
      "x": 3,
      "y": 0,
      "z": 0,
      "name": "Empty",
      "level": 0
    },
    {
      "x": 3,
      "y": 1,
      "z": 0,
      "name": "Empty",
      "level": 0
    },
    {
      "x": 3,
      "y": 2,
      "z": 0,
      "name": "Empty",
      "level": 0
    },
    {
      "x": 3,
      "y": 5,
      "z": 0,
      "name": "Empty",
      "level": 0
    },
    {
      "x": 3,
      "y": 0,
      "z": 1,
      "name": "Empty",
      "level": 0
    },
    {
      "x": 3,
      "y": 5,
      "z": 1,
      "name": "Empty",
      "level": 0
    },
    {
      "x": 4,
      "y": 0,
      "z": -1,
      "name": "Empty",
      "level": 0
    },
    {
      "x": 4,
      "y": 0,
      "z": 0,
      "name": "Empty",
      "level": 0
    },
    {
      "x": 4,
      "y": 0,
      "z": 1,
      "name": "Empty",
      "level": 0
    }
  ]
}