{
  "version": 8,
  "blockIdVersion": 11,
  "anchorX": 0,
  "anchorY": 0,
  "anchorZ": 0,
  "blocks": [
    {
      "x": -24,
      "y": 0,
      "z": -18,
      "name": "Rock_Stone_Brick",
      "rotation": 3
    },
    {
      "x": -24,
      "y": 1,
      "z": -18,
      "name": "Rock_Stone_Brick"
    },
    {
      "x": -24,
      "y": 2,
      "z": -18,
      "name": "Rock_Stone_Brick"
    },
    {
      "x": -24,
      "y": 3,
      "z": -18,
      "name": "Rock_Stone_Brick"
    },
    {
      "x": -24,
      "y": 4,
      "z": -18,
      "name": "Rock_Stone_Brick"
    },
    {
      "x": -24,
      "y": 0,
      "z": -17,
      "name": "Rock_Stone_Brick",
      "rotation": 3
    },
    {
      "x": -24,
      "y": 1,
      "z": -17,
      "name": "Rock_Stone_Brick"
    },
    {
      "x": -24,
      "y": 4,
      "z": -17,
      "name": "Rock_Stone_Brick"
    },
    {
      "x": -24,
      "y": 0,
      "z": -16,
      "name": "Rock_Stone_Brick",
      "rotation": 3
    },
    {
      "x": -24,
      "y": 1,
      "z": -16,
      "name": "Rock_Stone_Brick"
    },
    {
      "x": -24,
      "y": 4,
      "z": -16,
      "name": "Rock_Stone_Brick"
    },
    {
      "x": -24,
      "y": 0,
      "z": -15,
      "name": "Rock_Stone_Brick",
      "rotation": 3
    },
    {
      "x": -24,
      "y": 1,
      "z": -15,
      "name": "Rock_Stone_Brick"
    },
    {
      "x": -24,
      "y": 4,
      "z": -15,
      "name": "Rock_Stone_Brick"
    },
    {
      "x": -24,
      "y": 0,
      "z": -14,
      "name": "Rock_Stone_Brick",
      "rotation": 3
    },
    {
      "x": -24,
      "y": 1,
      "z": -14,
      "name": "Rock_Stone_Brick"
    },
    {
      "x": -24,
      "y": 4,
      "z": -14,
      "name": "Rock_Stone_Brick"
    },
    {
      "x": -24,
      "y": 0,
      "z": -13,
      "name": "Rock_Stone_Brick",
      "rotation": 3
    },
    {
      "x": -24,
      "y": 1,
      "z": -13,
      "name": "Rock_Stone_Brick"
    },
    {
      "x": -24,
      "y": 4,
      "z": -13,
      "name": "Rock_Stone_Brick"
    },
    {
      "x": -24,
      "y": 0,
      "z": -12,
      "name": "Rock_Stone_Brick",
      "rotation": 3
    },
    {
      "x": -24,
      "y": 1,
      "z": -12,
      "name": "Rock_Stone_Brick"
    },
    {
      "x": -24,
      "y": 2,
      "z": -12,
      "name": "Rock_Stone_Brick"
    },
    {
      "x": -24,
      "y": 3,
      "z": -12,
      "name": "Rock_Stone_Brick"
    },
    {
      "x": -24,
      "y": 4,
      "z": -12,
      "name": "Rock_Stone_Brick"
    },
    {
      "x": -24,
      "y": 0,
      "z": -11,
      "name": "Rock_Stone_Brick"
    },
    {
      "x": -24,
      "y": 1,
      "z": -11,
      "name": "Rock_Stone_Brick"
    },
    {
      "x": -24,
      "y": 2,
      "z": -11,
      "name": "Rock_Stone_Brick"
    },
    {
      "x": -24,
      "y": 3,
      "z": -11,
      "name": "Rock_Stone_Brick"
    },
    {
      "x": -24,
      "y": 4,
      "z": -11,
      "name": "Rock_Stone_Brick"
    },
    {
      "x": -24,
      "y": 0,
      "z": -10,
      "name": "Rock_Stone_Brick"
    },
    {
      "x": -24,
      "y": 1,
      "z": -10,
      "name": "Rock_Stone_Brick"
    },
    {
      "x": -24,
      "y": 4,
      "z": -10,
      "name": "Rock_Stone_Brick"
    },
    {
      "x": -24,
      "y": 0,
      "z": -9,
      "name": "Rock_Stone_Brick"
    },
    {
      "x": -24,
      "y": 1,
      "z": -9,
      "name": "Rock_Stone_Brick"
    },
    {
      "x": -24,
      "y": 2,
      "z": -9,
      "name": "Rock_Stone_Brick"
    },
    {
      "x": -24,
      "y": 3,
      "z": -9,
      "name": "Rock_Stone_Brick"
    },
    {
      "x": -24,
      "y": 4,
      "z": -9,
      "name": "Rock_Stone_Brick"
    },
    {
      "x": -24,
      "y": 0,
      "z": -8,
      "name": "Rock_Stone_Brick",
      "rotation": 1
    },
    {
      "x": -24,
      "y": 4,
      "z": -8,
      "name": "Rock_Stone_Brick",
      "rotation": 1
    },
    {
      "x": -24,
      "y": 0,
      "z": -7,
      "name": "Rock_Stone_Brick",
      "rotation": 1
    },
    {
      "x": -24,
      "y": 1,
      "z": -7,
      "name": "Rock_Stone_Brick",
      "rotation": 1
    },
    {
      "x": -24,
      "y": 2,
      "z": -7,
      "name": "Rock_Stone_Brick",
      "rotation": 1
    },
    {
      "x": -24,
      "y": 3,
      "z": -7,
      "name": "Rock_Stone_Brick",
      "rotation": 1
    },
    {
      "x": -24,
      "y": 4,
      "z": -7,
      "name": "Rock_Stone_Brick",
      "rotation": 1
    },
    {
      "x": -24,
      "y": 0,
      "z": -6,
      "name": "Rock_Stone_Brick",
      "rotation": 1
    },
    {
      "x": -24,
      "y": 4,
      "z": -6,
      "name": "Rock_Stone_Brick",
      "rotation": 1
    },
    {
      "x": -24,
      "y": 0,
      "z": -5,
      "name": "Rock_Stone_Brick",
      "rotation": 1
    },
    {
      "x": -24,
      "y": 1,
      "z": -5,
      "name": "Rock_Stone_Brick",
      "rotation": 1
    },
    {
      "x": -24,
      "y": 2,
      "z": -5,
      "name": "Rock_Stone_Brick",
      "rotation": 1
    },
    {
      "x": -24,
      "y": 3,
      "z": -5,
      "name": "Rock_Stone_Brick",
      "rotation": 1
    },
    {
      "x": -24,
      "y": 4,
      "z": -5,
      "name": "Rock_Stone_Brick",
      "rotation": 1
    },
    {
      "x": -24,
      "y": 0,
      "z": -4,
      "name": "Rock_Stone_Brick"
    },
    {
      "x": -24,
      "y": 4,
      "z": -4,
      "name": "Rock_Stone_Brick",
      "rotation": 1
    },
    {
      "x": -24,
      "y": 0,
      "z": -3,
      "name": "Rock_Stone_Brick"
    },
    {
      "x": -24,
      "y": 4,
      "z": -3,
      "name": "Rock_Stone_Brick",
      "rotation": 1
    },
    {
      "x": -24,
      "y": 0,
      "z": -2,
      "name": "Rock_Stone_Brick"
    },
    {
      "x": -24,
      "y": 4,
      "z": -2,
      "name": "Rock_Stone_Brick",
      "rotation": 1
    },
    {
      "x": -24,
      "y": 0,
      "z": -1,
      "name": "Rock_Stone_Brick"
    },
    {
      "x": -24,
      "y": 4,
      "z": -1,
      "name": "Rock_Stone_Brick",
      "rotation": 1
    },
    {
      "x": -24,
      "y": 0,
      "z": 0,
      "name": "Rock_Stone_Brick"
    },
    {
      "x": -24,
      "y": 4,
      "z": 0,
      "name": "Rock_Stone_Brick",
      "rotation": 1
    },
    {
      "x": -24,
      "y": 0,
      "z": 1,
      "name": "Rock_Stone_Brick"
    },
    {
      "x": -24,
      "y": 4,
      "z": 1,
      "name": "Rock_Stone_Brick",
      "rotation": 1
    },
    {
      "x": -24,
      "y": 0,
      "z": 2,
      "name": "Rock_Stone_Brick",
      "rotation": 1
    },
    {
      "x": -24,
      "y": 1,
      "z": 2,
      "name": "Rock_Stone_Brick",
      "rotation": 1
    },
    {
      "x": -24,
      "y": 2,
      "z": 2,
      "name": "Rock_Stone_Brick",
      "rotation": 1
    },
    {
      "x": -24,
      "y": 3,
      "z": 2,
      "name": "Rock_Stone_Brick",
      "rotation": 1
    },
    {
      "x": -24,
      "y": 4,
      "z": 2,
      "name": "Rock_Stone_Brick",
      "rotation": 1
    },
    {
      "x": -24,
      "y": 0,
      "z": 3,
      "name": "Rock_Stone_Brick",
      "rotation": 1
    },
    {
      "x": -24,
      "y": 4,
      "z": 3,
      "name": "Rock_Stone_Brick",
      "rotation": 1
    },
    {
      "x": -24,
      "y": 0,
      "z": 4,
      "name": "Rock_Stone_Brick",
      "rotation": 1
    },
    {
      "x": -24,
      "y": 1,
      "z": 4,
      "name": "Rock_Stone_Brick",
      "rotation": 1
    },
    {
      "x": -24,
      "y": 2,
      "z": 4,
      "name": "Rock_Stone_Brick",
      "rotation": 1
    },
    {
      "x": -24,
      "y": 3,
      "z": 4,
      "name": "Rock_Stone_Brick",
      "rotation": 1
    },
    {
      "x": -24,
      "y": 4,
      "z": 4,
      "name": "Rock_Stone_Brick",
      "rotation": 1
    },
    {
      "x": -24,
      "y": 0,
      "z": 5,
      "name": "Rock_Stone_Brick",
      "rotation": 1
    },
    {
      "x": -24,
      "y": 1,
      "z": 5,
      "name": "Rock_Stone_Brick",
      "rotation": 1
    },
    {
      "x": -24,
      "y": 2,
      "z": 5,
      "name": "Rock_Stone_Brick",
      "rotation": 1
    },
    {
      "x": -24,
      "y": 3,
      "z": 5,
      "name": "Rock_Stone_Brick",
      "rotation": 1
    },
    {
      "x": -24,
      "y": 4,
      "z": 5,
      "name": "Rock_Stone_Brick",
      "rotation": 1
    },
    {
      "x": -24,
      "y": 0,
      "z": 6,
      "name": "Rock_Stone_Brick",
      "rotation": 1
    },
    {
      "x": -24,
      "y": 4,
      "z": 6,
      "name": "Rock_Stone_Brick",
      "rotation": 1
    },
    {
      "x": -24,
      "y": 0,
      "z": 7,
      "name": "Rock_Stone_Brick"
    },
    {
      "x": -24,
      "y": 1,
      "z": 7,
      "name": "Rock_Stone_Brick",
      "rotation": 1
    },
    {
      "x": -24,
      "y": 2,
      "z": 7,
      "name": "Rock_Stone_Brick",
      "rotation": 1
    },
    {
      "x": -24,
      "y": 3,
      "z": 7,
      "name": "Rock_Stone_Brick",
      "rotation": 1
    },
    {
      "x": -24,
      "y": 4,
      "z": 7,
      "name": "Rock_Stone_Brick",
      "rotation": 1
    },
    {
      "x": -24,
      "y": 0,
      "z": 8,
      "name": "Rock_Stone_Brick"
    },
    {
      "x": -24,
      "y": 1,
      "z": 8,
      "name": "Rock_Stone_Brick",
      "rotation": 1
    },
    {
      "x": -24,
      "y": 4,
      "z": 8,
      "name": "Rock_Stone_Brick",
      "rotation": 1
    },
    {
      "x": -24,
      "y": 0,
      "z": 9,
      "name": "Rock_Stone_Brick"
    },
    {
      "x": -24,
      "y": 1,
      "z": 9,
      "name": "Rock_Stone_Brick",
      "rotation": 1
    },
    {
      "x": -24,
      "y": 2,
      "z": 9,
      "name": "Rock_Stone_Brick",
      "rotation": 1
    },
    {
      "x": -24,
      "y": 3,
      "z": 9,
      "name": "Rock_Stone_Brick",
      "rotation": 1
    },
    {
      "x": -24,
      "y": 4,
      "z": 9,
      "name": "Rock_Stone_Brick",
      "rotation": 1
    },
    {
      "x": -24,
      "y": 0,
      "z": 10,
      "name": "Rock_Stone_Brick"
    },
    {
      "x": -24,
      "y": 1,
      "z": 10,
      "name": "Rock_Stone_Brick",
      "rotation": 1
    },
    {
      "x": -24,
      "y": 2,
      "z": 10,
      "name": "Rock_Stone_Brick",
      "rotation": 1
    },
    {
      "x": -24,
      "y": 3,
      "z": 10,
      "name": "Rock_Stone_Brick",
      "rotation": 1
    },
    {
      "x": -24,
      "y": 4,
      "z": 10,
      "name": "Rock_Stone_Brick",
      "rotation": 1
    },
    {
      "x": -24,
      "y": 0,
      "z": 11,
      "name": "Rock_Stone_Brick"
    },
    {
      "x": -24,
      "y": 1,
      "z": 11,
      "name": "Rock_Stone_Brick",
      "rotation": 1
    },
    {
      "x": -24,
      "y": 4,
      "z": 11,
      "name": "Rock_Stone_Brick",
      "rotation": 1
    },
    {
      "x": -24,
      "y": 0,
      "z": 12,
      "name": "Rock_Stone_Brick"
    },
    {
      "x": -24,
      "y": 1,
      "z": 12,
      "name": "Rock_Stone_Brick",
      "rotation": 1
    },
    {
      "x": -24,
      "y": 4,
      "z": 12,
      "name": "Rock_Stone_Brick",
      "rotation": 1
    },
    {
      "x": -24,
      "y": 0,
      "z": 13,
      "name": "Rock_Stone_Brick"
    },
    {
      "x": -24,
      "y": 1,
      "z": 13,
      "name": "Rock_Stone_Brick",
      "rotation": 1
    },
    {
      "x": -24,
      "y": 4,
      "z": 13,
      "name": "Rock_Stone_Brick",
      "rotation": 1
    },
    {
      "x": -24,
      "y": 0,
      "z": 14,
      "name": "Rock_Stone_Brick"
    },
    {
      "x": -24,
      "y": 1,
      "z": 14,
      "name": "Rock_Stone_Brick",
      "rotation": 1
    },
    {
      "x": -24,
      "y": 4,
      "z": 14,
      "name": "Rock_Stone_Brick",
      "rotation": 1
    },
    {
      "x": -24,
      "y": 0,
      "z": 15,
      "name": "Rock_Stone_Brick"
    },
    {
      "x": -24,
      "y": 1,
      "z": 15,
      "name": "Rock_Stone_Brick",
      "rotation": 1
    },
    {
      "x": -24,
      "y": 4,
      "z": 15,
      "name": "Rock_Stone_Brick",
      "rotation": 1
    },
    {
      "x": -24,
      "y": 0,
      "z": 16,
      "name": "Rock_Stone_Brick"
    },
    {
      "x": -24,
      "y": 1,
      "z": 16,
      "name": "Rock_Stone_Brick",
      "rotation": 1
    },
    {
      "x": -24,
      "y": 4,
      "z": 16,
      "name": "Rock_Stone_Brick",
      "rotation": 1
    },
    {
      "x": -24,
      "y": 0,
      "z": 17,
      "name": "Rock_Stone_Brick"
    },
    {
      "x": -24,
      "y": 1,
      "z": 17,
      "name": "Rock_Stone_Brick",
      "rotation": 1
    },
    {
      "x": -24,
      "y": 4,
      "z": 17,
      "name": "Rock_Stone_Brick",
      "rotation": 1
    },
    {
      "x": -24,
      "y": 0,
      "z": 18,
      "name": "Rock_Stone_Brick"
    },
    {
      "x": -24,
      "y": 1,
      "z": 18,
      "name": "Rock_Stone_Brick",
      "rotation": 1
    },
    {
      "x": -24,
      "y": 2,
      "z": 18,
      "name": "Rock_Stone_Brick",
      "rotation": 1
    },
    {
      "x": -24,
      "y": 3,
      "z": 18,
      "name": "Rock_Stone_Brick",
      "rotation": 1
    },
    {
      "x": -24,
      "y": 4,
      "z": 18,
      "name": "Rock_Stone_Brick",
      "rotation": 1
    },
    {
      "x": -23,
      "y": 0,
      "z": -20,
      "name": "Rock_Stone_Brick",
      "rotation": 3
    },
    {
      "x": -23,
      "y": 1,
      "z": -20,
      "name": "Rock_Stone_Brick"
    },
    {
      "x": -23,
      "y": 2,
      "z": -20,
      "name": "Rock_Stone_Brick"
    },
    {
      "x": -23,
      "y": 3,
      "z": -20,
      "name": "Rock_Stone_Brick"
    },
    {
      "x": -23,
      "y": 4,
      "z": -20,
      "name": "Rock_Stone_Brick"
    },
    {
      "x": -23,
      "y": 0,
      "z": -19,
      "name": "Rock_Stone_Brick",
      "rotation": 3
    },
    {
      "x": -23,
      "y": 1,
      "z": -19,
      "name": "Rock_Stone_Brick"
    },
    {
      "x": -23,
      "y": 2,
      "z": -19,
      "name": "Rock_Stone_Brick"
    },
    {
      "x": -23,
      "y": 3,
      "z": -19,
      "name": "Rock_Stone_Brick"
    },
    {
      "x": -23,
      "y": 4,
      "z": -19,
      "name": "Rock_Stone_Brick"
    },
    {
      "x": -23,
      "y": 0,
      "z": -18,
      "name": "Rock_Stone_Brick",
      "rotation": 3
    },
    {
      "x": -23,
      "y": 1,
      "z": -18,
      "name": "Rock_Stone_Brick"
    },
    {
      "x": -23,
      "y": 2,
      "z": -18,
      "name": "Rock_Stone_Brick"
    },
    {
      "x": -23,
      "y": 3,
      "z": -18,
      "name": "Rock_Stone_Brick"
    },
    {
      "x": -23,
      "y": 4,
      "z": -18,
      "name": "Rock_Stone_Brick"
    },
    {
      "x": -23,
      "y": 4,
      "z": -17,
      "name": "Wood_Hardwood_Planks"
    },
    {
      "x": -23,
      "y": 4,
      "z": -16,
      "name": "Wood_Hardwood_Planks"
    },
    {
      "x": -23,
      "y": 4,
      "z": -15,
      "name": "Wood_Hardwood_Planks"
    },
    {
      "x": -23,
      "y": 4,
      "z": -14,
      "name": "Wood_Hardwood_Planks"
    },
    {
      "x": -23,
      "y": 4,
      "z": -13,
      "name": "Wood_Hardwood_Planks"
    },
    {
      "x": -23,
      "y": 4,
      "z": -12,
      "name": "Wood_Hardwood_Planks"
    },
    {
      "x": -23,
      "y": 4,
      "z": -11,
      "name": "Wood_Hardwood_Planks"
    },
    {
      "x": -23,
      "y": 4,
      "z": -10,
      "name": "Wood_Hardwood_Planks"
    },
    {
      "x": -23,
      "y": 4,
      "z": -9,
      "name": "Wood_Hardwood_Planks"
    },
    {
      "x": -23,
      "y": 4,
      "z": -8,
      "name": "Wood_Hardwood_Planks"
    },
    {
      "x": -23,
      "y": 4,
      "z": -7,
      "name": "Wood_Hardwood_Planks"
    },
    {
      "x": -23,
      "y": 4,
      "z": -6,
      "name": "Wood_Hardwood_Planks"
    },
    {
      "x": -23,
      "y": 4,
      "z": -5,
      "name": "Wood_Hardwood_Planks"
    },
    {
      "x": -23,
      "y": 4,
      "z": -4,
      "name": "Wood_Hardwood_Planks"
    },
    {
      "x": -23,
      "y": 4,
      "z": -3,
      "name": "Wood_Hardwood_Planks"
    },
    {
      "x": -23,
      "y": 4,
      "z": -2,
      "name": "Wood_Hardwood_Planks"
    },
    {
      "x": -23,
      "y": 4,
      "z": -1,
      "name": "Wood_Hardwood_Planks"
    },
    {
      "x": -23,
      "y": 4,
      "z": 0,
      "name": "Wood_Hardwood_Planks"
    },
    {
      "x": -23,
      "y": 4,
      "z": 1,
      "name": "Wood_Hardwood_Planks"
    },
    {
      "x": -23,
      "y": 4,
      "z": 2,
      "name": "Wood_Hardwood_Planks"
    },
    {
      "x": -23,
      "y": 4,
      "z": 3,
      "name": "Wood_Hardwood_Planks"
    },
    {
      "x": -23,
      "y": 4,
      "z": 4,
      "name": "Wood_Hardwood_Planks"
    },
    {
      "x": -23,
      "y": 4,
      "z": 5,
      "name": "Wood_Hardwood_Planks"
    },
    {
      "x": -23,
      "y": 4,
      "z": 6,
      "name": "Wood_Hardwood_Planks"
    },
    {
      "x": -23,
      "y": 4,
      "z": 7,
      "name": "Wood_Hardwood_Planks"
    },
    {
      "x": -23,
      "y": 4,
      "z": 8,
      "name": "Wood_Hardwood_Planks"
    },
    {
      "x": -23,
      "y": 4,
      "z": 9,
      "name": "Wood_Hardwood_Planks"
    },
    {
      "x": -23,
      "y": 4,
      "z": 10,
      "name": "Wood_Hardwood_Planks"
    },
    {
      "x": -23,
      "y": 4,
      "z": 11,
      "name": "Wood_Hardwood_Planks"
    },
    {
      "x": -23,
      "y": 4,
      "z": 12,
      "name": "Wood_Hardwood_Planks"
    },
    {
      "x": -23,
      "y": 4,
      "z": 13,
      "name": "Wood_Hardwood_Planks"
    },
    {
      "x": -23,
      "y": 4,
      "z": 14,
      "name": "Wood_Hardwood_Planks"
    },
    {
      "x": -23,
      "y": 4,
      "z": 15,
      "name": "Wood_Hardwood_Planks"
    },
    {
      "x": -23,
      "y": 4,
      "z": 16,
      "name": "Wood_Hardwood_Planks"
    },
    {
      "x": -23,
      "y": 4,
      "z": 17,
      "name": "Wood_Hardwood_Planks"
    },
    {
      "x": -23,
      "y": 0,
      "z": 18,
      "name": "Rock_Stone_Brick"
    },
    {
      "x": -23,
      "y": 1,
      "z": 18,
      "name": "Rock_Stone_Brick",
      "rotation": 1
    },
    {
      "x": -23,
      "y": 2,
      "z": 18,
      "name": "Rock_Stone_Brick",
      "rotation": 1
    },
    {
      "x": -23,
      "y": 3,
      "z": 18,
      "name": "Rock_Stone_Brick",
      "rotation": 1
    },
    {
      "x": -23,
      "y": 4,
      "z": 18,
      "name": "Rock_Stone_Brick"
    },
    {
      "x": -23,
      "y": 0,
      "z": 19,
      "name": "Rock_Stone_Brick"
    },
    {
      "x": -23,
      "y": 1,
      "z": 19,
      "name": "Rock_Stone_Brick",
      "rotation": 1
    },
    {
      "x": -23,
      "y": 2,
      "z": 19,
      "name": "Rock_Stone_Brick",
      "rotation": 1
    },
    {
      "x": -23,
      "y": 3,
      "z": 19,
      "name": "Rock_Stone_Brick",
      "rotation": 1
    },
    {
      "x": -23,
      "y": 4,
      "z": 19,
      "name": "Rock_Stone_Brick"
    },
    {
      "x": -23,
      "y": 0,
      "z": 20,
      "name": "Rock_Stone_Brick"
    },
    {
      "x": -23,
      "y": 1,
      "z": 20,
      "name": "Rock_Stone_Brick",
      "rotation": 1
    },
    {
      "x": -23,
      "y": 2,
      "z": 20,
      "name": "Rock_Stone_Brick",
      "rotation": 1
    },
    {
      "x": -23,
      "y": 3,
      "z": 20,
      "name": "Rock_Stone_Brick",
      "rotation": 1
    },
    {
      "x": -23,
      "y": 4,
      "z": 20,
      "name": "Rock_Stone_Brick"
    },
    {
      "x": -22,
      "y": 0,
      "z": -21,
      "name": "Rock_Stone_Brick",
      "rotation": 3
    },
    {
      "x": -22,
      "y": 1,
      "z": -21,
      "name": "Rock_Stone_Brick"
    },
    {
      "x": -22,
      "y": 2,
      "z": -21,
      "name": "Rock_Stone_Brick"
    },
    {
      "x": -22,
      "y": 3,
      "z": -21,
      "name": "Rock_Stone_Brick"
    },
    {
      "x": -22,
      "y": 4,
      "z": -21,
      "name": "Rock_Stone_Brick"
    },
    {
      "x": -22,
      "y": 0,
      "z": -20,
      "name": "Rock_Stone_Brick",
      "rotation": 3
    },
    {
      "x": -22,
      "y": 1,
      "z": -20,
      "name": "Rock_Stone_Brick"
    },
    {
      "x": -22,
      "y": 2,
      "z": -20,
      "name": "Rock_Stone_Brick"
    },
    {
      "x": -22,
      "y": 3,
      "z": -20,
      "name": "Rock_Stone_Brick"
    },
    {
      "x": -22,
      "y": 4,
      "z": -20,
      "name": "Rock_Stone_Brick"
    },
    {
      "x": -22,
      "y": 4,
      "z": -19,
      "name": "Wood_Hardwood_Planks"
    },
    {
      "x": -22,
      "y": 4,
      "z": -18,
      "name": "Wood_Hardwood_Planks"
    },
    {
      "x": -22,
      "y": 4,
      "z": -17,
      "name": "Wood_Hardwood_Planks"
    },
    {
      "x": -22,
      "y": 4,
      "z": -16,
      "name": "Wood_Hardwood_Planks"
    },
    {
      "x": -22,
      "y": 4,
      "z": -15,
      "name": "Wood_Hardwood_Planks"
    },
    {
      "x": -22,
      "y": 4,
      "z": -14,
      "name": "Wood_Hardwood_Planks"
    },
    {
      "x": -22,
      "y": 4,
      "z": -13,
      "name": "Wood_Hardwood_Planks"
    },
    {
      "x": -22,
      "y": 4,
      "z": -12,
      "name": "Wood_Hardwood_Planks"
    },
    {
      "x": -22,
      "y": 4,
      "z": -11,
      "name": "Wood_Hardwood_Planks"
    },
    {
      "x": -22,
      "y": 4,
      "z": -10,
      "name": "Wood_Hardwood_Planks"
    },
    {
      "x": -22,
      "y": 4,
      "z": -9,
      "name": "Wood_Hardwood_Planks"
    },
    {
      "x": -22,
      "y": 4,
      "z": -8,
      "name": "Wood_Hardwood_Planks"
    },
    {
      "x": -22,
      "y": 4,
      "z": -7,
      "name": "Wood_Hardwood_Planks"
    },
    {
      "x": -22,
      "y": 4,
      "z": -6,
      "name": "Wood_Hardwood_Planks"
    },
    {
      "x": -22,
      "y": 4,
      "z": -5,
      "name": "Wood_Hardwood_Planks"
    },
    {
      "x": -22,
      "y": 4,
      "z": -4,
      "name": "Wood_Hardwood_Planks"
    },
    {
      "x": -22,
      "y": 4,
      "z": -3,
      "name": "Wood_Hardwood_Planks"
    },
    {
      "x": -22,
      "y": 4,
      "z": -2,
      "name": "Wood_Hardwood_Planks"
    },
    {
      "x": -22,
      "y": 4,
      "z": -1,
      "name": "Wood_Hardwood_Planks"
    },
    {
      "x": -22,
      "y": 4,
      "z": 0,
      "name": "Wood_Hardwood_Planks"
    },
    {
      "x": -22,
      "y": 4,
      "z": 1,
      "name": "Wood_Hardwood_Planks"
    },
    {
      "x": -22,
      "y": 4,
      "z": 2,
      "name": "Wood_Hardwood_Planks"
    },
    {
      "x": -22,
      "y": 4,
      "z": 3,
      "name": "Wood_Hardwood_Planks"
    },
    {
      "x": -22,
      "y": 4,
      "z": 4,
      "name": "Wood_Hardwood_Planks"
    },
    {
      "x": -22,
      "y": 4,
      "z": 5,
      "name": "Wood_Hardwood_Planks"
    },
    {
      "x": -22,
      "y": 4,
      "z": 6,
      "name": "Wood_Hardwood_Planks"
    },
    {
      "x": -22,
      "y": 4,
      "z": 7,
      "name": "Wood_Hardwood_Planks"
    },
    {
      "x": -22,
      "y": 4,
      "z": 8,
      "name": "Wood_Hardwood_Planks"
    },
    {
      "x": -22,
      "y": 4,
      "z": 9,
      "name": "Wood_Hardwood_Planks"
    },
    {
      "x": -22,
      "y": 4,
      "z": 10,
      "name": "Wood_Hardwood_Planks"
    },
    {
      "x": -22,
      "y": 4,
      "z": 11,
      "name": "Wood_Hardwood_Planks"
    },
    {
      "x": -22,
      "y": 4,
      "z": 12,
      "name": "Wood_Hardwood_Planks"
    },
    {
      "x": -22,
      "y": 4,
      "z": 13,
      "name": "Wood_Hardwood_Planks"
    },
    {
      "x": -22,
      "y": 4,
      "z": 14,
      "name": "Wood_Hardwood_Planks"
    },
    {
      "x": -22,
      "y": 4,
      "z": 15,
      "name": "Wood_Hardwood_Planks"
    },
    {
      "x": -22,
      "y": 4,
      "z": 16,
      "name": "Wood_Hardwood_Planks"
    },
    {
      "x": -22,
      "y": 4,
      "z": 17,
      "name": "Wood_Hardwood_Planks"
    },
    {
      "x": -22,
      "y": 4,
      "z": 18,
      "name": "Wood_Hardwood_Planks"
    },
    {
      "x": -22,
      "y": 4,
      "z": 19,
      "name": "Wood_Hardwood_Planks"
    },
    {
      "x": -22,
      "y": 0,
      "z": 20,
      "name": "Rock_Stone_Brick"
    },
    {
      "x": -22,
      "y": 1,
      "z": 20,
      "name": "Rock_Stone_Brick",
      "rotation": 1
    },
    {
      "x": -22,
      "y": 2,
      "z": 20,
      "name": "Rock_Stone_Brick",
      "rotation": 1
    },
    {
      "x": -22,
      "y": 3,
      "z": 20,
      "name": "Rock_Stone_Brick",
      "rotation": 1
    },
    {
      "x": -22,
      "y": 4,
      "z": 20,
      "name": "Rock_Stone_Brick"
    },
    {
      "x": -22,
      "y": 0,
      "z": 21,
      "name": "Rock_Stone_Brick"
    },
    {
      "x": -22,
      "y": 1,
      "z": 21,
      "name": "Rock_Stone_Brick",
      "rotation": 1
    },
    {
      "x": -22,
      "y": 2,
      "z": 21,
      "name": "Rock_Stone_Brick",
      "rotation": 1
    },
    {
      "x": -22,
      "y": 3,
      "z": 21,
      "name": "Rock_Stone_Brick",
      "rotation": 1
    },
    {
      "x": -22,
      "y": 4,
      "z": 21,
      "name": "Rock_Stone_Brick"
    },
    {
      "x": -21,
      "y": 0,
      "z": -22,
      "name": "Rock_Stone_Brick",
      "rotation": 3
    },
    {
      "x": -21,
      "y": 1,
      "z": -22,
      "name": "Rock_Stone_Brick"
    },
    {
      "x": -21,
      "y": 2,
      "z": -22,
      "name": "Rock_Stone_Brick"
    },
    {
      "x": -21,
      "y": 3,
      "z": -22,
      "name": "Rock_Stone_Brick"
    },
    {
      "x": -21,
      "y": 4,
      "z": -22,
      "name": "Rock_Stone_Brick"
    },
    {
      "x": -21,
      "y": 0,
      "z": -21,
      "name": "Rock_Stone_Brick",
      "rotation": 3
    },
    {
      "x": -21,
      "y": 1,
      "z": -21,
      "name": "Rock_Stone_Brick"
    },
    {
      "x": -21,
      "y": 2,
      "z": -21,
      "name": "Rock_Stone_Brick"
    },
    {
      "x": -21,
      "y": 3,
      "z": -21,
      "name": "Rock_Stone_Brick"
    },
    {
      "x": -21,
      "y": 4,
      "z": -21,
      "name": "Rock_Stone_Brick"
    },
    {
      "x": -21,
      "y": 4,
      "z": -20,
      "name": "Wood_Hardwood_Planks"
    },
    {
      "x": -21,
      "y": 4,
      "z": -19,
      "name": "Wood_Hardwood_Planks"
    },
    {
      "x": -21,
      "y": 4,
      "z": -18,
      "name": "Wood_Hardwood_Planks"
    },
    {
      "x": -21,
      "y": 4,
      "z": -17,
      "name": "Wood_Hardwood_Planks"
    },
    {
      "x": -21,
      "y": 4,
      "z": -16,
      "name": "Wood_Hardwood_Planks"
    },
    {
      "x": -21,
      "y": 4,
      "z": -15,
      "name": "Wood_Hardwood_Planks"
    },
    {
      "x": -21,
      "y": 4,
      "z": -14,
      "name": "Wood_Hardwood_Planks"
    },
    {
      "x": -21,
      "y": 4,
      "z": -13,
      "name": "Wood_Hardwood_Planks"
    },
    {
      "x": -21,
      "y": 4,
      "z": -12,
      "name": "Wood_Hardwood_Planks"
    },
    {
      "x": -21,
      "y": 4,
      "z": -11,
      "name": "Wood_Hardwood_Planks"
    },
    {
      "x": -21,
      "y": 4,
      "z": -10,
      "name": "Wood_Hardwood_Planks"
    },
    {
      "x": -21,
      "y": 4,
      "z": -9,
      "name": "Wood_Hardwood_Planks"
    },
    {
      "x": -21,
      "y": 4,
      "z": -8,
      "name": "Wood_Hardwood_Planks"
    },
    {
      "x": -21,
      "y": 4,
      "z": -7,
      "name": "Wood_Hardwood_Planks"
    },
    {
      "x": -21,
      "y": 4,
      "z": -6,
      "name": "Wood_Hardwood_Planks"
    },
    {
      "x": -21,
      "y": 4,
      "z": -5,
      "name": "Wood_Hardwood_Planks"
    },
    {
      "x": -21,
      "y": 4,
      "z": -4,
      "name": "Wood_Hardwood_Planks"
    },
    {
      "x": -21,
      "y": 4,
      "z": -3,
      "name": "Wood_Hardwood_Planks"
    },
    {
      "x": -21,
      "y": 4,
      "z": -2,
      "name": "Wood_Hardwood_Planks"
    },
    {
      "x": -21,
      "y": 4,
      "z": -1,
      "name": "Wood_Hardwood_Planks"
    },
    {
      "x": -21,
      "y": 4,
      "z": 0,
      "name": "Wood_Hardwood_Planks"
    },
    {
      "x": -21,
      "y": 4,
      "z": 1,
      "name": "Wood_Hardwood_Planks"
    },
    {
      "x": -21,
      "y": 4,
      "z": 2,
      "name": "Wood_Hardwood_Planks"
    },
    {
      "x": -21,
      "y": 4,
      "z": 3,
      "name": "Wood_Hardwood_Planks"
    },
    {
      "x": -21,
      "y": 4,
      "z": 4,
      "name": "Wood_Hardwood_Planks"
    },
    {
      "x": -21,
      "y": 4,
      "z": 5,
      "name": "Wood_Hardwood_Planks"
    },
    {
      "x": -21,
      "y": 4,
      "z": 6,
      "name": "Wood_Hardwood_Planks"
    },
    {
      "x": -21,
      "y": 4,
      "z": 7,
      "name": "Wood_Hardwood_Planks"
    },
    {
      "x": -21,
      "y": 4,
      "z": 8,
      "name": "Wood_Hardwood_Planks"
    },
    {
      "x": -21,
      "y": 4,
      "z": 9,
      "name": "Wood_Hardwood_Planks"
    },
    {
      "x": -21,
      "y": 4,
      "z": 10,
      "name": "Wood_Hardwood_Planks"
    },
    {
      "x": -21,
      "y": 4,
      "z": 11,
      "name": "Wood_Hardwood_Planks"
    },
    {
      "x": -21,
      "y": 4,
      "z": 12,
      "name": "Wood_Hardwood_Planks"
    },
    {
      "x": -21,
      "y": 4,
      "z": 13,
      "name": "Wood_Hardwood_Planks"
    },
    {
      "x": -21,
      "y": 4,
      "z": 14,
      "name": "Wood_Hardwood_Planks"
    },
    {
      "x": -21,
      "y": 4,
      "z": 15,
      "name": "Wood_Hardwood_Planks"
    },
    {
      "x": -21,
      "y": 4,
      "z": 16,
      "name": "Wood_Hardwood_Planks"
    },
    {
      "x": -21,
      "y": 4,
      "z": 17,
      "name": "Wood_Hardwood_Planks"
    },
    {
      "x": -21,
      "y": 4,
      "z": 18,
      "name": "Wood_Hardwood_Planks"
    },
    {
      "x": -21,
      "y": 4,
      "z": 19,
      "name": "Wood_Hardwood_Planks"
    },
    {
      "x": -21,
      "y": 4,
      "z": 20,
      "name": "Wood_Hardwood_Planks"
    },
    {
      "x": -21,
      "y": 0,
      "z": 21,
      "name": "Rock_Stone_Brick"
    },
    {
      "x": -21,
      "y": 1,
      "z": 21,
      "name": "Rock_Stone_Brick",
      "rotation": 1
    },
    {
      "x": -21,
      "y": 2,
      "z": 21,
      "name": "Rock_Stone_Brick",
      "rotation": 1
    },
    {
      "x": -21,
      "y": 3,
      "z": 21,
      "name": "Rock_Stone_Brick",
      "rotation": 1
    },
    {
      "x": -21,
      "y": 4,
      "z": 21,
      "name": "Rock_Stone_Brick"
    },
    {
      "x": -21,
      "y": 0,
      "z": 22,
      "name": "Rock_Stone_Brick"
    },
    {
      "x": -21,
      "y": 1,
      "z": 22,
      "name": "Rock_Stone_Brick",
      "rotation": 1
    },
    {
      "x": -21,
      "y": 2,
      "z": 22,
      "name": "Rock_Stone_Brick",
      "rotation": 1
    },
    {
      "x": -21,
      "y": 3,
      "z": 22,
      "name": "Rock_Stone_Brick",
      "rotation": 1
    },
    {
      "x": -21,
      "y": 4,
      "z": 22,
      "name": "Rock_Stone_Brick"
    },
    {
      "x": -20,
      "y": 0,
      "z": -23,
      "name": "Rock_Stone_Brick",
      "rotation": 3
    },
    {
      "x": -20,
      "y": 1,
      "z": -23,
      "name": "Rock_Stone_Brick"
    },
    {
      "x": -20,
      "y": 2,
      "z": -23,
      "name": "Rock_Stone_Brick"
    },
    {
      "x": -20,
      "y": 3,
      "z": -23,
      "name": "Rock_Stone_Brick"
    },
    {
      "x": -20,
      "y": 4,
      "z": -23,
      "name": "Rock_Stone_Brick"
    },
    {
      "x": -20,
      "y": 0,
      "z": -22,
      "name": "Rock_Stone_Brick",
      "rotation": 3
    },
    {
      "x": -20,
      "y": 1,
      "z": -22,
      "name": "Rock_Stone_Brick"
    },
    {
      "x": -20,
      "y": 2,
      "z": -22,
      "name": "Rock_Stone_Brick"
    },
    {
      "x": -20,
      "y": 3,
      "z": -22,
      "name": "Rock_Stone_Brick"
    },
    {
      "x": -20,
      "y": 4,
      "z": -22,
      "name": "Rock_Stone_Brick"
    },
    {
      "x": -20,
      "y": 4,
      "z": -21,
      "name": "Wood_Hardwood_Planks"
    },
    {
      "x": -20,
      "y": 4,
      "z": -20,
      "name": "Wood_Hardwood_Planks"
    },
    {
      "x": -20,
      "y": 4,
      "z": -19,
      "name": "Wood_Hardwood_Planks"
    },
    {
      "x": -20,
      "y": 4,
      "z": -18,
      "name": "Wood_Hardwood_Planks"
    },
    {
      "x": -20,
      "y": 4,
      "z": -17,
      "name": "Wood_Hardwood_Planks"
    },
    {
      "x": -20,
      "y": 4,
      "z": -16,
      "name": "Wood_Hardwood_Planks"
    },
    {
      "x": -20,
      "y": 4,
      "z": -15,
      "name": "Wood_Hardwood_Planks"
    },
    {
      "x": -20,
      "y": 4,
      "z": -14,
      "name": "Wood_Hardwood_Planks"
    },
    {
      "x": -20,
      "y": 4,
      "z": -13,
      "name": "Wood_Hardwood_Planks"
    },
    {
      "x": -20,
      "y": 4,
      "z": -12,
      "name": "Wood_Hardwood_Planks"
    },
    {
      "x": -20,
      "y": 4,
      "z": -11,
      "name": "Wood_Hardwood_Planks"
    },
    {
      "x": -20,
      "y": 4,
      "z": -10,
      "name": "Wood_Hardwood_Planks"
    },
    {
      "x": -20,
      "y": 4,
      "z": -9,
      "name": "Wood_Hardwood_Planks"
    },
    {
      "x": -20,
      "y": 4,
      "z": -8,
      "name": "Wood_Hardwood_Planks"
    },
    {
      "x": -20,
      "y": 4,
      "z": -7,
      "name": "Wood_Hardwood_Planks"
    },
    {
      "x": -20,
      "y": 4,
      "z": -6,
      "name": "Wood_Hardwood_Planks"
    },
    {
      "x": -20,
      "y": 4,
      "z": -5,
      "name": "Wood_Hardwood_Planks"
    },
    {
      "x": -20,
      "y": 4,
      "z": -4,
      "name": "Wood_Hardwood_Planks"
    },
    {
      "x": -20,
      "y": 4,
      "z": -3,
      "name": "Wood_Hardwood_Planks"
    },
    {
      "x": -20,
      "y": 4,
      "z": -2,
      "name": "Wood_Hardwood_Planks"
    },
    {
      "x": -20,
      "y": 4,
      "z": -1,
      "name": "Wood_Hardwood_Planks"
    },
    {
      "x": -20,
      "y": 4,
      "z": 0,
      "name": "Wood_Hardwood_Planks"
    },
    {
      "x": -20,
      "y": 4,
      "z": 1,
      "name": "Wood_Hardwood_Planks"
    },
    {
      "x": -20,
      "y": 4,
      "z": 2,
      "name": "Wood_Hardwood_Planks"
    },
    {
      "x": -20,
      "y": 4,
      "z": 3,
      "name": "Wood_Hardwood_Planks"
    },
    {
      "x": -20,
      "y": 4,
      "z": 4,
      "name": "Wood_Hardwood_Planks"
    },
    {
      "x": -20,
      "y": 4,
      "z": 5,
      "name": "Wood_Hardwood_Planks"
    },
    {
      "x": -20,
      "y": 4,
      "z": 6,
      "name": "Wood_Hardwood_Planks"
    },
    {
      "x": -20,
      "y": 4,
      "z": 7,
      "name": "Wood_Hardwood_Planks"
    },
    {
      "x": -20,
      "y": 4,
      "z": 8,
      "name": "Wood_Hardwood_Planks"
    },
    {
      "x": -20,
      "y": 4,
      "z": 9,
      "name": "Wood_Hardwood_Planks"
    },
    {
      "x": -20,
      "y": 4,
      "z": 10,
      "name": "Wood_Hardwood_Planks"
    },
    {
      "x": -20,
      "y": 4,
      "z": 11,
      "name": "Wood_Hardwood_Planks"
    },
    {
      "x": -20,
      "y": 4,
      "z": 12,
      "name": "Wood_Hardwood_Planks"
    },
    {
      "x": -20,
      "y": 4,
      "z": 13,
      "name": "Wood_Hardwood_Planks"
    },
    {
      "x": -20,
      "y": 4,
      "z": 14,
      "name": "Wood_Hardwood_Planks"
    },
    {
      "x": -20,
      "y": 4,
      "z": 15,
      "name": "Wood_Hardwood_Planks"
    },
    {
      "x": -20,
      "y": 4,
      "z": 16,
      "name": "Wood_Hardwood_Planks"
    },
    {
      "x": -20,
      "y": 4,
      "z": 17,
      "name": "Wood_Hardwood_Planks"
    },
    {
      "x": -20,
      "y": 4,
      "z": 18,
      "name": "Wood_Hardwood_Planks"
    },
    {
      "x": -20,
      "y": 4,
      "z": 19,
      "name": "Wood_Hardwood_Planks"
    },
    {
      "x": -20,
      "y": 4,
      "z": 20,
      "name": "Wood_Hardwood_Planks"
    },
    {
      "x": -20,
      "y": 4,
      "z": 21,
      "name": "Wood_Hardwood_Planks"
    },
    {
      "x": -20,
      "y": 0,
      "z": 22,
      "name": "Rock_Stone_Brick"
    },
    {
      "x": -20,
      "y": 1,
      "z": 22,
      "name": "Rock_Stone_Brick",
      "rotation": 1
    },
    {
      "x": -20,
      "y": 2,
      "z": 22,
      "name": "Rock_Stone_Brick",
      "rotation": 1
    },
    {
      "x": -20,
      "y": 3,
      "z": 22,
      "name": "Rock_Stone_Brick",
      "rotation": 1
    },
    {
      "x": -20,
      "y": 4,
      "z": 22,
      "name": "Rock_Stone_Brick"
    },
    {
      "x": -20,
      "y": 0,
      "z": 23,
      "name": "Rock_Stone_Brick"
    },
    {
      "x": -20,
      "y": 1,
      "z": 23,
      "name": "Rock_Stone_Brick",
      "rotation": 1
    },
    {
      "x": -20,
      "y": 2,
      "z": 23,
      "name": "Rock_Stone_Brick",
      "rotation": 1
    },
    {
      "x": -20,
      "y": 3,
      "z": 23,
      "name": "Rock_Stone_Brick",
      "rotation": 1
    },
    {
      "x": -20,
      "y": 4,
      "z": 23,
      "name": "Rock_Stone_Brick"
    },
    {
      "x": -19,
      "y": 0,
      "z": -23,
      "name": "Rock_Stone_Brick",
      "rotation": 3
    },
    {
      "x": -19,
      "y": 1,
      "z": -23,
      "name": "Rock_Stone_Brick"
    },
    {
      "x": -19,
      "y": 2,
      "z": -23,
      "name": "Rock_Stone_Brick"
    },
    {
      "x": -19,
      "y": 3,
      "z": -23,
      "name": "Rock_Stone_Brick"
    },
    {
      "x": -19,
      "y": 4,
      "z": -23,
      "name": "Rock_Stone_Brick"
    },
    {
      "x": -19,
      "y": 4,
      "z": -22,
      "name": "Wood_Hardwood_Planks"
    },
    {
      "x": -19,
      "y": 4,
      "z": -21,
      "name": "Wood_Hardwood_Planks"
    },
    {
      "x": -19,
      "y": 4,
      "z": -20,
      "name": "Wood_Hardwood_Planks"
    },
    {
      "x": -19,
      "y": 4,
      "z": -19,
      "name": "Wood_Hardwood_Planks"
    },
    {
      "x": -19,
      "y": 4,
      "z": -18,
      "name": "Wood_Hardwood_Planks"
    },
    {
      "x": -19,
      "y": 4,
      "z": -17,
      "name": "Wood_Hardwood_Planks"
    },
    {
      "x": -19,
      "y": 4,
      "z": -16,
      "name": "Wood_Hardwood_Planks"
    },
    {
      "x": -19,
      "y": 4,
      "z": -15,
      "name": "Wood_Hardwood_Planks"
    },
    {
      "x": -19,
      "y": 4,
      "z": -14,
      "name": "Wood_Hardwood_Planks"
    },
    {
      "x": -19,
      "y": 4,
      "z": -13,
      "name": "Wood_Hardwood_Planks"
    },
    {
      "x": -19,
      "y": 4,
      "z": -12,
      "name": "Wood_Hardwood_Planks"
    },
    {
      "x": -19,
      "y": 4,
      "z": -11,
      "name": "Wood_Hardwood_Planks"
    },
    {
      "x": -19,
      "y": 4,
      "z": -10,
      "name": "Wood_Hardwood_Planks"
    },
    {
      "x": -19,
      "y": 4,
      "z": -9,
      "name": "Wood_Hardwood_Planks"
    },
    {
      "x": -19,
      "y": 4,
      "z": -8,
      "name": "Wood_Hardwood_Planks"
    },
    {
      "x": -19,
      "y": 4,
      "z": -7,
      "name": "Wood_Hardwood_Planks"
    },
    {
      "x": -19,
      "y": 4,
      "z": -6,
      "name": "Wood_Hardwood_Planks"
    },
    {
      "x": -19,
      "y": 4,
      "z": -5,
      "name": "Wood_Hardwood_Planks"
    },
    {
      "x": -19,
      "y": 4,
      "z": -4,
      "name": "Wood_Hardwood_Planks"
    },
    {
      "x": -19,
      "y": 4,
      "z": -3,
      "name": "Wood_Hardwood_Planks"
    },
    {
      "x": -19,
      "y": 4,
      "z": -2,
      "name": "Wood_Hardwood_Planks"
    },
    {
      "x": -19,
      "y": 4,
      "z": -1,
      "name": "Wood_Hardwood_Planks"
    },
    {
      "x": -19,
      "y": 4,
      "z": 0,
      "name": "Wood_Hardwood_Planks"
    },
    {
      "x": -19,
      "y": 4,
      "z": 1,
      "name": "Wood_Hardwood_Planks"
    },
    {
      "x": -19,
      "y": 4,
      "z": 2,
      "name": "Wood_Hardwood_Planks"
    },
    {
      "x": -19,
      "y": 4,
      "z": 3,
      "name": "Wood_Hardwood_Planks"
    },
    {
      "x": -19,
      "y": 4,
      "z": 4,
      "name": "Wood_Hardwood_Planks"
    },
    {
      "x": -19,
      "y": 4,
      "z": 5,
      "name": "Wood_Hardwood_Planks"
    },
    {
      "x": -19,
      "y": 4,
      "z": 6,
      "name": "Wood_Hardwood_Planks"
    },
    {
      "x": -19,
      "y": 4,
      "z": 7,
      "name": "Wood_Hardwood_Planks"
    },
    {
      "x": -19,
      "y": 4,
      "z": 8,
      "name": "Wood_Hardwood_Planks"
    },
    {
      "x": -19,
      "y": 4,
      "z": 9,
      "name": "Wood_Hardwood_Planks"
    },
    {
      "x": -19,
      "y": 4,
      "z": 10,
      "name": "Wood_Hardwood_Planks"
    },
    {
      "x": -19,
      "y": 4,
      "z": 11,
      "name": "Wood_Hardwood_Planks"
    },
    {
      "x": -19,
      "y": 4,
      "z": 12,
      "name": "Wood_Hardwood_Planks"
    },
    {
      "x": -19,
      "y": 4,
      "z": 13,
      "name": "Wood_Hardwood_Planks"
    },
    {
      "x": -19,
      "y": 4,
      "z": 14,
      "name": "Wood_Hardwood_Planks"
    },
    {
      "x": -19,
      "y": 4,
      "z": 15,
      "name": "Wood_Hardwood_Planks"
    },
    {
      "x": -19,
      "y": 4,
      "z": 16,
      "name": "Wood_Hardwood_Planks"
    },
    {
      "x": -19,
      "y": 4,
      "z": 17,
      "name": "Wood_Hardwood_Planks"
    },
    {
      "x": -19,
      "y": 4,
      "z": 18,
      "name": "Wood_Hardwood_Planks"
    },
    {
      "x": -19,
      "y": 4,
      "z": 19,
      "name": "Wood_Hardwood_Planks"
    },
    {
      "x": -19,
      "y": 4,
      "z": 20,
      "name": "Wood_Hardwood_Planks"
    },
    {
      "x": -19,
      "y": 4,
      "z": 21,
      "name": "Wood_Hardwood_Planks"
    },
    {
      "x": -19,
      "y": 4,
      "z": 22,
      "name": "Wood_Hardwood_Planks"
    },
    {
      "x": -19,
      "y": 0,
      "z": 23,
      "name": "Rock_Stone_Brick"
    },
    {
      "x": -19,
      "y": 1,
      "z": 23,
      "name": "Rock_Stone_Brick",
      "rotation": 1
    },
    {
      "x": -19,
      "y": 2,
      "z": 23,
      "name": "Rock_Stone_Brick",
      "rotation": 1
    },
    {
      "x": -19,
      "y": 3,
      "z": 23,
      "name": "Rock_Stone_Brick",
      "rotation": 1
    },
    {
      "x": -19,
      "y": 4,
      "z": 23,
      "name": "Rock_Stone_Brick"
    },
    {
      "x": -18,
      "y": 0,
      "z": -24,
      "name": "Rock_Stone_Brick",
      "rotation": 3
    },
    {
      "x": -18,
      "y": 1,
      "z": -24,
      "name": "Rock_Stone_Brick"
    },
    {
      "x": -18,
      "y": 2,
      "z": -24,
      "name": "Rock_Stone_Brick"
    },
    {
      "x": -18,
      "y": 3,
      "z": -24,
      "name": "Rock_Stone_Brick"
    },
    {
      "x": -18,
      "y": 4,
      "z": -24,
      "name": "Rock_Stone_Brick"
    },
    {
      "x": -18,
      "y": 0,
      "z": -23,
      "name": "Rock_Stone_Brick",
      "rotation": 3
    },
    {
      "x": -18,
      "y": 1,
      "z": -23,
      "name": "Rock_Stone_Brick"
    },
    {
      "x": -18,
      "y": 2,
      "z": -23,
      "name": "Rock_Stone_Brick"
    },
    {
      "x": -18,
      "y": 3,
      "z": -23,
      "name": "Rock_Stone_Brick"
    },
    {
      "x": -18,
      "y": 4,
      "z": -23,
      "name": "Rock_Stone_Brick"
    },
    {
      "x": -18,
      "y": 4,
      "z": -22,
      "name": "Wood_Hardwood_Planks"
    },
    {
      "x": -18,
      "y": 4,
      "z": -21,
      "name": "Wood_Hardwood_Planks"
    },
    {
      "x": -18,
      "y": 4,
      "z": -20,
      "name": "Wood_Hardwood_Planks"
    },
    {
      "x": -18,
      "y": 4,
      "z": -19,
      "name": "Wood_Hardwood_Planks"
    },
    {
      "x": -18,
      "y": 4,
      "z": -18,
      "name": "Wood_Hardwood_Planks"
    },
    {
      "x": -18,
      "y": 4,
      "z": -17,
      "name": "Wood_Hardwood_Planks"
    },
    {
      "x": -18,
      "y": 4,
      "z": -16,
      "name": "Wood_Hardwood_Planks"
    },
    {
      "x": -18,
      "y": 0,
      "z": -15,
      "name": "Rock_Stone_Brick",
      "rotation": 3
    },
    {
      "x": -18,
      "y": 1,
      "z": -15,
      "name": "Rock_Stone_Brick"
    },
    {
      "x": -18,
      "y": 2,
      "z": -15,
      "name": "Rock_Stone_Brick"
    },
    {
      "x": -18,
      "y": 3,
      "z": -15,
      "name": "Rock_Stone_Brick"
    },
    {
      "x": -18,
      "y": 4,
      "z": -15,
      "name": "Rock_Stone_Brick"
    },
    {
      "x": -18,
      "y": 0,
      "z": -14,
      "name": "Rock_Stone_Brick",
      "rotation": 3
    },
    {
      "x": -18,
      "y": 1,
      "z": -14,
      "name": "Rock_Stone_Brick"
    },
    {
      "x": -18,
      "y": 2,
      "z": -14,
      "name": "Rock_Stone_Brick"
    },
    {
      "x": -18,
      "y": 3,
      "z": -14,
      "name": "Rock_Stone_Brick"
    },
    {
      "x": -18,
      "y": 4,
      "z": -14,
      "name": "Rock_Stone_Brick"
    },
    {
      "x": -18,
      "y": 0,
      "z": -13,
      "name": "Rock_Stone_Brick"
    },
    {
      "x": -18,
      "y": 1,
      "z": -13,
      "name": "Rock_Stone_Brick"
    },
    {
      "x": -18,
      "y": 2,
      "z": -13,
      "name": "Rock_Stone_Brick"
    },
    {
      "x": -18,
      "y": 3,
      "z": -13,
      "name": "Rock_Stone_Brick"
    },
    {
      "x": -18,
      "y": 4,
      "z": -13,
      "name": "Rock_Stone_Brick"
    },
    {
      "x": -18,
      "y": 4,
      "z": -12,
      "name": "Wood_Hardwood_Planks"
    },
    {
      "x": -18,
      "y": 4,
      "z": -11,
      "name": "Wood_Hardwood_Planks"
    },
    {
      "x": -18,
      "y": 4,
      "z": -10,
      "name": "Wood_Hardwood_Planks"
    },
    {
      "x": -18,
      "y": 4,
      "z": -9,
      "name": "Wood_Hardwood_Planks"
    },
    {
      "x": -18,
      "y": 4,
      "z": -8,
      "name": "Wood_Hardwood_Planks"
    },
    {
      "x": -18,
      "y": 4,
      "z": -7,
      "name": "Wood_Hardwood_Planks"
    },
    {
      "x": -18,
      "y": 4,
      "z": -6,
      "name": "Wood_Hardwood_Planks"
    },
    {
      "x": -18,
      "y": 4,
      "z": -5,
      "name": "Wood_Hardwood_Planks"
    },
    {
      "x": -18,
      "y": 4,
      "z": -4,
      "name": "Wood_Hardwood_Planks"
    },
    {
      "x": -18,
      "y": 4,
      "z": -3,
      "name": "Wood_Hardwood_Planks"
    },
    {
      "x": -18,
      "y": 4,
      "z": -2,
      "name": "Wood_Hardwood_Planks"
    },
    {
      "x": -18,
      "y": 4,
      "z": -1,
      "name": "Wood_Hardwood_Planks"
    },
    {
      "x": -18,
      "y": 4,
      "z": 0,
      "name": "Wood_Hardwood_Planks"
    },
    {
      "x": -18,
      "y": 4,
      "z": 1,
      "name": "Wood_Hardwood_Planks"
    },
    {
      "x": -18,
      "y": 4,
      "z": 2,
      "name": "Wood_Hardwood_Planks"
    },
    {
      "x": -18,
      "y": 4,
      "z": 3,
      "name": "Wood_Hardwood_Planks"
    },
    {
      "x": -18,
      "y": 4,
      "z": 4,
      "name": "Wood_Hardwood_Planks"
    },
    {
      "x": -18,
      "y": 4,
      "z": 5,
      "name": "Wood_Hardwood_Planks"
    },
    {
      "x": -18,
      "y": 4,
      "z": 6,
      "name": "Wood_Hardwood_Planks"
    },
    {
      "x": -18,
      "y": 4,
      "z": 7,
      "name": "Wood_Hardwood_Planks"
    },
    {
      "x": -18,
      "y": 4,
      "z": 8,
      "name": "Wood_Hardwood_Planks"
    },
    {
      "x": -18,
      "y": 4,
      "z": 9,
      "name": "Wood_Hardwood_Planks"
    },
    {
      "x": -18,
      "y": 4,
      "z": 10,
      "name": "Wood_Hardwood_Planks"
    },
    {
      "x": -18,
      "y": 4,
      "z": 11,
      "name": "Wood_Hardwood_Planks"
    },
    {
      "x": -18,
      "y": 0,
      "z": 12,
      "name": "Rock_Stone_Brick"
    },
    {
      "x": -18,
      "y": 1,
      "z": 12,
      "name": "Rock_Stone_Brick"
    },
    {
      "x": -18,
      "y": 2,
      "z": 12,
      "name": "Rock_Stone_Brick"
    },
    {
      "x": -18,
      "y": 3,
      "z": 12,
      "name": "Rock_Stone_Brick"
    },
    {
      "x": -18,
      "y": 4,
      "z": 12,
      "name": "Rock_Stone_Brick"
    },
    {
      "x": -18,
      "y": 0,
      "z": 13,
      "name": "Rock_Stone_Brick"
    },
    {
      "x": -18,
      "y": 1,
      "z": 13,
      "name": "Rock_Stone_Brick"
    },
    {
      "x": -18,
      "y": 2,
      "z": 13,
      "name": "Rock_Stone_Brick"
    },
    {
      "x": -18,
      "y": 3,
      "z": 13,
      "name": "Rock_Stone_Brick"
    },
    {
      "x": -18,
      "y": 4,
      "z": 13,
      "name": "Rock_Stone_Brick"
    },
    {
      "x": -18,
      "y": 0,
      "z": 14,
      "name": "Rock_Stone_Brick"
    },
    {
      "x": -18,
      "y": 1,
      "z": 14,
      "name": "Rock_Stone_Brick"
    },
    {
      "x": -18,
      "y": 2,
      "z": 14,
      "name": "Rock_Stone_Brick"
    },
    {
      "x": -18,
      "y": 3,
      "z": 14,
      "name": "Rock_Stone_Brick"
    },
    {
      "x": -18,
      "y": 4,
      "z": 14,
      "name": "Rock_Stone_Brick"
    },
    {
      "x": -18,
      "y": 4,
      "z": 15,
      "name": "Wood_Hardwood_Planks"
    },
    {
      "x": -18,
      "y": 4,
      "z": 16,
      "name": "Wood_Hardwood_Planks"
    },
    {
      "x": -18,
      "y": 4,
      "z": 17,
      "name": "Wood_Hardwood_Planks"
    },
    {
      "x": -18,
      "y": 4,
      "z": 18,
      "name": "Wood_Hardwood_Planks"
    },
    {
      "x": -18,
      "y": 4,
      "z": 19,
      "name": "Wood_Hardwood_Planks"
    },
    {
      "x": -18,
      "y": 4,
      "z": 20,
      "name": "Wood_Hardwood_Planks"
    },
    {
      "x": -18,
      "y": 4,
      "z": 21,
      "name": "Wood_Hardwood_Planks"
    },
    {
      "x": -18,
      "y": 4,
      "z": 22,
      "name": "Wood_Hardwood_Planks"
    },
    {
      "x": -18,
      "y": 0,
      "z": 23,
      "name": "Rock_Stone_Brick"
    },
    {
      "x": -18,
      "y": 1,
      "z": 23,
      "name": "Rock_Stone_Brick",
      "rotation": 1
    },
    {
      "x": -18,
      "y": 2,
      "z": 23,
      "name": "Rock_Stone_Brick",
      "rotation": 1
    },
    {
      "x": -18,
      "y": 3,
      "z": 23,
      "name": "Rock_Stone_Brick",
      "rotation": 1
    },
    {
      "x": -18,
      "y": 4,
      "z": 23,
      "name": "Rock_Stone_Brick"
    },
    {
      "x": -18,
      "y": 0,
      "z": 24,
      "name": "Rock_Stone_Brick"
    },
    {
      "x": -18,
      "y": 1,
      "z": 24,
      "name": "Rock_Stone_Brick",
      "rotation": 1
    },
    {
      "x": -18,
      "y": 2,
      "z": 24,
      "name": "Rock_Stone_Brick",
      "rotation": 1
    },
    {
      "x": -18,
      "y": 3,
      "z": 24,
      "name": "Rock_Stone_Brick",
      "rotation": 1
    },
    {
      "x": -18,
      "y": 4,
      "z": 24,
      "name": "Rock_Stone_Brick",
      "rotation": 1
    },
    {
      "x": -17,
      "y": 0,
      "z": -24,
      "name": "Rock_Stone_Brick",
      "rotation": 3
    },
    {
      "x": -17,
      "y": 1,
      "z": -24,
      "name": "Rock_Stone_Brick"
    },
    {
      "x": -17,
      "y": 4,
      "z": -24,
      "name": "Rock_Stone_Brick"
    },
    {
      "x": -17,
      "y": 4,
      "z": -23,
      "name": "Wood_Hardwood_Planks"
    },
    {
      "x": -17,
      "y": 4,
      "z": -22,
      "name": "Wood_Hardwood_Planks"
    },
    {
      "x": -17,
      "y": 4,
      "z": -21,
      "name": "Wood_Hardwood_Planks"
    },
    {
      "x": -17,
      "y": 4,
      "z": -20,
      "name": "Wood_Hardwood_Planks"
    },
    {
      "x": -17,
      "y": 4,
      "z": -19,
      "name": "Wood_Hardwood_Planks"
    },
    {
      "x": -17,
      "y": 4,
      "z": -18,
      "name": "Wood_Hardwood_Planks"
    },
    {
      "x": -17,
      "y": 4,
      "z": -17,
      "name": "Wood_Hardwood_Planks"
    },
    {
      "x": -17,
      "y": 0,
      "z": -16,
      "name": "Rock_Stone_Brick"
    },
    {
      "x": -17,
      "y": 1,
      "z": -16,
      "name": "Rock_Stone_Brick"
    },
    {
      "x": -17,
      "y": 2,
      "z": -16,
      "name": "Rock_Stone_Brick"
    },
    {
      "x": -17,
      "y": 3,
      "z": -16,
      "name": "Rock_Stone_Brick"
    },
    {
      "x": -17,
      "y": 4,
      "z": -16,
      "name": "Rock_Stone_Brick"
    },
    {
      "x": -17,
      "y": 0,
      "z": -15,
      "name": "Rock_Stone_Brick"
    },
    {
      "x": -17,
      "y": 1,
      "z": -15,
      "name": "Rock_Stone_Brick"
    },
    {
      "x": -17,
      "y": 2,
      "z": -15,
      "name": "Rock_Stone_Brick"
    },
    {
      "x": -17,
      "y": 3,
      "z": -15,
      "name": "Rock_Stone_Brick"
    },
    {
      "x": -17,
      "y": 4,
      "z": -15,
      "name": "Rock_Stone_Brick"
    },
    {
      "x": -17,
      "y": 4,
      "z": -14,
      "name": "Wood_Hardwood_Planks"
    },
    {
      "x": -17,
      "y": 4,
      "z": -13,
      "name": "Wood_Hardwood_Planks"
    },
    {
      "x": -17,
      "y": 4,
      "z": -12,
      "name": "Wood_Hardwood_Planks"
    },
    {
      "x": -17,
      "y": 4,
      "z": -11,
      "name": "Wood_Hardwood_Planks"
    },
    {
      "x": -17,
      "y": 4,
      "z": -10,
      "name": "Wood_Hardwood_Planks"
    },
    {
      "x": -17,
      "y": 4,
      "z": -9,
      "name": "Wood_Hardwood_Planks"
    },
    {
      "x": -17,
      "y": 4,
      "z": -8,
      "name": "Wood_Hardwood_Planks"
    },
    {
      "x": -17,
      "y": 4,
      "z": -7,
      "name": "Wood_Hardwood_Planks"
    },
    {
      "x": -17,
      "y": 4,
      "z": -6,
      "name": "Wood_Hardwood_Planks"
    },
    {
      "x": -17,
      "y": 4,
      "z": -5,
      "name": "Wood_Hardwood_Planks"
    },
    {
      "x": -17,
      "y": 4,
      "z": -4,
      "name": "Wood_Hardwood_Planks"
    },
    {
      "x": -17,
      "y": 4,
      "z": -3,
      "name": "Wood_Hardwood_Planks"
    },
    {
      "x": -17,
      "y": 4,
      "z": -2,
      "name": "Wood_Hardwood_Planks"
    },
    {
      "x": -17,
      "y": 4,
      "z": -1,
      "name": "Wood_Hardwood_Planks"
    },
    {
      "x": -17,
      "y": 4,
      "z": 0,
      "name": "Wood_Hardwood_Planks"
    },
    {
      "x": -17,
      "y": 4,
      "z": 1,
      "name": "Wood_Hardwood_Planks"
    },
    {
      "x": -17,
      "y": 4,
      "z": 2,
      "name": "Wood_Hardwood_Planks"
    },
    {
      "x": -17,
      "y": 4,
      "z": 3,
      "name": "Wood_Hardwood_Planks"
    },
    {
      "x": -17,
      "y": 4,
      "z": 4,
      "name": "Wood_Hardwood_Planks"
    },
    {
      "x": -17,
      "y": 4,
      "z": 5,
      "name": "Wood_Hardwood_Planks"
    },
    {
      "x": -17,
      "y": 4,
      "z": 6,
      "name": "Wood_Hardwood_Planks"
    },
    {
      "x": -17,
      "y": 4,
      "z": 7,
      "name": "Wood_Hardwood_Planks"
    },
    {
      "x": -17,
      "y": 4,
      "z": 8,
      "name": "Wood_Hardwood_Planks"
    },
    {
      "x": -17,
      "y": 4,
      "z": 9,
      "name": "Wood_Hardwood_Planks"
    },
    {
      "x": -17,
      "y": 4,
      "z": 10,
      "name": "Wood_Hardwood_Planks"
    },
    {
      "x": -17,
      "y": 4,
      "z": 11,
      "name": "Wood_Hardwood_Planks"
    },
    {
      "x": -17,
      "y": 4,
      "z": 12,
      "name": "Wood_Hardwood_Planks"
    },
    {
      "x": -17,
      "y": 4,
      "z": 13,
      "name": "Wood_Hardwood_Planks"
    },
    {
      "x": -17,
      "y": 0,
      "z": 14,
      "name": "Rock_Stone_Brick"
    },
    {
      "x": -17,
      "y": 1,
      "z": 14,
      "name": "Rock_Stone_Brick"
    },
    {
      "x": -17,
      "y": 2,
      "z": 14,
      "name": "Rock_Stone_Brick"
    },
    {
      "x": -17,
      "y": 3,
      "z": 14,
      "name": "Rock_Stone_Brick"
    },
    {
      "x": -17,
      "y": 4,
      "z": 14,
      "name": "Rock_Stone_Brick"
    },
    {
      "x": -17,
      "y": 0,
      "z": 15,
      "name": "Rock_Stone_Brick"
    },
    {
      "x": -17,
      "y": 1,
      "z": 15,
      "name": "Rock_Stone_Brick"
    },
    {
      "x": -17,
      "y": 2,
      "z": 15,
      "name": "Rock_Stone_Brick"
    },
    {
      "x": -17,
      "y": 3,
      "z": 15,
      "name": "Rock_Stone_Brick"
    },
    {
      "x": -17,
      "y": 4,
      "z": 15,
      "name": "Rock_Stone_Brick"
    },
    {
      "x": -17,
      "y": 4,
      "z": 16,
      "name": "Wood_Hardwood_Planks"
    },
    {
      "x": -17,
      "y": 4,
      "z": 17,
      "name": "Wood_Hardwood_Planks"
    },
    {
      "x": -17,
      "y": 4,
      "z": 18,
      "name": "Wood_Hardwood_Planks"
    },
    {
      "x": -17,
      "y": 4,
      "z": 19,
      "name": "Wood_Hardwood_Planks"
    },
    {
      "x": -17,
      "y": 4,
      "z": 20,
      "name": "Wood_Hardwood_Planks"
    },
    {
      "x": -17,
      "y": 4,
      "z": 21,
      "name": "Wood_Hardwood_Planks"
    },
    {
      "x": -17,
      "y": 4,
      "z": 22,
      "name": "Wood_Hardwood_Planks"
    },
    {
      "x": -17,
      "y": 4,
      "z": 23,
      "name": "Wood_Hardwood_Planks"
    },
    {
      "x": -17,
      "y": 0,
      "z": 24,
      "name": "Rock_Stone_Brick"
    },
    {
      "x": -17,
      "y": 1,
      "z": 24,
      "name": "Rock_Stone_Brick",
      "rotation": 1
    },
    {
      "x": -17,
      "y": 4,
      "z": 24,
      "name": "Rock_Stone_Brick",
      "rotation": 1
    },
    {
      "x": -16,
      "y": 0,
      "z": -24,
      "name": "Rock_Stone_Brick",
      "rotation": 3
    },
    {
      "x": -16,
      "y": 1,
      "z": -24,
      "name": "Rock_Stone_Brick"
    },
    {
      "x": -16,
      "y": 4,
      "z": -24,
      "name": "Rock_Stone_Brick"
    },
    {
      "x": -16,
      "y": 4,
      "z": -23,
      "name": "Wood_Hardwood_Planks"
    },
    {
      "x": -16,
      "y": 4,
      "z": -22,
      "name": "Wood_Hardwood_Planks"
    },
    {
      "x": -16,
      "y": 4,
      "z": -21,
      "name": "Wood_Hardwood_Planks"
    },
    {
      "x": -16,
      "y": 4,
      "z": -20,
      "name": "Wood_Hardwood_Planks"
    },
    {
      "x": -16,
      "y": 4,
      "z": -19,
      "name": "Wood_Hardwood_Planks"
    },
    {
      "x": -16,
      "y": 4,
      "z": -18,
      "name": "Wood_Hardwood_Planks"
    },
    {
      "x": -16,
      "y": 0,
      "z": -17,
      "name": "Rock_Stone_Brick"
    },
    {
      "x": -16,
      "y": 1,
      "z": -17,
      "name": "Rock_Stone_Brick"
    },
    {
      "x": -16,
      "y": 2,
      "z": -17,
      "name": "Rock_Stone_Brick"
    },
    {
      "x": -16,
      "y": 3,
      "z": -17,
      "name": "Rock_Stone_Brick"
    },
    {
      "x": -16,
      "y": 4,
      "z": -17,
      "name": "Rock_Stone_Brick"
    },
    {
      "x": -16,
      "y": 0,
      "z": -16,
      "name": "Rock_Stone_Brick"
    },
    {
      "x": -16,
      "y": 1,
      "z": -16,
      "name": "Rock_Stone_Brick"
    },
    {
      "x": -16,
      "y": 2,
      "z": -16,
      "name": "Rock_Stone_Brick"
    },
    {
      "x": -16,
      "y": 3,
      "z": -16,
      "name": "Rock_Stone_Brick"
    },
    {
      "x": -16,
      "y": 4,
      "z": -16,
      "name": "Rock_Stone_Brick"
    },
    {
      "x": -16,
      "y": 4,
      "z": -15,
      "name": "Wood_Hardwood_Planks"
    },
    {
      "x": -16,
      "y": 4,
      "z": -14,
      "name": "Wood_Hardwood_Planks"
    },
    {
      "x": -16,
      "y": 4,
      "z": -13,
      "name": "Wood_Hardwood_Planks"
    },
    {
      "x": -16,
      "y": 4,
      "z": -12,
      "name": "Wood_Hardwood_Planks"
    },
    {
      "x": -16,
      "y": 4,
      "z": -11,
      "name": "Wood_Hardwood_Planks"
    },
    {
      "x": -16,
      "y": 4,
      "z": -10,
      "name": "Wood_Hardwood_Planks"
    },
    {
      "x": -16,
      "y": 4,
      "z": -9,
      "name": "Wood_Hardwood_Planks"
    },
    {
      "x": -16,
      "y": 4,
      "z": -8,
      "name": "Wood_Hardwood_Planks"
    },
    {
      "x": -16,
      "y": 4,
      "z": -7,
      "name": "Wood_Hardwood_Planks"
    },
    {
      "x": -16,
      "y": 4,
      "z": -6,
      "name": "Wood_Hardwood_Planks"
    },
    {
      "x": -16,
      "y": 4,
      "z": -5,
      "name": "Wood_Hardwood_Planks"
    },
    {
      "x": -16,
      "y": 4,
      "z": -4,
      "name": "Wood_Hardwood_Planks"
    },
    {
      "x": -16,
      "y": 4,
      "z": -3,
      "name": "Wood_Hardwood_Planks"
    },
    {
      "x": -16,
      "y": 4,
      "z": -2,
      "name": "Wood_Hardwood_Planks"
    },
    {
      "x": -16,
      "y": 4,
      "z": -1,
      "name": "Wood_Hardwood_Planks"
    },
    {
      "x": -16,
      "y": 4,
      "z": 0,
      "name": "Wood_Hardwood_Planks"
    },
    {
      "x": -16,
      "y": 4,
      "z": 1,
      "name": "Wood_Hardwood_Planks"
    },
    {
      "x": -16,
      "y": 4,
      "z": 2,
      "name": "Wood_Hardwood_Planks"
    },
    {
      "x": -16,
      "y": 4,
      "z": 3,
      "name": "Wood_Hardwood_Planks"
    },
    {
      "x": -16,
      "y": 4,
      "z": 4,
      "name": "Wood_Hardwood_Planks"
    },
    {
      "x": -16,
      "y": 4,
      "z": 5,
      "name": "Wood_Hardwood_Planks"
    },
    {
      "x": -16,
      "y": 4,
      "z": 6,
      "name": "Wood_Hardwood_Planks"
    },
    {
      "x": -16,
      "y": 4,
      "z": 7,
      "name": "Wood_Hardwood_Planks"
    },
    {
      "x": -16,
      "y": 4,
      "z": 8,
      "name": "Wood_Hardwood_Planks"
    },
    {
      "x": -16,
      "y": 4,
      "z": 9,
      "name": "Wood_Hardwood_Planks"
    },
    {
      "x": -16,
      "y": 4,
      "z": 10,
      "name": "Wood_Hardwood_Planks"
    },
    {
      "x": -16,
      "y": 4,
      "z": 11,
      "name": "Wood_Hardwood_Planks"
    },
    {
      "x": -16,
      "y": 4,
      "z": 12,
      "name": "Wood_Hardwood_Planks"
    },
    {
      "x": -16,
      "y": 4,
      "z": 13,
      "name": "Wood_Hardwood_Planks"
    },
    {
      "x": -16,
      "y": 4,
      "z": 14,
      "name": "Wood_Hardwood_Planks"
    },
    {
      "x": -16,
      "y": 0,
      "z": 15,
      "name": "Rock_Stone_Brick"
    },
    {
      "x": -16,
      "y": 1,
      "z": 15,
      "name": "Rock_Stone_Brick"
    },
    {
      "x": -16,
      "y": 2,
      "z": 15,
      "name": "Rock_Stone_Brick"
    },
    {
      "x": -16,
      "y": 3,
      "z": 15,
      "name": "Rock_Stone_Brick"
    },
    {
      "x": -16,
      "y": 4,
      "z": 15,
      "name": "Rock_Stone_Brick"
    },
    {
      "x": -16,
      "y": 0,
      "z": 16,
      "name": "Rock_Stone_Brick"
    },
    {
      "x": -16,
      "y": 1,
      "z": 16,
      "name": "Rock_Stone_Brick"
    },
    {
      "x": -16,
      "y": 2,
      "z": 16,
      "name": "Rock_Stone_Brick"
    },
    {
      "x": -16,
      "y": 3,
      "z": 16,
      "name": "Rock_Stone_Brick"
    },
    {
      "x": -16,
      "y": 4,
      "z": 16,
      "name": "Rock_Stone_Brick"
    },
    {
      "x": -16,
      "y": 4,
      "z": 17,
      "name": "Wood_Hardwood_Planks"
    },
    {
      "x": -16,
      "y": 4,
      "z": 18,
      "name": "Wood_Hardwood_Planks"
    },
    {
      "x": -16,
      "y": 4,
      "z": 19,
      "name": "Wood_Hardwood_Planks"
    },
    {
      "x": -16,
      "y": 4,
      "z": 20,
      "name": "Wood_Hardwood_Planks"
    },
    {
      "x": -16,
      "y": 4,
      "z": 21,
      "name": "Wood_Hardwood_Planks"
    },
    {
      "x": -16,
      "y": 4,
      "z": 22,
      "name": "Wood_Hardwood_Planks"
    },
    {
      "x": -16,
      "y": 4,
      "z": 23,
      "name": "Wood_Hardwood_Planks"
    },
    {
      "x": -16,
      "y": 0,
      "z": 24,
      "name": "Rock_Stone_Brick"
    },
    {
      "x": -16,
      "y": 1,
      "z": 24,
      "name": "Rock_Stone_Brick",
      "rotation": 1
    },
    {
      "x": -16,
      "y": 4,
      "z": 24,
      "name": "Rock_Stone_Brick",
      "rotation": 1
    },
    {
      "x": -15,
      "y": 0,
      "z": -24,
      "name": "Rock_Stone_Brick",
      "rotation": 3
    },
    {
      "x": -15,
      "y": 1,
      "z": -24,
      "name": "Rock_Stone_Brick"
    },
    {
      "x": -15,
      "y": 4,
      "z": -24,
      "name": "Rock_Stone_Brick"
    },
    {
      "x": -15,
      "y": 4,
      "z": -23,
      "name": "Wood_Hardwood_Planks"
    },
    {
      "x": -15,
      "y": 4,
      "z": -22,
      "name": "Wood_Hardwood_Planks"
    },
    {
      "x": -15,
      "y": 4,
      "z": -21,
      "name": "Wood_Hardwood_Planks"
    },
    {
      "x": -15,
      "y": 4,
      "z": -20,
      "name": "Wood_Hardwood_Planks"
    },
    {
      "x": -15,
      "y": 4,
      "z": -19,
      "name": "Wood_Hardwood_Planks"
    },
    {
      "x": -15,
      "y": 0,
      "z": -18,
      "name": "Rock_Stone_Brick",
      "rotation": 3
    },
    {
      "x": -15,
      "y": 1,
      "z": -18,
      "name": "Rock_Stone_Brick"
    },
    {
      "x": -15,
      "y": 2,
      "z": -18,
      "name": "Rock_Stone_Brick"
    },
    {
      "x": -15,
      "y": 3,
      "z": -18,
      "name": "Rock_Stone_Brick"
    },
    {
      "x": -15,
      "y": 4,
      "z": -18,
      "name": "Rock_Stone_Brick"
    },
    {
      "x": -15,
      "y": 0,
      "z": -17,
      "name": "Rock_Stone_Brick"
    },
    {
      "x": -15,
      "y": 1,
      "z": -17,
      "name": "Rock_Stone_Brick"
    },
    {
      "x": -15,
      "y": 2,
      "z": -17,
      "name": "Rock_Stone_Brick"
    },
    {
      "x": -15,
      "y": 3,
      "z": -17,
      "name": "Rock_Stone_Brick"
    },
    {
      "x": -15,
      "y": 4,
      "z": -17,
      "name": "Rock_Stone_Brick"
    },
    {
      "x": -15,
      "y": 4,
      "z": -16,
      "name": "Wood_Hardwood_Planks"
    },
    {
      "x": -15,
      "y": 4,
      "z": -15,
      "name": "Wood_Hardwood_Planks"
    },
    {
      "x": -15,
      "y": 4,
      "z": -14,
      "name": "Wood_Hardwood_Planks"
    },
    {
      "x": -15,
      "y": 4,
      "z": -13,
      "name": "Wood_Hardwood_Planks"
    },
    {
      "x": -15,
      "y": 4,
      "z": -12,
      "name": "Wood_Hardwood_Planks"
    },
    {
      "x": -15,
      "y": 4,
      "z": -11,
      "name": "Wood_Hardwood_Planks"
    },
    {
      "x": -15,
      "y": 4,
      "z": -10,
      "name": "Wood_Hardwood_Planks"
    },
    {
      "x": -15,
      "y": 4,
      "z": -9,
      "name": "Wood_Hardwood_Planks"
    },
    {
      "x": -15,
      "y": 4,
      "z": -8,
      "name": "Wood_Hardwood_Planks"
    },
    {
      "x": -15,
      "y": 4,
      "z": -7,
      "name": "Wood_Hardwood_Planks"
    },
    {
      "x": -15,
      "y": 4,
      "z": -6,
      "name": "Wood_Hardwood_Planks"
    },
    {
      "x": -15,
      "y": 4,
      "z": -5,
      "name": "Wood_Hardwood_Planks"
    },
    {
      "x": -15,
      "y": 4,
      "z": -4,
      "name": "Wood_Hardwood_Planks"
    },
    {
      "x": -15,
      "y": 4,
      "z": -3,
      "name": "Wood_Hardwood_Planks"
    },
    {
      "x": -15,
      "y": 4,
      "z": -2,
      "name": "Wood_Hardwood_Planks"
    },
    {
      "x": -15,
      "y": 4,
      "z": -1,
      "name": "Wood_Hardwood_Planks"
    },
    {
      "x": -15,
      "y": 4,
      "z": 0,
      "name": "Wood_Hardwood_Planks"
    },
    {
      "x": -15,
      "y": 4,
      "z": 1,
      "name": "Wood_Hardwood_Planks"
    },
    {
      "x": -15,
      "y": 4,
      "z": 2,
      "name": "Wood_Hardwood_Planks"
    },
    {
      "x": -15,
      "y": 4,
      "z": 3,
      "name": "Wood_Hardwood_Planks"
    },
    {
      "x": -15,
      "y": 4,
      "z": 4,
      "name": "Wood_Hardwood_Planks"
    },
    {
      "x": -15,
      "y": 4,
      "z": 5,
      "name": "Wood_Hardwood_Planks"
    },
    {
      "x": -15,
      "y": 4,
      "z": 6,
      "name": "Wood_Hardwood_Planks"
    },
    {
      "x": -15,
      "y": 4,
      "z": 7,
      "name": "Wood_Hardwood_Planks"
    },
    {
      "x": -15,
      "y": 4,
      "z": 8,
      "name": "Wood_Hardwood_Planks"
    },
    {
      "x": -15,
      "y": 4,
      "z": 9,
      "name": "Wood_Hardwood_Planks"
    },
    {
      "x": -15,
      "y": 4,
      "z": 10,
      "name": "Wood_Hardwood_Planks"
    },
    {
      "x": -15,
      "y": 4,
      "z": 11,
      "name": "Wood_Hardwood_Planks"
    },
    {
      "x": -15,
      "y": 4,
      "z": 12,
      "name": "Wood_Hardwood_Planks"
    },
    {
      "x": -15,
      "y": 4,
      "z": 13,
      "name": "Wood_Hardwood_Planks"
    },
    {
      "x": -15,
      "y": 4,
      "z": 14,
      "name": "Wood_Hardwood_Planks"
    },
    {
      "x": -15,
      "y": 4,
      "z": 15,
      "name": "Wood_Hardwood_Planks"
    },
    {
      "x": -15,
      "y": 0,
      "z": 16,
      "name": "Rock_Stone_Brick"
    },
    {
      "x": -15,
      "y": 1,
      "z": 16,
      "name": "Rock_Stone_Brick"
    },
    {
      "x": -15,
      "y": 2,
      "z": 16,
      "name": "Rock_Stone_Brick"
    },
    {
      "x": -15,
      "y": 3,
      "z": 16,
      "name": "Rock_Stone_Brick"
    },
    {
      "x": -15,
      "y": 4,
      "z": 16,
      "name": "Rock_Stone_Brick"
    },
    {
      "x": -15,
      "y": 0,
      "z": 17,
      "name": "Rock_Stone_Brick"
    },
    {
      "x": -15,
      "y": 1,
      "z": 17,
      "name": "Rock_Stone_Brick"
    },
    {
      "x": -15,
      "y": 2,
      "z": 17,
      "name": "Rock_Stone_Brick"
    },
    {
      "x": -15,
      "y": 3,
      "z": 17,
      "name": "Rock_Stone_Brick"
    },
    {
      "x": -15,
      "y": 4,
      "z": 17,
      "name": "Rock_Stone_Brick"
    },
    {
      "x": -15,
      "y": 4,
      "z": 18,
      "name": "Wood_Hardwood_Planks"
    },
    {
      "x": -15,
      "y": 4,
      "z": 19,
      "name": "Wood_Hardwood_Planks"
    },
    {
      "x": -15,
      "y": 4,
      "z": 20,
      "name": "Wood_Hardwood_Planks"
    },
    {
      "x": -15,
      "y": 4,
      "z": 21,
      "name": "Wood_Hardwood_Planks"
    },
    {
      "x": -15,
      "y": 4,
      "z": 22,
      "name": "Wood_Hardwood_Planks"
    },
    {
      "x": -15,
      "y": 4,
      "z": 23,
      "name": "Wood_Hardwood_Planks"
    },
    {
      "x": -15,
      "y": 0,
      "z": 24,
      "name": "Rock_Stone_Brick"
    },
    {
      "x": -15,
      "y": 1,
      "z": 24,
      "name": "Rock_Stone_Brick",
      "rotation": 1
    },
    {
      "x": -15,
      "y": 4,
      "z": 24,
      "name": "Rock_Stone_Brick",
      "rotation": 1
    },
    {
      "x": -14,
      "y": 0,
      "z": -24,
      "name": "Rock_Stone_Brick",
      "rotation": 3
    },
    {
      "x": -14,
      "y": 1,
      "z": -24,
      "name": "Rock_Stone_Brick"
    },
    {
      "x": -14,
      "y": 4,
      "z": -24,
      "name": "Rock_Stone_Brick"
    },
    {
      "x": -14,
      "y": 4,
      "z": -23,
      "name": "Wood_Hardwood_Planks"
    },
    {
      "x": -14,
      "y": 4,
      "z": -22,
      "name": "Wood_Hardwood_Planks"
    },
    {
      "x": -14,
      "y": 4,
      "z": -21,
      "name": "Wood_Hardwood_Planks"
    },
    {
      "x": -14,
      "y": 4,
      "z": -20,
      "name": "Wood_Hardwood_Planks"
    },
    {
      "x": -14,
      "y": 4,
      "z": -19,
      "name": "Wood_Hardwood_Planks"
    },
    {
      "x": -14,
      "y": 0,
      "z": -18,
      "name": "Rock_Stone_Brick",
      "rotation": 3
    },
    {
      "x": -14,
      "y": 1,
      "z": -18,
      "name": "Rock_Stone_Brick"
    },
    {
      "x": -14,
      "y": 2,
      "z": -18,
      "name": "Rock_Stone_Brick"
    },
    {
      "x": -14,
      "y": 3,
      "z": -18,
      "name": "Rock_Stone_Brick"
    },
    {
      "x": -14,
      "y": 4,
      "z": -18,
      "name": "Rock_Stone_Brick"
    },
    {
      "x": -14,
      "y": 4,
      "z": -17,
      "name": "Wood_Hardwood_Planks"
    },
    {
      "x": -14,
      "y": 4,
      "z": -16,
      "name": "Wood_Hardwood_Planks"
    },
    {
      "x": -14,
      "y": 4,
      "z": -15,
      "name": "Wood_Hardwood_Planks"
    },
    {
      "x": -14,
      "y": 4,
      "z": -14,
      "name": "Wood_Hardwood_Planks"
    },
    {
      "x": -14,
      "y": 4,
      "z": -13,
      "name": "Wood_Hardwood_Planks"
    },
    {
      "x": -14,
      "y": 4,
      "z": -12,
      "name": "Wood_Hardwood_Planks"
    },
    {
      "x": -14,
      "y": 4,
      "z": -11,
      "name": "Wood_Hardwood_Planks"
    },
    {
      "x": -14,
      "y": 4,
      "z": -10,
      "name": "Wood_Hardwood_Planks"
    },
    {
      "x": -14,
      "y": 4,
      "z": -9,
      "name": "Wood_Hardwood_Planks"
    },
    {
      "x": -14,
      "y": 4,
      "z": -8,
      "name": "Wood_Hardwood_Planks"
    },
    {
      "x": -14,
      "y": 4,
      "z": -7,
      "name": "Wood_Hardwood_Planks"
    },
    {
      "x": -14,
      "y": 4,
      "z": -6,
      "name": "Wood_Hardwood_Planks"
    },
    {
      "x": -14,
      "y": 4,
      "z": -5,
      "name": "Wood_Hardwood_Planks"
    },
    {
      "x": -14,
      "y": 4,
      "z": -4,
      "name": "Wood_Hardwood_Planks"
    },
    {
      "x": -14,
      "y": 4,
      "z": -3,
      "name": "Wood_Hardwood_Planks"
    },
    {
      "x": -14,
      "y": 4,
      "z": -2,
      "name": "Wood_Hardwood_Planks"
    },
    {
      "x": -14,
      "y": 4,
      "z": -1,
      "name": "Wood_Hardwood_Planks"
    },
    {
      "x": -14,
      "y": 4,
      "z": 0,
      "name": "Wood_Hardwood_Planks"
    },
    {
      "x": -14,
      "y": 4,
      "z": 1,
      "name": "Wood_Hardwood_Planks"
    },
    {
      "x": -14,
      "y": 4,
      "z": 2,
      "name": "Wood_Hardwood_Planks"
    },
    {
      "x": -14,
      "y": 4,
      "z": 3,
      "name": "Wood_Hardwood_Planks"
    },
    {
      "x": -14,
      "y": 4,
      "z": 4,
      "name": "Wood_Hardwood_Planks"
    },
    {
      "x": -14,
      "y": 4,
      "z": 5,
      "name": "Wood_Hardwood_Planks"
    },
    {
      "x": -14,
      "y": 4,
      "z": 6,
      "name": "Wood_Hardwood_Planks"
    },
    {
      "x": -14,
      "y": 4,
      "z": 7,
      "name": "Wood_Hardwood_Planks"
    },
    {
      "x": -14,
      "y": 4,
      "z": 8,
      "name": "Wood_Hardwood_Planks"
    },
    {
      "x": -14,
      "y": 4,
      "z": 9,
      "name": "Wood_Hardwood_Planks"
    },
    {
      "x": -14,
      "y": 4,
      "z": 10,
      "name": "Wood_Hardwood_Planks"
    },
    {
      "x": -14,
      "y": 4,
      "z": 11,
      "name": "Wood_Hardwood_Planks"
    },
    {
      "x": -14,
      "y": 4,
      "z": 12,
      "name": "Wood_Hardwood_Planks"
    },
    {
      "x": -14,
      "y": 4,
      "z": 13,
      "name": "Wood_Hardwood_Planks"
    },
    {
      "x": -14,
      "y": 4,
      "z": 14,
      "name": "Wood_Hardwood_Planks"
    },
    {
      "x": -14,
      "y": 4,
      "z": 15,
      "name": "Wood_Hardwood_Planks"
    },
    {
      "x": -14,
      "y": 4,
      "z": 16,
      "name": "Wood_Hardwood_Planks"
    },
    {
      "x": -14,
      "y": 0,
      "z": 17,
      "name": "Rock_Stone_Brick"
    },
    {
      "x": -14,
      "y": 1,
      "z": 17,
      "name": "Rock_Stone_Brick"
    },
    {
      "x": -14,
      "y": 2,
      "z": 17,
      "name": "Rock_Stone_Brick"
    },
    {
      "x": -14,
      "y": 3,
      "z": 17,
      "name": "Rock_Stone_Brick"
    },
    {
      "x": -14,
      "y": 4,
      "z": 17,
      "name": "Rock_Stone_Brick"
    },
    {
      "x": -14,
      "y": 0,
      "z": 18,
      "name": "Rock_Stone_Brick"
    },
    {
      "x": -14,
      "y": 1,
      "z": 18,
      "name": "Rock_Stone_Brick"
    },
    {
      "x": -14,
      "y": 2,
      "z": 18,
      "name": "Rock_Stone_Brick"
    },
    {
      "x": -14,
      "y": 3,
      "z": 18,
      "name": "Rock_Stone_Brick"
    },
    {
      "x": -14,
      "y": 4,
      "z": 18,
      "name": "Rock_Stone_Brick"
    },
    {
      "x": -14,
      "y": 4,
      "z": 19,
      "name": "Wood_Hardwood_Planks"
    },
    {
      "x": -14,
      "y": 4,
      "z": 20,
      "name": "Wood_Hardwood_Planks"
    },
    {
      "x": -14,
      "y": 4,
      "z": 21,
      "name": "Wood_Hardwood_Planks"
    },
    {
      "x": -14,
      "y": 4,
      "z": 22,
      "name": "Wood_Hardwood_Planks"
    },
    {
      "x": -14,
      "y": 4,
      "z": 23,
      "name": "Wood_Hardwood_Planks"
    },
    {
      "x": -14,
      "y": 0,
      "z": 24,
      "name": "Rock_Stone_Brick"
    },
    {
      "x": -14,
      "y": 1,
      "z": 24,
      "name": "Rock_Stone_Brick",
      "rotation": 1
    },
    {
      "x": -14,
      "y": 4,
      "z": 24,
      "name": "Rock_Stone_Brick",
      "rotation": 1
    },
    {
      "x": -13,
      "y": 0,
      "z": -24,
      "name": "Rock_Stone_Brick",
      "rotation": 3
    },
    {
      "x": -13,
      "y": 1,
      "z": -24,
      "name": "Rock_Stone_Brick"
    },
    {
      "x": -13,
      "y": 4,
      "z": -24,
      "name": "Rock_Stone_Brick"
    },
    {
      "x": -13,
      "y": 4,
      "z": -23,
      "name": "Wood_Hardwood_Planks"
    },
    {
      "x": -13,
      "y": 4,
      "z": -22,
      "name": "Wood_Hardwood_Planks"
    },
    {
      "x": -13,
      "y": 4,
      "z": -21,
      "name": "Wood_Hardwood_Planks"
    },
    {
      "x": -13,
      "y": 4,
      "z": -20,
      "name": "Wood_Hardwood_Planks"
    },
    {
      "x": -13,
      "y": 4,
      "z": -19,
      "name": "Wood_Hardwood_Planks"
    },
    {
      "x": -13,
      "y": 0,
      "z": -18,
      "name": "Rock_Stone_Brick",
      "rotation": 3
    },
    {
      "x": -13,
      "y": 1,
      "z": -18,
      "name": "Rock_Stone_Brick"
    },
    {
      "x": -13,
      "y": 2,
      "z": -18,
      "name": "Rock_Stone_Brick"
    },
    {
      "x": -13,
      "y": 3,
      "z": -18,
      "name": "Rock_Stone_Brick"
    },
    {
      "x": -13,
      "y": 4,
      "z": -18,
      "name": "Rock_Stone_Brick"
    },
    {
      "x": -13,
      "y": 4,
      "z": -17,
      "name": "Wood_Hardwood_Planks"
    },
    {
      "x": -13,
      "y": 4,
      "z": -16,
      "name": "Wood_Hardwood_Planks"
    },
    {
      "x": -13,
      "y": 4,
      "z": -15,
      "name": "Wood_Hardwood_Planks"
    },
    {
      "x": -13,
      "y": 4,
      "z": -14,
      "name": "Wood_Hardwood_Planks"
    },
    {
      "x": -13,
      "y": 4,
      "z": -13,
      "name": "Wood_Hardwood_Planks"
    },
    {
      "x": -13,
      "y": 4,
      "z": -12,
      "name": "Wood_Hardwood_Planks"
    },
    {
      "x": -13,
      "y": 4,
      "z": -11,
      "name": "Wood_Hardwood_Planks"
    },
    {
      "x": -13,
      "y": 4,
      "z": -10,
      "name": "Wood_Hardwood_Planks"
    },
    {
      "x": -13,
      "y": 4,
      "z": -9,
      "name": "Wood_Hardwood_Planks"
    },
    {
      "x": -13,
      "y": 4,
      "z": -8,
      "name": "Wood_Hardwood_Planks"
    },
    {
      "x": -13,
      "y": 4,
      "z": -7,
      "name": "Wood_Hardwood_Planks"
    },
    {
      "x": -13,
      "y": 4,
      "z": -6,
      "name": "Wood_Hardwood_Planks"
    },
    {
      "x": -13,
      "y": 4,
      "z": -5,
      "name": "Wood_Hardwood_Planks"
    },
    {
      "x": -13,
      "y": 4,
      "z": -4,
      "name": "Wood_Hardwood_Planks"
    },
    {
      "x": -13,
      "y": 4,
      "z": -3,
      "name": "Wood_Hardwood_Planks"
    },
    {
      "x": -13,
      "y": 4,
      "z": -2,
      "name": "Wood_Hardwood_Planks"
    },
    {
      "x": -13,
      "y": 4,
      "z": -1,
      "name": "Wood_Hardwood_Planks"
    },
    {
      "x": -13,
      "y": 4,
      "z": 0,
      "name": "Wood_Hardwood_Planks"
    },
    {
      "x": -13,
      "y": 4,
      "z": 1,
      "name": "Wood_Hardwood_Planks"
    },
    {
      "x": -13,
      "y": 4,
      "z": 2,
      "name": "Wood_Hardwood_Planks"
    },
    {
      "x": -13,
      "y": 4,
      "z": 3,
      "name": "Wood_Hardwood_Planks"
    },
    {
      "x": -13,
      "y": 4,
      "z": 4,
      "name": "Wood_Hardwood_Planks"
    },
    {
      "x": -13,
      "y": 4,
      "z": 5,
      "name": "Wood_Hardwood_Planks"
    },
    {
      "x": -13,
      "y": 4,
      "z": 6,
      "name": "Wood_Hardwood_Planks"
    },
    {
      "x": -13,
      "y": 4,
      "z": 7,
      "name": "Wood_Hardwood_Planks"
    },
    {
      "x": -13,
      "y": 4,
      "z": 8,
      "name": "Wood_Hardwood_Planks"
    },
    {
      "x": -13,
      "y": 4,
      "z": 9,
      "name": "Wood_Hardwood_Planks"
    },
    {
      "x": -13,
      "y": 4,
      "z": 10,
      "name": "Wood_Hardwood_Planks"
    },
    {
      "x": -13,
      "y": 4,
      "z": 11,
      "name": "Wood_Hardwood_Planks"
    },
    {
      "x": -13,
      "y": 4,
      "z": 12,
      "name": "Wood_Hardwood_Planks"
    },
    {
      "x": -13,
      "y": 4,
      "z": 13,
      "name": "Wood_Hardwood_Planks"
    },
    {
      "x": -13,
      "y": 4,
      "z": 14,
      "name": "Wood_Hardwood_Planks"
    },
    {
      "x": -13,
      "y": 4,
      "z": 15,
      "name": "Wood_Hardwood_Planks"
    },
    {
      "x": -13,
      "y": 4,
      "z": 16,
      "name": "Wood_Hardwood_Planks"
    },
    {
      "x": -13,
      "y": 4,
      "z": 17,
      "name": "Wood_Hardwood_Planks"
    },
    {
      "x": -13,
      "y": 0,
      "z": 18,
      "name": "Rock_Stone_Brick"
    },
    {
      "x": -13,
      "y": 1,
      "z": 18,
      "name": "Rock_Stone_Brick"
    },
    {
      "x": -13,
      "y": 2,
      "z": 18,
      "name": "Rock_Stone_Brick"
    },
    {
      "x": -13,
      "y": 3,
      "z": 18,
      "name": "Rock_Stone_Brick"
    },
    {
      "x": -13,
      "y": 4,
      "z": 18,
      "name": "Rock_Stone_Brick"
    },
    {
      "x": -13,
      "y": 4,
      "z": 19,
      "name": "Wood_Hardwood_Planks"
    },
    {
      "x": -13,
      "y": 4,
      "z": 20,
      "name": "Wood_Hardwood_Planks"
    },
    {
      "x": -13,
      "y": 4,
      "z": 21,
      "name": "Wood_Hardwood_Planks"
    },
    {
      "x": -13,
      "y": 4,
      "z": 22,
      "name": "Wood_Hardwood_Planks"
    },
    {
      "x": -13,
      "y": 4,
      "z": 23,
      "name": "Wood_Hardwood_Planks"
    },
    {
      "x": -13,
      "y": 0,
      "z": 24,
      "name": "Rock_Stone_Brick"
    },
    {
      "x": -13,
      "y": 1,
      "z": 24,
      "name": "Rock_Stone_Brick",
      "rotation": 1
    },
    {
      "x": -13,
      "y": 4,
      "z": 24,
      "name": "Rock_Stone_Brick",
      "rotation": 1
    },
    {
      "x": -12,
      "y": 0,
      "z": -24,
      "name": "Rock_Stone_Brick",
      "rotation": 3
    },
    {
      "x": -12,
      "y": 1,
      "z": -24,
      "name": "Rock_Stone_Brick"
    },
    {
      "x": -12,
      "y": 4,
      "z": -24,
      "name": "Rock_Stone_Brick"
    },
    {
      "x": -12,
      "y": 4,
      "z": -23,
      "name": "Wood_Hardwood_Planks"
    },
    {
      "x": -12,
      "y": 4,
      "z": -22,
      "name": "Wood_Hardwood_Planks"
    },
    {
      "x": -12,
      "y": 4,
      "z": -21,
      "name": "Wood_Hardwood_Planks"
    },
    {
      "x": -12,
      "y": 4,
      "z": -20,
      "name": "Wood_Hardwood_Planks"
    },
    {
      "x": -12,
      "y": 4,
      "z": -19,
      "name": "Wood_Hardwood_Planks"
    },
    {
      "x": -12,
      "y": 4,
      "z": -18,
      "name": "Wood_Hardwood_Planks"
    },
    {
      "x": -12,
      "y": 4,
      "z": -17,
      "name": "Wood_Hardwood_Planks"
    },
    {
      "x": -12,
      "y": 4,
      "z": -16,
      "name": "Wood_Hardwood_Planks"
    },
    {
      "x": -12,
      "y": 4,
      "z": -15,
      "name": "Wood_Hardwood_Planks"
    },
    {
      "x": -12,
      "y": 4,
      "z": -14,
      "name": "Wood_Hardwood_Planks"
    },
    {
      "x": -12,
      "y": 4,
      "z": -13,
      "name": "Wood_Hardwood_Planks"
    },
    {
      "x": -12,
      "y": 4,
      "z": -12,
      "name": "Wood_Hardwood_Planks"
    },
    {
      "x": -12,
      "y": 4,
      "z": -11,
      "name": "Wood_Hardwood_Planks"
    },
    {
      "x": -12,
      "y": 4,
      "z": -10,
      "name": "Wood_Hardwood_Planks"
    },
    {
      "x": -12,
      "y": 4,
      "z": -9,
      "name": "Wood_Hardwood_Planks"
    },
    {
      "x": -12,
      "y": 4,
      "z": -8,
      "name": "Wood_Hardwood_Planks"
    },
    {
      "x": -12,
      "y": 4,
      "z": -7,
      "name": "Wood_Hardwood_Planks"
    },
    {
      "x": -12,
      "y": 4,
      "z": -6,
      "name": "Wood_Hardwood_Planks"
    },
    {
      "x": -12,
      "y": 4,
      "z": -5,
      "name": "Wood_Hardwood_Planks"
    },
    {
      "x": -12,
      "y": 4,
      "z": -4,
      "name": "Wood_Hardwood_Planks"
    },
    {
      "x": -12,
      "y": 4,
      "z": -3,
      "name": "Wood_Hardwood_Planks"
    },
    {
      "x": -12,
      "y": 4,
      "z": -2,
      "name": "Wood_Hardwood_Planks"
    },
    {
      "x": -12,
      "y": 4,
      "z": -1,
      "name": "Wood_Hardwood_Planks"
    },
    {
      "x": -12,
      "y": 4,
      "z": 0,
      "name": "Wood_Hardwood_Planks"
    },
    {
      "x": -12,
      "y": 4,
      "z": 1,
      "name": "Wood_Hardwood_Planks"
    },
    {
      "x": -12,
      "y": 4,
      "z": 2,
      "name": "Wood_Hardwood_Planks"
    },
    {
      "x": -12,
      "y": 4,
      "z": 3,
      "name": "Wood_Hardwood_Planks"
    },
    {
      "x": -12,
      "y": 4,
      "z": 4,
      "name": "Wood_Hardwood_Planks"
    },
    {
      "x": -12,
      "y": 4,
      "z": 5,
      "name": "Wood_Hardwood_Planks"
    },
    {
      "x": -12,
      "y": 4,
      "z": 6,
      "name": "Wood_Hardwood_Planks"
    },
    {
      "x": -12,
      "y": 4,
      "z": 7,
      "name": "Wood_Hardwood_Planks"
    },
    {
      "x": -12,
      "y": 4,
      "z": 8,
      "name": "Wood_Hardwood_Planks"
    },
    {
      "x": -12,
      "y": 4,
      "z": 9,
      "name": "Wood_Hardwood_Planks"
    },
    {
      "x": -12,
      "y": 4,
      "z": 10,
      "name": "Wood_Hardwood_Planks"
    },
    {
      "x": -12,
      "y": 4,
      "z": 11,
      "name": "Wood_Hardwood_Planks"
    },
    {
      "x": -12,
      "y": 4,
      "z": 12,
      "name": "Wood_Hardwood_Planks"
    },
    {
      "x": -12,
      "y": 4,
      "z": 13,
      "name": "Wood_Hardwood_Planks"
    },
    {
      "x": -12,
      "y": 4,
      "z": 14,
      "name": "Wood_Hardwood_Planks"
    },
    {
      "x": -12,
      "y": 4,
      "z": 15,
      "name": "Wood_Hardwood_Planks"
    },
    {
      "x": -12,
      "y": 4,
      "z": 16,
      "name": "Wood_Hardwood_Planks"
    },
    {
      "x": -12,
      "y": 4,
      "z": 17,
      "name": "Wood_Hardwood_Planks"
    },
    {
      "x": -12,
      "y": 0,
      "z": 18,
      "name": "Rock_Stone_Brick"
    },
    {
      "x": -12,
      "y": 1,
      "z": 18,
      "name": "Rock_Stone_Brick"
    },
    {
      "x": -12,
      "y": 2,
      "z": 18,
      "name": "Rock_Stone_Brick"
    },
    {
      "x": -12,
      "y": 3,
      "z": 18,
      "name": "Rock_Stone_Brick"
    },
    {
      "x": -12,
      "y": 4,
      "z": 18,
      "name": "Rock_Stone_Brick"
    },
    {
      "x": -12,
      "y": 4,
      "z": 19,
      "name": "Wood_Hardwood_Planks"
    },
    {
      "x": -12,
      "y": 4,
      "z": 20,
      "name": "Wood_Hardwood_Planks"
    },
    {
      "x": -12,
      "y": 4,
      "z": 21,
      "name": "Wood_Hardwood_Planks"
    },
    {
      "x": -12,
      "y": 4,
      "z": 22,
      "name": "Wood_Hardwood_Planks"
    },
    {
      "x": -12,
      "y": 4,
      "z": 23,
      "name": "Wood_Hardwood_Planks"
    },
    {
      "x": -12,
      "y": 0,
      "z": 24,
      "name": "Rock_Stone_Brick"
    },
    {
      "x": -12,
      "y": 1,
      "z": 24,
      "name": "Rock_Stone_Brick",
      "rotation": 1
    },
    {
      "x": -12,
      "y": 2,
      "z": 24,
      "name": "Rock_Stone_Brick",
      "rotation": 1
    },
    {
      "x": -12,
      "y": 3,
      "z": 24,
      "name": "Rock_Stone_Brick",
      "rotation": 1
    },
    {
      "x": -12,
      "y": 4,
      "z": 24,
      "name": "Rock_Stone_Brick",
      "rotation": 1
    },
    {
      "x": -11,
      "y": 0,
      "z": -24,
      "name": "Rock_Stone_Brick"
    },
    {
      "x": -11,
      "y": 1,
      "z": -24,
      "name": "Rock_Stone_Brick"
    },
    {
      "x": -11,
      "y": 4,
      "z": -24,
      "name": "Rock_Stone_Brick"
    },
    {
      "x": -11,
      "y": 4,
      "z": -23,
      "name": "Wood_Hardwood_Planks"
    },
    {
      "x": -11,
      "y": 4,
      "z": -22,
      "name": "Wood_Hardwood_Planks"
    },
    {
      "x": -11,
      "y": 4,
      "z": -21,
      "name": "Wood_Hardwood_Planks"
    },
    {
      "x": -11,
      "y": 4,
      "z": -20,
      "name": "Wood_Hardwood_Planks"
    },
    {
      "x": -11,
      "y": 4,
      "z": -19,
      "name": "Wood_Hardwood_Planks"
    },
    {
      "x": -11,
      "y": 4,
      "z": -18,
      "name": "Wood_Hardwood_Planks"
    },
    {
      "x": -11,
      "y": 4,
      "z": -17,
      "name": "Wood_Hardwood_Planks"
    },
    {
      "x": -11,
      "y": 4,
      "z": -16,
      "name": "Wood_Hardwood_Planks"
    },
    {
      "x": -11,
      "y": 4,
      "z": -15,
      "name": "Wood_Hardwood_Planks"
    },
    {
      "x": -11,
      "y": 4,
      "z": -14,
      "name": "Wood_Hardwood_Planks"
    },
    {
      "x": -11,
      "y": 4,
      "z": -13,
      "name": "Wood_Hardwood_Planks"
    },
    {
      "x": -11,
      "y": 4,
      "z": -12,
      "name": "Wood_Hardwood_Planks"
    },
    {
      "x": -11,
      "y": 4,
      "z": -11,
      "name": "Wood_Hardwood_Planks"
    },
    {
      "x": -11,
      "y": 4,
      "z": -10,
      "name": "Wood_Hardwood_Planks"
    },
    {
      "x": -11,
      "y": 4,
      "z": -9,
      "name": "Wood_Hardwood_Planks"
    },
    {
      "x": -11,
      "y": 4,
      "z": -8,
      "name": "Wood_Hardwood_Planks"
    },
    {
      "x": -11,
      "y": 4,
      "z": -7,
      "name": "Wood_Hardwood_Planks"
    },
    {
      "x": -11,
      "y": 4,
      "z": -6,
      "name": "Wood_Hardwood_Planks"
    },
    {
      "x": -11,
      "y": 4,
      "z": -5,
      "name": "Wood_Hardwood_Planks"
    },
    {
      "x": -11,
      "y": 4,
      "z": -4,
      "name": "Wood_Hardwood_Planks"
    },
    {
      "x": -11,
      "y": 4,
      "z": -3,
      "name": "Wood_Hardwood_Planks"
    },
    {
      "x": -11,
      "y": 4,
      "z": -2,
      "name": "Wood_Hardwood_Planks"
    },
    {
      "x": -11,
      "y": 4,
      "z": -1,
      "name": "Wood_Hardwood_Planks"
    },
    {
      "x": -11,
      "y": 4,
      "z": 0,
      "name": "Wood_Hardwood_Planks"
    },
    {
      "x": -11,
      "y": 4,
      "z": 1,
      "name": "Wood_Hardwood_Planks"
    },
    {
      "x": -11,
      "y": 4,
      "z": 2,
      "name": "Wood_Hardwood_Planks"
    },
    {
      "x": -11,
      "y": 4,
      "z": 3,
      "name": "Wood_Hardwood_Planks"
    },
    {
      "x": -11,
      "y": 4,
      "z": 4,
      "name": "Wood_Hardwood_Planks"
    },
    {
      "x": -11,
      "y": 4,
      "z": 5,
      "name": "Wood_Hardwood_Planks"
    },
    {
      "x": -11,
      "y": 4,
      "z": 6,
      "name": "Wood_Hardwood_Planks"
    },
    {
      "x": -11,
      "y": 4,
      "z": 7,
      "name": "Wood_Hardwood_Planks"
    },
    {
      "x": -11,
      "y": 4,
      "z": 8,
      "name": "Wood_Hardwood_Planks"
    },
    {
      "x": -11,
      "y": 4,
      "z": 9,
      "name": "Wood_Hardwood_Planks"
    },
    {
      "x": -11,
      "y": 4,
      "z": 10,
      "name": "Wood_Hardwood_Planks"
    },
    {
      "x": -11,
      "y": 4,
      "z": 11,
      "name": "Wood_Hardwood_Planks"
    },
    {
      "x": -11,
      "y": 4,
      "z": 12,
      "name": "Wood_Hardwood_Planks"
    },
    {
      "x": -11,
      "y": 4,
      "z": 13,
      "name": "Wood_Hardwood_Planks"
    },
    {
      "x": -11,
      "y": 4,
      "z": 14,
      "name": "Wood_Hardwood_Planks"
    },
    {
      "x": -11,
      "y": 4,
      "z": 15,
      "name": "Wood_Hardwood_Planks"
    },
    {
      "x": -11,
      "y": 4,
      "z": 16,
      "name": "Wood_Hardwood_Planks"
    },
    {
      "x": -11,
      "y": 4,
      "z": 17,
      "name": "Wood_Hardwood_Planks"
    },
    {
      "x": -11,
      "y": 4,
      "z": 18,
      "name": "Wood_Hardwood_Planks"
    },
    {
      "x": -11,
      "y": 4,
      "z": 19,
      "name": "Wood_Hardwood_Planks"
    },
    {
      "x": -11,
      "y": 4,
      "z": 20,
      "name": "Wood_Hardwood_Planks"
    },
    {
      "x": -11,
      "y": 4,
      "z": 21,
      "name": "Wood_Hardwood_Planks"
    },
    {
      "x": -11,
      "y": 4,
      "z": 22,
      "name": "Wood_Hardwood_Planks"
    },
    {
      "x": -11,
      "y": 4,
      "z": 23,
      "name": "Wood_Hardwood_Planks"
    },
    {
      "x": -11,
      "y": 0,
      "z": 24,
      "name": "Rock_Stone_Brick"
    },
    {
      "x": -11,
      "y": 1,
      "z": 24,
      "name": "Rock_Stone_Brick",
      "rotation": 1
    },
    {
      "x": -11,
      "y": 2,
      "z": 24,
      "name": "Rock_Stone_Brick",
      "rotation": 1
    },
    {
      "x": -11,
      "y": 3,
      "z": 24,
      "name": "Rock_Stone_Brick",
      "rotation": 1
    },
    {
      "x": -11,
      "y": 4,
      "z": 24,
      "name": "Rock_Stone_Brick",
      "rotation": 1
    },
    {
      "x": -10,
      "y": 0,
      "z": -24,
      "name": "Rock_Stone_Brick"
    },
    {
      "x": -10,
      "y": 1,
      "z": -24,
      "name": "Rock_Stone_Brick"
    },
    {
      "x": -10,
      "y": 2,
      "z": -24,
      "name": "Rock_Stone_Brick"
    },
    {
      "x": -10,
      "y": 3,
      "z": -24,
      "name": "Rock_Stone_Brick"
    },
    {
      "x": -10,
      "y": 4,
      "z": -24,
      "name": "Rock_Stone_Brick"
    },
    {
      "x": -10,
      "y": 4,
      "z": -23,
      "name": "Wood_Hardwood_Planks"
    },
    {
      "x": -10,
      "y": 4,
      "z": -22,
      "name": "Wood_Hardwood_Planks"
    },
    {
      "x": -10,
      "y": 4,
      "z": -21,
      "name": "Wood_Hardwood_Planks"
    },
    {
      "x": -10,
      "y": 4,
      "z": -20,
      "name": "Wood_Hardwood_Planks"
    },
    {
      "x": -10,
      "y": 4,
      "z": -19,
      "name": "Wood_Hardwood_Planks"
    },
    {
      "x": -10,
      "y": 4,
      "z": -18,
      "name": "Wood_Hardwood_Planks"
    },
    {
      "x": -10,
      "y": 4,
      "z": -17,
      "name": "Wood_Hardwood_Planks"
    },
    {
      "x": -10,
      "y": 4,
      "z": -16,
      "name": "Wood_Hardwood_Planks"
    },
    {
      "x": -10,
      "y": 4,
      "z": -15,
      "name": "Wood_Hardwood_Planks"
    },
    {
      "x": -10,
      "y": 4,
      "z": -14,
      "name": "Wood_Hardwood_Planks"
    },
    {
      "x": -10,
      "y": 4,
      "z": -13,
      "name": "Wood_Hardwood_Planks"
    },
    {
      "x": -10,
      "y": 4,
      "z": -12,
      "name": "Wood_Hardwood_Planks"
    },
    {
      "x": -10,
      "y": 4,
      "z": -11,
      "name": "Wood_Hardwood_Planks"
    },
    {
      "x": -10,
      "y": 4,
      "z": -10,
      "name": "Wood_Hardwood_Planks"
    },
    {
      "x": -10,
      "y": 4,
      "z": -9,
      "name": "Wood_Hardwood_Planks"
    },
    {
      "x": -10,
      "y": 4,
      "z": -8,
      "name": "Wood_Hardwood_Planks"
    },
    {
      "x": -10,
      "y": 4,
      "z": -7,
      "name": "Wood_Hardwood_Planks"
    },
    {
      "x": -10,
      "y": 4,
      "z": -6,
      "name": "Wood_Hardwood_Planks"
    },
    {
      "x": -10,
      "y": 4,
      "z": -5,
      "name": "Wood_Hardwood_Planks"
    },
    {
      "x": -10,
      "y": 4,
      "z": -4,
      "name": "Wood_Hardwood_Planks"
    },
    {
      "x": -10,
      "y": 4,
      "z": -3,
      "name": "Wood_Hardwood_Planks"
    },
    {
      "x": -10,
      "y": 4,
      "z": -2,
      "name": "Wood_Hardwood_Planks"
    },
    {
      "x": -10,
      "y": 4,
      "z": -1,
      "name": "Wood_Hardwood_Planks"
    },
    {
      "x": -10,
      "y": 4,
      "z": 0,
      "name": "Wood_Hardwood_Planks"
    },
    {
      "x": -10,
      "y": 4,
      "z": 1,
      "name": "Wood_Hardwood_Planks"
    },
    {
      "x": -10,
      "y": 4,
      "z": 2,
      "name": "Wood_Hardwood_Planks"
    },
    {
      "x": -10,
      "y": 4,
      "z": 3,
      "name": "Wood_Hardwood_Planks"
    },
    {
      "x": -10,
      "y": 4,
      "z": 4,
      "name": "Wood_Hardwood_Planks"
    },
    {
      "x": -10,
      "y": 4,
      "z": 5,
      "name": "Wood_Hardwood_Planks"
    },
    {
      "x": -10,
      "y": 4,
      "z": 6,
      "name": "Wood_Hardwood_Planks"
    },
    {
      "x": -10,
      "y": 4,
      "z": 7,
      "name": "Wood_Hardwood_Planks"
    },
    {
      "x": -10,
      "y": 4,
      "z": 8,
      "name": "Wood_Hardwood_Planks"
    },
    {
      "x": -10,
      "y": 4,
      "z": 9,
      "name": "Wood_Hardwood_Planks"
    },
    {
      "x": -10,
      "y": 4,
      "z": 10,
      "name": "Wood_Hardwood_Planks"
    },
    {
      "x": -10,
      "y": 4,
      "z": 11,
      "name": "Wood_Hardwood_Planks"
    },
    {
      "x": -10,
      "y": 4,
      "z": 12,
      "name": "Wood_Hardwood_Planks"
    },
    {
      "x": -10,
      "y": 4,
      "z": 13,
      "name": "Wood_Hardwood_Planks"
    },
    {
      "x": -10,
      "y": 4,
      "z": 14,
      "name": "Wood_Hardwood_Planks"
    },
    {
      "x": -10,
      "y": 4,
      "z": 15,
      "name": "Wood_Hardwood_Planks"
    },
    {
      "x": -10,
      "y": 4,
      "z": 16,
      "name": "Wood_Hardwood_Planks"
    },
    {
      "x": -10,
      "y": 4,
      "z": 17,
      "name": "Wood_Hardwood_Planks"
    },
    {
      "x": -10,
      "y": 4,
      "z": 18,
      "name": "Wood_Hardwood_Planks"
    },
    {
      "x": -10,
      "y": 4,
      "z": 19,
      "name": "Wood_Hardwood_Planks"
    },
    {
      "x": -10,
      "y": 4,
      "z": 20,
      "name": "Wood_Hardwood_Planks"
    },
    {
      "x": -10,
      "y": 4,
      "z": 21,
      "name": "Wood_Hardwood_Planks"
    },
    {
      "x": -10,
      "y": 4,
      "z": 22,
      "name": "Wood_Hardwood_Planks"
    },
    {
      "x": -10,
      "y": 4,
      "z": 23,
      "name": "Wood_Hardwood_Planks"
    },
    {
      "x": -10,
      "y": 0,
      "z": 24,
      "name": "Rock_Stone_Brick"
    },
    {
      "x": -10,
      "y": 1,
      "z": 24,
      "name": "Rock_Stone_Brick",
      "rotation": 1
    },
    {
      "x": -10,
      "y": 4,
      "z": 24,
      "name": "Rock_Stone_Brick",
      "rotation": 1
    },
    {
      "x": -9,
      "y": 0,
      "z": -24,
      "name": "Rock_Stone_Brick"
    },
    {
      "x": -9,
      "y": 1,
      "z": -24,
      "name": "Rock_Stone_Brick"
    },
    {
      "x": -9,
      "y": 2,
      "z": -24,
      "name": "Rock_Stone_Brick"
    },
    {
      "x": -9,
      "y": 3,
      "z": -24,
      "name": "Rock_Stone_Brick"
    },
    {
      "x": -9,
      "y": 4,
      "z": -24,
      "name": "Rock_Stone_Brick"
    },
    {
      "x": -9,
      "y": 4,
      "z": -23,
      "name": "Wood_Hardwood_Planks"
    },
    {
      "x": -9,
      "y": 4,
      "z": -22,
      "name": "Wood_Hardwood_Planks"
    },
    {
      "x": -9,
      "y": 4,
      "z": -21,
      "name": "Wood_Hardwood_Planks"
    },
    {
      "x": -9,
      "y": 4,
      "z": -20,
      "name": "Wood_Hardwood_Planks"
    },
    {
      "x": -9,
      "y": 4,
      "z": -19,
      "name": "Wood_Hardwood_Planks"
    },
    {
      "x": -9,
      "y": 4,
      "z": -18,
      "name": "Wood_Hardwood_Planks"
    },
    {
      "x": -9,
      "y": 4,
      "z": -17,
